Workbook

Sheet Utilidad
A1: 150420 | B1: 150420 | C1: 23.88 | D1: 23.88 | E1: 0
A2: 0 | B2: 0 | C2: 0 | D2: 0 | E2: 0
A3: 60303 | B3: 60303 | C3: 13.9 | D3: 13.205 | E3: 0
A4: 90117 | B4: 90117 | C4: 30.55 | D4: 31.02332 | E4: 0
A5: 0 | B5: 0 | C5: 0 | D5: 0 | E5: 0
A6: -28228 | B6: -34429.131 | C6: 30.55 | D6: 32.0775 | E6: 0
A7: 116673 | B7: 124546.13 | C7: 31.13 | D7: 31.314734 | E7: 0.0165
A8: 0 | B8: 0 | C8: 0 | D8: 0 | E8: 0
A9: 20214 | B9: 24875.066 | C9: 20.26 | D9: 19.247 | E9: 0.0776
A10: 11970 | B10: 15456.337 | C10: 11.43 | D10: 10.8585 | E10: 0
A11: 60996 | B11: 64047.728 | C11: 36.6 | D11: 35.689666 | E11: 0.0402
A12: 20167 | B12: 20167 | C12: 48.56 | D12: 47.983531 | E12: 0.04476
... A67: 0 | B67: 0 | C67: 0 | D67: 0 | E67: 0
I71: Cola Concentradora (canoa) | J71: =B10 -> 15456.337 | K71: =IF(D10>1,D10/100,D10) -> 0.108585 | L71: =+J71*K71 -> 1678.3263
I72: Concentradora a Stock Preconcentrado | J72: =B11 -> 64047.728 | K72: =IF(D11>1,D11/100,D11) -> 0.35689666 | L72: =+J72*K72 -> 22858.42
I73: SF a molienda | J73: =B12 -> 20167 | K73: =IF(D12>1,D12/100,D12) -> 0.47983531 | L73: =+J73*K73 -> 9676.8387
I74: Repulpeo | J74: =B13 -> 1437 | K74: =IF(D13>1,D13/100,D13) -> 0.49744624 | L74: =+J74*K74 -> 714.83024
I75: Delta Stock Preconcentrado | J75: =B14 -> 12216.728 | K75: =IF(D14>1,D14/100,D14) -> 0.393965 | L75: =+J75*K75 -> 4812.9631
I76: Alimentación Preconcentrado a Molienda | J76: =B15 -> 88249 | K76: =IF(D15>1,D15/100,D15) -> 0.41240586 | L76: =+J76*K76 -> 36394.405
I77: Cola de Molienda | J77: =B16 -> 43841 | K77: =IF(D16>1,D16/100,D16) -> 0.093195 | L77: =+J77*K77 -> 4085.762
I78: Concentrado a Almacenamiento | J78: =B17 -> 66012 | K78: =IF(D17>1,D17/100,D17) -> 0.64685681 | L78: =+J78*K78 -> 42700.312
I79: Delta Almacenamiento de Concentrado | J79: =B18 -> -5099 | K79: =IF(D18>1,D18/100,D18) -> 0.683025 | L79: =+J79*K79 -> -3482.7445
I80: Concentrado a Stock Pellet Feed ROM | J80: =B19 -> 0 | K80: =IF(D19>1,D19/100,D19) -> 0 | L80: =+J80*K80 -> 0
I81: Delta Stock Pellet Feed ROM | J81: =B20 -> 71111 | K81: =IF(D20>1,D20/100,D20) -> 0.64945024 | L81: =+J81*K81 -> 46183.056
I82: Transporte Pellet Feed en camiones a Guayacan | J82: =B21 -> 1422 | K82: =IF(D21>1,D21/100,D21) -> 0.631373 | L82: =+J82*K82 -> 897.81241
... I116: De nodo Alim Otros Materiales + Emergencia a S Preconcentrado | J116: =B55 -> 0 | K116: =IF(D55>1,D55/100,D55) -> 0 | L116: =+J116*K116 -> 0

Sheet Datos Extra
A1: Flujos | B1: Masas | C1: Leyes | D1: Humedad
A2: Stock Intermedio | B2: 11665 | C2: 0.5 | D2: 0.01
A3: Stock Preconcentrado | B3: 32218.642 | C3: 0.5 | D3: 0.01
A4: Stock Pellet Feed | B4: 33 | C4: 0.5 | D4: 0.089433339
A5: Stock Sinter Feed Patio Tolva | B5: 0 | C5: 0.5 | D5: 0
A6: Stock Pellet Feed Guayacan | B6: 108658.53 | C6: 0.5 | D6: 0.092196679
A7: Stock Sinter Guayacan | B7: 60226.45 | C7: 0.5 | D7: 0
A8: Stock Granza Guayacan | B8: 64802 | C8: 0.5 | D8: 0
A9: Pellet Feed Acopiado Trenes | B9: 71110.958 | C9: 0.65092955 | D9: 0.01
A10: Pellet Feed Produccion Primaria | B10: 66011.839 | C10: 0.6505 | D10: 0.01
A11: Sinter Feed MLC camiones | B11: 0 | C11: 0 | D11: 0.01
A12: Sinter Feed Pleito camiones | B12: 0 | C12: 0 | D12: 0.01
A13: Sinter Feed Infiernillo camiones | B13: 0 | C13: 0.6346 | D13: 0.01
... A45: Resguardo | B45: 1000 | C45: 0.6 | D45: 0.01

Sheet Flujos
B2: Mediciones | F2: Balance | J2: % Cambio relativo | M2: Max Var Ton | N2: Max Var FeT
B3: Flujos | C3: TMS | D3: %FeT | F3: Flujos | G3: TMS | H3: %FeT | J3: TMSD | K3: %Fe T
B4: Alim Mina | C4: =Utilidad!A1 -> 150420 | D4: =IF(Utilidad!C1>1,Utilidad!C1/100,Utilidad!C1) -> 0.2388 | F4: Alim Mina | G4: =Utilidad!B1 -> 150420 | H4: =IF(Utilidad!D1>1,Utilidad!D1/100,Utilidad!D1) -> 0.2388 | J4: =+IF(C4<>0,(G4-C4)/C4,ABS(G4-C4)) -> 0 | K4: =+IF(D4<>0,(H4-D4)/D4,0) -> 0 | M4: =+IF(J4<>"",ABS(J4),0) -> 0 | N4: =+IF(J4<>"",ABS(K4),0) -> 0
B5: Alim ML Pleito a CH-CM | C5: =Utilidad!A2 -> 0 | D5: =IF(Utilidad!C2>1,Utilidad!C2/100,Utilidad!C2) -> 0 | F5: Alim ML Pleito a CH-CM | G5: =Utilidad!B2 -> 0 | H5: =IF(Utilidad!D2>1,Utilidad!D2/100,Utilidad!D2) -> 0 | J5: =+IF(C5<>0,(G5-C5)/C5,ABS(G5-C5)) -> 0 | K5: =+IF(D5<>0,(H5-D5)/D5,0) -> 0 | M5: =+IF(J5<>"",ABS(J5),0) -> 0 | N5: =+IF(J5<>"",ABS(K5),0) -> 0
B6: Rechazos | C6: =Utilidad!A3 -> 60303 | D6: =IF(Utilidad!C3>1,Utilidad!C3/100,Utilidad!C3) -> 0.139 | F6: Rechazos | G6: =Utilidad!B3 -> 60303 | H6: =IF(Utilidad!D3>1,Utilidad!D3/100,Utilidad!D3) -> 0.13205 | J6: =+IF(C6<>0,(G6-C6)/C6,ABS(G6-C6)) -> 0 | K6: =+IF(D6<>0,(H6-D6)/D6,0) -> -0.05 | M6: =+IF(J6<>"",ABS(J6),0) -> 0 | N6: =+IF(J6<>"",ABS(K6),0) -> 0.05
B7: Producción CH a Stock Intermedio | C7: =Utilidad!A4 -> 90117 | D7: =IF(Utilidad!C4>1,Utilidad!C4/100,Utilidad!C4) -> 0.3055 | F7: Producción CH a Stock Intermedio | G7: =Utilidad!B4 -> 90117 | H7: =IF(Utilidad!D4>1,Utilidad!D4/100,Utilidad!D4) -> 0.3102332 | J7: =+IF(C7<>0,(G7-C7)/C7,ABS(G7-C7)) -> 0 | K7: =+IF(D7<>0,(H7-D7)/D7,0) -> 0.015493274 | M7: =+IF(J7<>"",ABS(J7),0) -> 0 | N7: =+IF(J7<>"",ABS(K7),0) -> 0.015493274
B8: Otros Materiales desde Pleito a Stock Intermedio | C8: =Utilidad!A5 -> 0 | D8: =IF(Utilidad!C5>1,Utilidad!C5/100,Utilidad!C5) -> 0 | F8: Otros Materiales desde Pleito a Stock Intermedio | G8: =Utilidad!B5 -> 0 | H8: =IF(Utilidad!D5>1,Utilidad!D5/100,Utilidad!D5) -> 0 | J8: =+IF(C8<>0,(G8-C8)/C8,ABS(G8-C8)) -> 0 | K8: =+IF(D8<>0,(H8-D8)/D8,0) -> 0 | M8: =+IF(J8<>"",ABS(J8),0) -> 0 | N8: =+IF(J8<>"",ABS(K8),0) -> 0
B9: Delta Stock Intermedio | C9: =Utilidad!A6 -> -28228 | D9: =IF(Utilidad!C6>1,Utilidad!C6/100,Utilidad!C6) -> 0.3055 | F9: Delta Stock Intermedio | G9: =Utilidad!B6 -> -34429.131 | H9: =IF(Utilidad!D6>1,Utilidad!D6/100,Utilidad!D6) -> 0.320775 | J9: =+IF(C9<>0,(G9-C9)/C9,ABS(G9-C9)) -> 0.21968013 | K9: =+IF(D9<>0,(H9-D9)/D9,0) -> 0.05 | M9: =+IF(J9<>"",ABS(J9),0) -> 0.21968013 | N9: =+IF(J9<>"",ABS(K9),0) -> 0.05 | Q9: =G10-G14-G15 -> 40331.403
B10: Alimentación a Concentradora | C10: =Utilidad!A7 -> 116673 | D10: =IF(Utilidad!C7>1,Utilidad!C7/100,Utilidad!C7) -> 0.3113 | F10: Alimentación a Concentradora | G10: =Utilidad!B7 -> 124546.13 | H10: =IF(Utilidad!D7>1,Utilidad!D7/100,Utilidad!D7) -> 0.31314734 | J10: =+IF(C10<>0,(G10-C10)/C10,ABS(G10-C10)) -> 0.067480314 | K10: =+IF(D10<>0,(H10-D10)/D10,0) -> 0.0059342684 | M10: =+IF(J10<>"",ABS(J10),0) -> 0.067480314 | N10: =+IF(J10<>"",ABS(K10),0) -> 0.0059342684 | Q10: =G13+G12 -> 40331.403
B11: By Pass Stock Intermedio a Stock Preconcentrado | C11: =Utilidad!A8 -> 0 | D11: =IF(Utilidad!C8>1,Utilidad!C8/100,Utilidad!C8) -> 0 | F11: By Pass Stock Intermedio a Stock Preconcentrado | G11: =Utilidad!B8 -> 0 | H11: =IF(Utilidad!D8>1,Utilidad!D8/100,Utilidad!D8) -> 0 | J11: =+IF(C11<>0,(G11-C11)/C11,ABS(G11-C11)) -> 0 | K11: =+IF(D11<>0,(H11-D11)/D11,0) -> 0 | M11: =+IF(J11<>"",ABS(J11),0) -> 0 | N11: =+IF(J11<>"",ABS(K11),0) -> 0
B12: Rechazo a Botadero | C12: =Utilidad!A9 -> 20214 | D12: =IF(Utilidad!C9>1,Utilidad!C9/100,Utilidad!C9) -> 0.2026 | F12: Rechazo a Botadero | G12: =Utilidad!B9 -> 24875.066 | H12: =IF(Utilidad!D9>1,Utilidad!D9/100,Utilidad!D9) -> 0.19247 | J12: =+IF(C12<>0,(G12-C12)/C12,ABS(G12-C12)) -> 0.23058605 | K12: =+IF(D12<>0,(H12-D12)/D12,0) -> -0.05 | M12: =+IF(J12<>"",ABS(J12),0) -> 0.23058605 | N12: =+IF(J12<>"",ABS(K12),0) -> 0.05
B13: Cola Concentradora (canoa) | C13: =Utilidad!A10 -> 11970 | D13: =IF(Utilidad!C10>1,Utilidad!C10/100,Utilidad!C10) -> 0.1143 | F13: Cola Concentradora (canoa) | G13: =Utilidad!B10 -> 15456.337 | H13: =IF(Utilidad!D10>1,Utilidad!D10/100,Utilidad!D10) -> 0.108585 | J13: =+IF(C13<>0,(G13-C13)/C13,ABS(G13-C13)) -> 0.2912562 | K13: =+IF(D13<>0,(H13-D13)/D13,0) -> -0.05 | M13: =+IF(J13<>"",ABS(J13),0) -> 0.2912562 | N13: =+IF(J13<>"",ABS(K13),0) -> 0.05
B14: Concentradora a Stock Preconcentrado | C14: =Utilidad!A11 -> 60996 | D14: =IF(Utilidad!C11>1,Utilidad!C11/100,Utilidad!C11) -> 0.366 | F14: Concentradora a Stock Preconcentrado | G14: =Utilidad!B11 -> 64047.728 | H14: =IF(Utilidad!D11>1,Utilidad!D11/100,Utilidad!D11) -> 0.35689666 | J14: =+IF(C14<>0,(G14-C14)/C14,ABS(G14-C14)) -> 0.050031602 | K14: =+IF(D14<>0,(H14-D14)/D14,0) -> -0.024872502 | M14: =+IF(J14<>"",ABS(J14),0) -> 0.050031602 | N14: =+IF(J14<>"",ABS(K14),0) -> 0.024872502
B15: SF a molienda | C15: =Utilidad!A12 -> 20167 | D15: =IF(Utilidad!C12>1,Utilidad!C12/100,Utilidad!C12) -> 0.4856 | F15: SF a molienda | G15: =Utilidad!B12 -> 20167 | H15: =IF(Utilidad!D12>1,Utilidad!D12/100,Utilidad!D12) -> 0.47983531 | J15: =+IF(C15<>0,(G15-C15)/C15,ABS(G15-C15)) -> 0 | K15: =+IF(D15<>0,(H15-D15)/D15,0) -> -0.011871271 | M15: =+IF(J15<>"",ABS(J15),0) -> 0 | N15: =+IF(J15<>"",ABS(K15),0) -> 0.011871271
B16: Repulpeo | C16: =Utilidad!A13 -> 1437 | D16: =IF(Utilidad!C13>1,Utilidad!C13/100,Utilidad!C13) -> 0.4975 | F16: Repulpeo | G16: =Utilidad!B13 -> 1437 | H16: =IF(Utilidad!D13>1,Utilidad!D13/100,Utilidad!D13) -> 0.49744624 | I16: =(G14*H14+G15*H15)/(G14+G15)*100 -> 38.633693 | J16: =+IF(C16<>0,(G16-C16)/C16,ABS(G16-C16)) -> 0 | K16: =+IF(D16<>0,(H16-D16)/D16,0) -> -0.00010806557 | M16: =+IF(J16<>"",ABS(J16),0) -> 0 | N16: =+IF(J16<>"",ABS(K16),0) -> 0.00010806557
B17: Delta Stock Preconcentrado | C17: =Utilidad!A14 -> 23352 | D17: =IF(Utilidad!C14>1,Utilidad!C14/100,Utilidad!C14) -> 0.4147 | F17: Delta Stock Preconcentrado | G17: =Utilidad!B14 -> 12216.728 | H17: =IF(Utilidad!D14>1,Utilidad!D14/100,Utilidad!D14) -> 0.393965 | J17: =+IF(C17<>0,(G17-C17)/C17,ABS(G17-C17)) -> -0.47684449 | K17: =+IF(D17<>0,(H17-D17)/D17,0) -> -0.05 | M17: =+IF(J17<>"",ABS(J17),0) -> 0.47684449 | N17: =+IF(J17<>"",ABS(K17),0) -> 0.05
B18: Alimentación Preconcentrado a Molienda | C18: =Utilidad!A15 -> 88249 | D18: =IF(Utilidad!C15>1,Utilidad!C15/100,Utilidad!C15) -> 0.4147 | F18: Alimentación Preconcentrado a Molienda | G18: =Utilidad!B15 -> 88249 | H18: =IF(Utilidad!D15>1,Utilidad!D15/100,Utilidad!D15) -> 0.41240586 | J18: =+IF(C18<>0,(G18-C18)/C18,ABS(G18-C18)) -> 0 | K18: =+IF(D18<>0,(H18-D18)/D18,0) -> -0.005532044 | M18: =+IF(J18<>"",ABS(J18),0) -> 0 | N18: =+IF(J18<>"",ABS(K18),0) -> 0.005532044
B19: Cola de Molienda | C19: =Utilidad!A16 -> 40418 | D19: =IF(Utilidad!C16>1,Utilidad!C16/100,Utilidad!C16) -> 0.0981 | F19: Cola de Molienda | G19: =Utilidad!B16 -> 43841 | H19: =IF(Utilidad!D16>1,Utilidad!D16/100,Utilidad!D16) -> 0.093195 | J19: =+IF(C19<>0,(G19-C19)/C19,ABS(G19-C19)) -> 0.08468999 | K19: =+IF(D19<>0,(H19-D19)/D19,0) -> -0.05 | M19: =+IF(J19<>"",ABS(J19),0) -> 0.08468999 | N19: =+IF(J19<>"",ABS(K19),0) -> 0.05
B20: Concentrado a Stock Pellet Feed ROM | C20: =Utilidad!A17 -> 66012 | D20: =IF(Utilidad!C17>1,Utilidad!C17/100,Utilidad!C17) -> 0.6505 | F20: Concentrado a Stock Pellet Feed ROM | G20: =Utilidad!B17 -> 66012 | H20: =IF(Utilidad!D17>1,Utilidad!D17/100,Utilidad!D17) -> 0.64685681 | J20: =+IF(C20<>0,(G20-C20)/C20,ABS(G20-C20)) -> 0 | K20: =+IF(D20<>0,(H20-D20)/D20,0) -> -0.0056005977 | M20: =+IF(J20<>"",ABS(J20),0) -> 0 | N20: =+IF(J20<>"",ABS(K20),0) -> 0.0056005977
B21: Delta Stock Pellet Feed ROM | C21: =Utilidad!A18 -> -5515 | D21: =IF(Utilidad!C18>1,Utilidad!C18/100,Utilidad!C18) -> 0.6505 | F21: Delta Stock Pellet Feed ROM | G21: =Utilidad!B18 -> -5099 | H21: =IF(Utilidad!D18>1,Utilidad!D18/100,Utilidad!D18) -> 0.683025 | J21: =+IF(C21<>0,(G21-C21)/C21,ABS(G21-C21)) -> -0.075430644 | K21: =+IF(D21<>0,(H21-D21)/D21,0) -> 0.05 | M21: =+IF(J21<>"",ABS(J21),0) -> 0.075430644 | N21: =+IF(J21<>"",ABS(K21),0) -> 0.05
B22: Transporte Pellet Feed en camiones a Guayacan | C22: =Utilidad!A19 -> 0 | D22: =IF(Utilidad!C19>1,Utilidad!C19/100,Utilidad!C19) -> 0 | F22: Transporte Pellet Feed en camiones a Guayacan | G22: =Utilidad!B19 -> 0 | H22: =IF(Utilidad!D19>1,Utilidad!D19/100,Utilidad!D19) -> 0 | J22: =+IF(C22<>0,(G22-C22)/C22,ABS(G22-C22)) -> 0 | K22: =+IF(D22<>0,(H22-D22)/D22,0) -> 0 | M22: =+IF(J22<>"",ABS(J22),0) -> 0 | N22: =+IF(J22<>"",ABS(K22),0) -> 0
B23: Transporte Pellet Feed en Trenes a Guayacan | C23: =Utilidad!A20 -> 71111 | D23: =IF(Utilidad!C20>1,Utilidad!C20/100,Utilidad!C20) -> 0.6509 | F23: Transporte Pellet Feed en Trenes a Guayacan | G23: =Utilidad!B20 -> 71111 | H23: =IF(Utilidad!D20>1,Utilidad!D20/100,Utilidad!D20) -> 0.64945024 | J23: =+IF(C23<>0,(G23-C23)/C23,ABS(G23-C23)) -> 0 | K23: =+IF(D23<>0,(H23-D23)/D23,0) -> -0.00222731 | M23: =+IF(J23<>"",ABS(J23),0) -> 0 | N23: =+IF(J23<>"",ABS(K23),0) -> 0.00222731
B24: Pérdidas Pellet Feed por Transporte | C24: =Utilidad!A21 -> 1422 | D24: =IF(Utilidad!C21>1,Utilidad!C21/100,Utilidad!C21) -> 0.6509 | F24: Pérdidas Pellet Feed por Transporte | G24: =Utilidad!B21 -> 1422 | H24: =IF(Utilidad!D21>1,Utilidad!D21/100,Utilidad!D21) -> 0.631373 | J24: =+IF(C24<>0,(G24-C24)/C24,ABS(G24-C24)) -> 0 | K24: =+IF(D24<>0,(H24-D24)/D24,0) -> -0.03 | M24: =+IF(J24<>"",ABS(J24),0) -> 0 | N24: =+IF(J24<>"",ABS(K24),0) -> 0.03
B25: Recepción total en Stock Pellet Feed Guayacan | C25: =Utilidad!A22 -> 69689 | D25: =IF(Utilidad!C22>1,Utilidad!C22/100,Utilidad!C22) -> 0.6509 | F25: Recepción total en Stock Pellet Feed Guayacan | G25: =Utilidad!B22 -> 69689 | H25: =IF(Utilidad!D22>1,Utilidad!D22/100,Utilidad!D22) -> 0.64981911 | J25: =+IF(C25<>0,(G25-C25)/C25,ABS(G25-C25)) -> 0 | K25: =+IF(D25<>0,(H25-D25)/D25,0) -> -0.0016606099 | M25: =+IF(J25<>"",ABS(J25),0) -> 0 | N25: =+IF(J25<>"",ABS(K25),0) -> 0.0016606099
B26: Delta Stock Pellet Feed Guayacan | C26: =Utilidad!A23 -> -2963 | D26: =IF(Utilidad!C23>1,Utilidad!C23/100,Utilidad!C23) -> 0.6509 | F26: Delta Stock Pellet Feed Guayacan | G26: =Utilidad!B23 -> -3438 | H26: =IF(Utilidad!D23>1,Utilidad!D23/100,Utilidad!D23) -> 0.683445 | J26: =+IF(C26<>0,(G26-C26)/C26,ABS(G26-C26)) -> 0.1603105 | K26: =+IF(D26<>0,(H26-D26)/D26,0) -> 0.05 | M26: =+IF(J26<>"",ABS(J26),0) -> 0.1603105 | N26: =+IF(J26<>"",ABS(K26),0) -> 0.05
B27: Embarque Pellet Feed Guayacan | C27: =Utilidad!A24 -> 73127 | D27: =IF(Utilidad!C24>1,Utilidad!C24/100,Utilidad!C24) -> 0.6514 | F27: Embarque Pellet Feed Guayacan | G27: =Utilidad!B24 -> 73127 | H27: =IF(Utilidad!D24>1,Utilidad!D24/100,Utilidad!D24) -> 0.6514 | J27: =+IF(C27<>0,(G27-C27)/C27,ABS(G27-C27)) -> 0 | K27: =+IF(D27<>0,(H27-D27)/D27,0) -> 0 | M27: =+IF(J27<>"",ABS(J27),0) -> 0 | N27: =+IF(J27<>"",ABS(K27),0) -> 0
B28: Transporte Camiones PF Guayacan | C28: =Utilidad!A25 -> 0 | D28: =IF(Utilidad!C25>1,Utilidad!C25/100,Utilidad!C25) -> 0 | F28: Transporte Camiones PF Guayacan | G28: =Utilidad!B25 -> 0 | H28: =IF(Utilidad!D25>1,Utilidad!D25/100,Utilidad!D25) -> 0 | J28: =+IF(C28<>0,(G28-C28)/C28,ABS(G28-C28)) -> 0 | K28: =+IF(D28<>0,(H28-D28)/D28,0) -> 0 | M28: =+IF(J28<>"",ABS(J28),0) -> 0 | N28: =+IF(J28<>"",ABS(K28),0) -> 0
... B70: Resguardo | C70: =Utilidad!A67 -> 0 | D70: =IF(Utilidad!C67>1,Utilidad!C67/100,Utilidad!C67) -> 0 | F70: Resguardo | G70: =Utilidad!B67 -> 0 | H70: =IF(Utilidad!D67>1,Utilidad!D67/100,Utilidad!D67) -> 0 | J70: =+IF(C70<>0,(G70-C70)/C70,ABS(G70-C70)) -> 0 | K70: =+IF(D70<>0,(H70-D70)/D70,0) -> 0 | M70: =+IF(J70<>"",ABS(J70),0) -> 0 | N70: =+IF(J70<>"",ABS(K70),0) -> 0

Sheet Mapa de Procesos
E6: =Flujos!G4 -> 150420
E7: =Flujos!H4 -> 0.2388 | I7: =+Utilidad!J65 -> 0 | L7: =+Utilidad!J68 -> 0 | Q7: =Flujos!G12 -> 24875.066
E8: =E6*E7 -> 35920.296 | I8: =+Utilidad!K65 -> 0 | L8: =+Utilidad!K68 -> 0 | Q8: =Flujos!H12 -> 0.19247
I9: =+Utilidad!L65 -> 0 | L9: =+Utilidad!L68 -> 0 | Q9: =Q7*Q8 -> 4787.704
E10: =+Utilidad!J63 -> 0
E11: =+Utilidad!K63 -> 0 | Q11: =+Utilidad!J71 -> 15456.337
C12: =+Utilidad!J101 -> 0 | E12: =+Utilidad!L63 -> 0 | Q12: =+Utilidad!K71 -> 0.108585
C13: =+Utilidad!K101 -> 0 | H13: =+Utilidad!J66 -> 0 | N13: =+Utilidad!J72 -> 64047.728 | Q13: =+Utilidad!L71 -> 1678.3263
C14: =+Utilidad!L101 -> 0 | H14: =+Utilidad!K66 -> 0 | J14: =+I7+H13-L14-L7 -> 0 | L14: =+Utilidad!J69 -> 0 | N14: =+Utilidad!K72 -> 0.35689666
G15: =Flujos!G6 -> 60303 | H15: =+Utilidad!L66 -> 0 | L15: =+Utilidad!K69 -> 0 | N15: =+Utilidad!L72 -> 22858.42
E16: =+C12-E10 -> 0 | G16: =Flujos!H6 -> 0.13205 | L16: =+Utilidad!L69 -> 0 | P16: Resguardo
G17: =G15*G16 -> 7963.0112 | P17: =Flujos!G70 -> 0
K18: =Flujos!C56 -> 37855 | P18: =Flujos!H70 -> 0
K19: =Flujos!D56 -> 0.5036 | P19: =P17*P18 -> 0
K20: =K18*K19 -> 19063.778 | L20: =+Utilidad!J76 -> 88249 | N20: =+L14+N13+K18-M22-L20 -> 12216.728
L22: =+Utilidad!K76 -> 0.41240586 | M22: =+Utilidad!J74 -> 1437 | O22: =+Utilidad!J73 -> 20167
L23: =+Utilidad!L76 -> 36394.405 | M23: =+Utilidad!K74 -> 0.49744624 | O23: =+Utilidad!K73 -> 0.47983531
M24: =+Utilidad!L74 -> 714.83024 | O24: =+Utilidad!L73 -> 9676.8387 | Q24: =+(O22+N13)/(L7) -> #DIV/0!
G25: =+Utilidad!J105 -> 0
C26: =+Utilidad!J103 -> 0 | G26: =+Utilidad!K105 -> 0
C27: =+Utilidad!K103 -> 0 | G27: =+Utilidad!L105 -> 0 | Q27: =+(K28)/(L20+M22+O22) -> 0.60091213
C28: =+Utilidad!L103 -> 0 | K28: =+Utilidad!J78 -> 66012
F29: =+C26-G25 -> 0 | K29: =+Utilidad!K78 -> 0.64685681 | M29: =K28/(L20+M22+O22) -> 0.60091213 | O29: =O22+L20+M22 -> 109853
I30: =+Utilidad!J77 -> 43841 | K30: =+Utilidad!L78 -> 42700.312 | O30: =O29-K28 -> 43841
I31: =+Utilidad!K77 -> 0.093195
I32: =I30*I31 -> 4085.762
G34: =+Utilidad!J108 -> 0
C35: =+Utilidad!J106 -> 0 | G35: =+Utilidad!K108 -> 0
C36: =+Utilidad!K106 -> 0 | G36: =+Utilidad!L108 -> 0
C37: =+Utilidad!L106 -> 0
F38: =+C35-G34 -> 0
K39: =K28-(I53+L53) -> -5099
C44: =+Utilidad!J109 -> 0 | G44: =+Utilidad!J111 -> 0
C45: =+Utilidad!K109 -> 0 | G45: =+Utilidad!K111 -> 0
C46: =+Utilidad!L109 -> 0 | G46: =+Utilidad!L111 -> 0
F48: =+C44-G44 -> 0
I53: =+Utilidad!J82 -> 1422 | L53: =+Utilidad!J83 -> 69689
C54: =+Utilidad!J112 -> 0 | I54: =+Utilidad!K82 -> 0.631373 | L54: =+Utilidad!K83 -> 0.64981911
C55: =+Utilidad!K112 -> 0 | I55: =+Utilidad!L82 -> 897.81241 | L55: =+Utilidad!L83 -> 45285.244
C56: =+Utilidad!L112 -> 0
...

Sheet Report
F3: BALANCE METALÚRGICO - VALLE ELQUI
F5: REPORTE MINAS EL ROMERAL | M5: FECHA DE BALANCE | P5: 45915
G8: TONELAJE | I8: LEY | J8: FINO | N8: TONELAJE | P8: LEY | Q8: FINO
G9: TMS | H9: TMH | I9: % FeT | J9: TMF | N9: TMS | O9: TMH | P9: % FeT | Q9: TMF
D10: ENTRADAS | K10: PRODUCCIÓN PRIMARIA
C11: FL_218_501_01 | D11: Alimentación Chancado Mina | G11: =Flujos!G4 -> 150420 | H11: =G11/(1-'Datos Extra'!D19) -> 150420 | I11: =Flujos!H4 -> 0.2388 | J11: =+I11*G11 -> 35920.296 | K11: Pellet Feed Producción Primaria | N11: =Flujos!G20 -> 66012 | O11: =N11/(1-'Datos Extra'!D29) -> 72276.176 | P11: =Flujos!H20 -> 0.64685681 | Q11: =+P11*N11 -> 42700.312
D12: Recepción Mediana Ley Pleito | G12: =Flujos!G5 -> 0 | H12: =G12/(1-'Datos Extra'!D20) -> 0 | I12: =Flujos!H5 -> 0 | J12: =+I12*G12 -> 0 | K12: PÉRDIDAS
D13: Materiales a Stock Intermedio | G13: =Flujos!G8 -> 0 | H13: =G13/(1-'Datos Extra'!D21) -> 0 | I13: =Flujos!H8 -> 0 | J13: =+I13*G13 -> 0 | K13: Rechazos a botadero Pta. Chancado | N13: =Flujos!G6 -> 60303 | O13: =N13*1/(1-'Datos Extra'!D36) -> 60303 | P13: =Flujos!H6 -> 0.13205 | Q13: =+P13*N13 -> 7963.0112
D14: Materiales a Stock Preconcentrado | G14: =Flujos!G55 -> 37855 | H14: =G14/(1-'Datos Extra'!D22) -> 38999.338 | I14: =Flujos!H55 -> 0.5036 | J14: =+I14*G14 -> 19063.778 | K14: Rechazos a botadero Pta. Concentradora | N14: =Flujos!G12 -> 24875.066 | O14: =N14/(1-'Datos Extra'!D37) -> 26967.765 | P14: =Flujos!H12 -> 0.19247 | Q14: =+P14*N14 -> 4787.704
D15: Sinter Feed a Patio Tolva | G15: =Flujos!G31 -> 0 | H15: =G15*'Datos Extra'!D23+Report!G15 -> 0 | I15: =Flujos!H31 -> 0 | J15: =+I15*G15 -> 0 | K15: Colas Pta. Concentradora | N15: =Flujos!G13 -> 15456.337 | P15: =Flujos!H13 -> 0.108585 | Q15: =+P15*N15 -> 1678.3263
K16: Colas Pta. Molienda | N16: =Flujos!G19 -> 43841 | P16: =Flujos!H19 -> 0.093195 | Q16: =+P16*N16 -> 4085.762
C19: FL_000_501_03 | D19: TOTAL | G19: =+SUM(G11:G15) -> 188275 | H19: =+SUM(H11:H15) -> 189419.34 | J19: =+SUM(J11:J15) -> 54984.074 | K19: TOTAL | N19: =+SUM(N13:N16) -> 144475.4 | O19: =+SUM(O13:O16) -> 87270.765 | Q19: =+SUM(Q13:Q16) -> 18514.804
D20: EMBARQUES - VENTAS LOCALES | K20: PRODUCCIÓN PUESTA EN PUERTO
D21: Pellet Feed | G21: ='Mapa de Procesos'!P102 -> 73127 | H21: =G21/(1-'Datos Extra'!D24) -> 80030.424 | I21: =Flujos!H27 -> 0.6514 | J21: =+I21*G21 -> 47634.928 | K21: Pellet Feed Acopiado (Trenes) | N21: =Flujos!G25 -> 69689 | O21: =N21/(1-'Datos Extra'!D28) -> 76766.628 | P21: =Flujos!H25 -> 0.64981911 | Q21: =+P21*N21 -> 45285.244
D22: Sinter | G22: =Flujos!G33 -> 0 | H22: =G22/(1-'Datos Extra'!D25) -> 0 | I22: =Flujos!H33 -> 0 | J22: =+I22*G22 -> 0 | K22: Sinter Feed MLC (camiones) | N22: =Flujos!G35 -> 0 | O22: =N22/(1-'Datos Extra'!D31) -> 0 | P22: =Flujos!H35 -> 0 | Q22: =+P22*N22 -> 0
D23: Granzas | G23: =Flujos!G40 -> 0 | H23: =G23/(1-'Datos Extra'!D26) -> 0 | I23: =Flujos!H40 -> 0 | J23: =+I23*G23 -> 0 | K23: Sinter Feed Pleito (camiones) | N23: =Flujos!G36 -> 0 | O23: =N23/(1-'Datos Extra'!D32) -> 0 | P23: =Flujos!H36 -> 0 | Q23: =+P23*N23 -> 0
D24: Pellet Feed camiones locales | G24: =Flujos!G58 -> 0 | H24: =G24/(1-'Datos Extra'!D42) -> 0 | I24: =Flujos!H58 -> 0 | J24: =G24*I24 -> 0 | K24: Sinter Feed APC (camiones) | N24: =Flujos!G57 -> 3157 | O24: =N24/(1-'Datos Extra'!D40) -> 3185.0282 | P24: =Flujos!H57 -> 0.6346 | Q24: =+P24*N24 -> 2003.4322
D25: Preconcentrado Ventas | G25: =Flujos!G68 -> 0 | H25: =G25/(1-'Datos Extra'!D29) -> 0 | I25: =Flujos!H68 -> 0 | J25: =G25*I25 -> 0 | K25: Sinter Feed Caro (camiones) | N25: =Flujos!G60 -> 3069 | O25: =N25/(1-'Datos Extra'!D41) -> 3108.4777 | P25: =Flujos!H60 -> 0.63 | Q25: =+P25*N25 -> 1933.47
K26: Sinter SERCOOP (camiones) | N26: =Flujos!G66 -> 0 | O26: =N26/(1-'Datos Extra'!D42) -> 0 | P26: =Flujos!H66 -> 0 | Q26: =+P26*N26 -> 0
K27: Sinter Santa Fe (camiones) | N27: =Flujos!G67 -> 0 | O27: =N27/(1-'Datos Extra'!D43) -> 0 | P27: =Flujos!H67 -> 0 | Q27: =+P27*N27 -> 0
K28: Preconcentrado Ventas | N28: =Flujos!G65 -> 0 | O28: =N28/(1-'Datos Extra'!D42) -> 0 | P28: =Flujos!H65 -> 0 | Q28: =+P28*N28 -> 0
K29: Granzas Pleito | N29: =Flujos!G37 -> 0 | O29: =N29/(1-'Datos Extra'!D34) -> 0 | P29: =Flujos!H37 -> 0 | Q29: =+P29*N29 -> 0
K30: Granzas Cristales | N30: =Flujos!G38 -> 0 | O30: =N30/(1-'Datos Extra'!D35) -> 0 | P30: =Flujos!H38 -> 0 | Q30: =+P30*N30 -> 0
D32: TOTAL | G32: =+SUM(G21:G24) -> 73127 | H32: =+SUM(H21:H24) -> 80030.424 | J32: =+SUM(J21:J24) -> 47634.928 | K32: TOTAL | N32: =SUM(N21:N30) -> 75915 | O32: =SUM(O21:O30) -> 83060.134 | Q32: =SUM(Q21:Q30) -> 49222.146
D34: INVENTARIOS
G35: TMH | H35: TMS | I35: Delta inventario TMS | J35: Delta inventario TMF
D36: Stock Intermedio | G36: ='Datos Extra'!B2 -> 11665 | H36: =G36*(1-'Datos Extra'!D2) -> 11548.35 | I36: =Flujos!G9 -> -34429.131 | J36: ='Mapa de Procesos'!L128 -> -11044.004
D37: Stock Preconcentrado | G37: ='Datos Extra'!B3 -> 32218.642 | H37: =G37*(1-'Datos Extra'!D3) -> 31896.455 | I37: =Flujos!G17 -> 12216.728 | J37: ='Mapa de Procesos'!L129 -> 4812.9631 | M37: ENTRADAS | N37: SALIDAS | O37: DELTA INVENTARIO | P37: BALANCE
D38: Stock Pellet Feed | G38: ='Datos Extra'!B4 -> 33 | H38: =G38*(1-'Datos Extra'!D4) -> 30.0487 | I38: =Flujos!G21 -> -5099 | J38: ='Mapa de Procesos'!L131 -> -3482.7445 | L38: TMS | M38: =G19+N22+N23+N24+N29+N30 -> 191432 | N38: =G21+G22+G23+N19+G24 -> 217602.4 | O38: =I43 -> -24523.403 | P38: =M38-N38-O38 -> -1647
D39: Stock Sinter Feed Patio Tolva | G39: ='Datos Extra'!B5 -> 0 | H39: =G39*(1-'Datos Extra'!D5) -> 0 | I39: =Flujos!G31 -> 0 | J39: ='Mapa de Procesos'!L132 -> 0 | L39: TMF | M39: =J19+Q22+Q23+Q24+Q29+Q30 -> 56987.506 | N39: =Q19+J21+J22+J23+J24 -> 66149.731 | O39: =J43 -> -8126.5675 | P39: =M39-N39-O39 -> -1035.6576
D40: Stock Pellet Feed Guayacán | G40: ='Datos Extra'!B6 -> 108658.53 | H40: =G40*(1-'Datos Extra'!D6) -> 98640.574 | I40: =Flujos!G26 -> -3438 | J40: ='Mapa de Procesos'!L138 -> -2349.6839
D41: Stock Sinter Guayacán | G41: ='Datos Extra'!B7 -> 60226.45 | H41: =G41*(1-'Datos Extra'!D7) -> 60226.45 | I41: =Flujos!G34 -> 6226 | J41: ='Mapa de Procesos'!L139 -> 3936.9022
D42: Stock Granza Guayacán | G42: ='Datos Extra'!B8 -> 64802 | H42: =G42*(1-'Datos Extra'!D8) -> 64802 | I42: =Flujos!G39 -> 0 | J42: ='Mapa de Procesos'!L140 -> 0
D43: Stock Preconcentrado Ventas | G43: ='Datos Extra'!B9 -> 71110.958 | H43: =G43*(1-'Datos Extra'!D9) -> 70399.848 | I43: =SUM(I36:I42) -> -24523.403 | J43: =SUM(J36:J42) -> -8126.5675
