Workbook

Sheet Resumen MLC
F2: BALANCE METALÚRGICO - VALLE HUASCO
F4: REPORTE DE MINA LOS COLORADOS | M4: FECHA DE BALANCE | P4: 46065
G7: TONELAJE | H7: TONELAJE | I7: LEY | J7: FINO | N7: TONELAJE | O7: TONELAJE | P7: LEY | Q7: FINO
G8: TMH | H8: TMS | I8: % FeT | J8: TMF | N8: TMH | O8: TMS | P8: % FeT | Q8: TMF
D9: ENTRADAS | K9: PRODUCCIÓN
C10: FL_218_501_01 | D10: Mineral hacia CH° Primario | G10: ='Diag Proc Los Colorados'!K3 -> 448636 | H10: =Utilidad!M40 -> 443431.82 | I10: =Utilidad!N40 -> 0.509697 | J10: =+H10*I10 -> 226015.87 | K10: Producto a Partir de Mineral | N10: =O10/(1-'Datos Extra'!E11) -> 310847.21 | O10: =Utilidad!M52 -> 307241.38 | P10: =Utilidad!N52 -> 0.60297908 | Q10: =+O10*P10 -> 185260.12
D11: Mineral hacia Planta de Beneficio | G11: =H11/(1-1.1%) -> 421288.31 | H11: =Flujos!G12 -> 416654.14 | I11: =Flujos!H12 -> 0.51006524 | J11: =+H11*I11 -> 212520.8 | K11: Producto a Partir de Preconcentrado | N11: 0 | O11: 0 | P11: 0 | Q11: =+O11*P11 -> 0
D12: Material hacia Planta de Rechazos | G12: ='Diag Proc Los Colorados'!K33 -> 147345.53 | H12: =Utilidad!M58 -> 145592.12 | I12: =Utilidad!N58 -> 0.21705979 | J12: =+H12*I12 -> 31602.194 | K12: Preconcentrado P45 | N12: =O12/(1-'Datos Extra'!E12) -> 0 | O12: ='Datos Extra'!B10 -> 0 | P12: =Utilidad!N60 -> 0.47504338 | Q12: =+O12*P12 -> 0
C13: FL_000_501_03 | D13: TOTAL | K13: TOTAL | N13: =SUM(N10:N12) -> 310847.21 | O13: =SUM(O10:O12) -> 307241.38 | P13: =+Q13/O13 -> 0.60297908 | Q13: =SUM(Q10:Q12) -> 185260.12
D14: TRANSPORTE | K14: PÉRDIDAS
D15: Preconcentrado hacia Planta de Pellets | G15: ='Datos Extra'!B1 -> 311847.36 | H15: ='Datos Extra'!C1 -> 311815.9 | I15: ='Datos Extra'!D1 -> 0.60972389 | J15: =H15*I15 -> 190121.6 | K15: Rechazos Finales | N15: =O15/(1-'Datos Extra'!E9) -> 116724.13 | O15: ='Diag Proc Los Colorados'!S28 -> 115335.12 | P15: ='Diag Proc Los Colorados'!S29 -> 0.14938041 | Q15: ='Diag Proc Los Colorados'!S30 -> 17228.806
D16: Sinter Feed hacia Planta de Pellets | G16: ='Datos Extra'!B2 -> 0 | H16: ='Datos Extra'!C2 -> 0 | I16: ='Datos Extra'!D2 -> 0 | J16: =H16*I16 -> 0 | K16: TOTAL | N16: =SUM(N14:N15) -> 116724.13 | O16: =SUM(O15) -> 115335.12 | P16: =+P15 -> 0.14938041 | Q16: =SUM(Q15) -> 17228.806
D17: P45 hacia Valle Copiapó | G17: ='Datos Extra'!B3 -> 14566.66 | H17: ='Datos Extra'!C3 -> 14565.203 | I17: ='Datos Extra'!D3 -> 0.4735 | J17: =H17*I17 -> 6896.6238
D18: Preconcentrado hacia Valle Copiapo | G18: ='Datos Extra'!B4 -> 26475.29 | H18: ='Datos Extra'!C4 -> 26473.172 | I18: ='Datos Extra'!D4 -> 0.6042 | J18: =H18*I18 -> 15995.091
D19: Sinter Feed hacia Valle Copiapo | G19: ='Datos Extra'!B5 -> 5017.45 | H19: ='Datos Extra'!C5 -> 5017.149 | I19: ='Datos Extra'!D5 -> 0.6296 | J19: =H19*I19 -> 3158.797
D20: P45 hacia Valle Elqui | G20: ='Datos Extra'!B6 -> 18139.79 | H20: ='Datos Extra'!C6 -> 18138.219 | I20: ='Datos Extra'!D6 -> 0.4795 | J20: =H20*I20 -> 8697.2761
D21: Preconcentrado hacia Valle Elqui | G21: ='Datos Extra'!B7 -> 27832.44 | H21: ='Datos Extra'!C7 -> 27830.213 | I21: ='Datos Extra'!D7 -> 0.5992 | J21: =H21*I21 -> 16675.864 | L21: 24218.025 | M21: 66344 | O21: 2100.8663
D22: Sinter Feed hacia Valle Elqui | G22: ='Datos Extra'!B8 -> 4410.46 | H22: ='Datos Extra'!C8 -> 4410.0781 | I22: ='Datos Extra'!D8 -> 0.6219 | J22: =H22*I22 -> 2742.6275 | O22: 2100.8663
D23: TOTAL | G23: =+SUM(G15:G22) -> 408289.45 | H23: =+SUM(H15:H22) -> 408249.93 | I23: =+J23/H23 -> 0.59837825 | J23: =+SUM(J15:J22) -> 244287.88 | N23: 471219.06 | O23: 2100.8663
D25: INVENTARIOS
C26: INV_501_01 | D26: Preconcentrado en Acopios Mina
D27: Sinter Feed 62 en Acopios Mina
D28: Sinter Feed 65 en Acopios Mina
D29: Preconcentrado en Pila Producto
D30: Sinter Feed en Pila Producto
D31: Preconcentrado P40 en Planta Rechazos
D32: TOTAL
D34: INDICADORES PLANTA BENEFICIO LOS COLORADOS
D36: RP LEY PLANTA BENEFICIO | K36: RECUPERACIÓN METALÚRGICA PLANTA BENEFICIO
D37: =(Flujos!H12-Flujos!H17)/(Flujos!H16-Flujos!H17) -> 0.73740147 | K37: ='Diag Proc Los Colorados'!Q55 -> 0.87172704
D39: RP MASA PLANTA BENEFICIO
D40: ='Diag Proc Los Colorados'!Q54 -> 0.73740147
F43: Reporte KPI | G43: Balance | H43: Delta | I43: %
E44: Mineral hacia Chancado | G44: =G10 -> 448636 | H44: =G44-F44 -> 448636 | I44: =IF(F44>0,H44/F44,0) -> 0
E45: Alim Planta | G45: 459737.27 | H45: =G45-F45 -> 459737.27 | I45: =IF(F45>0,H45/F45,0) -> 0
E46: Prod P.Ben | G46: =N10 -> 310847.21 | H46: =G46-F46 -> 310847.21 | I46: =IF(F46>0,H46/F46,0) -> 0
E47: Alim Planta Rechazo | G47: =G12 -> 147345.53 | H47: =G47-F47 -> 147345.53 | I47: =IF(F47>0,H47/F47,0) -> 0
E48: Torre 1 | H48: =G48-F48 -> 0 | I48: =IF(F48>0,H48/F48,0) -> 0
E49: Torre 2 [Recirculación] | H49: =G49-F49 -> 0 | I49: =IF(F49>0,H49/F49,0) -> 0
E50: Torre 2 [Acopio] | H50: =G50-F50 -> 0 | I50: =IF(F50>0,H50/F50,0) -> 0
...

Sheet Tabla Entrega
E5: Proporcion
D6: Producción | E6: SF | F6: Basico
D7: ='Datos Extra'!B27 -> 100 | E7: =100-F7 -> 100 | F7: ='Datos Extra'!B28 -> 0
C8: Ingresar leyes | D8: FeT | E8: 0 | F8: 61.19
D11: Datos balance
D12: TMH | E12: %Fe T | F12: %Hum | G12: TMS
C13: Alimentación Mina | D13: ='Datos Extra'!B17 -> 420796 | E13: ='Datos Extra'!C17 -> 0.50969692 | F13: ='Datos Extra'!D17 -> 0.0116 | G13: ='Datos Extra'!E17 -> 415914.77
C14: Alim Plantas (alim A52 y A82) | D14: ='Datos Extra'!B18 -> 309330 | E14: ='Datos Extra'!C18 -> 0.61191143 | F14: ='Datos Extra'!D18 -> 0.0116 | G14: ='Datos Extra'!E18 -> 305741.77
C15: Producción Plantas | D15: ='Datos Extra'!B19 -> 309330 | E15: ='Datos Extra'!C19 -> 0.6119 | F15: ='Datos Extra'!D19 -> 0.0116 | G15: ='Datos Extra'!E19 -> 305741.77
C16: Producción Básico (A52 + A82) | D16: ='Datos Extra'!B20 -> 0 | E16: ='Datos Extra'!C20 -> 0 | F16: ='Datos Extra'!D20 -> 0 | G16: ='Datos Extra'!E20 -> 0
C17: Producción Sinter Feed (A52 + A82) | D17: ='Datos Extra'!B21 -> 0 | E17: ='Datos Extra'!C21 -> 0 | F17: ='Datos Extra'!D21 -> 0 | G17: ='Datos Extra'!E21 -> 0
C18: Alimentación Planta Rechazo + RUMO | D18: ='Datos Extra'!B22 -> 0 | E18: ='Datos Extra'!C22 -> 0 | F18: ='Datos Extra'!D22 -> 0 | G18: ='Datos Extra'!E22 -> 0
C19: Producción Planta Rechazo + RUMO | D19: ='Datos Extra'!B23 -> 148804 | E19: ='Datos Extra'!C23 -> 0.20043924 | F19: ='Datos Extra'!D23 -> 0.0119 | G19: ='Datos Extra'!E23 -> 147033.23
C20: Alimentación Planta Rechazo | D20: ='Datos Extra'!B24 -> 27533 | E20: ='Datos Extra'!C24 -> 0.47780174 | F20: ='Datos Extra'!D24 -> 0.01 | G20: ='Datos Extra'!E24 -> 27257.67
C21: Producción Planta Rechazo | D21: ='Datos Extra'!B25 -> 0 | E21: ='Datos Extra'!C25 -> 0 | F21: ='Datos Extra'!D25 -> 0 | G21: ='Datos Extra'!E25 -> 0

Sheet Utilidad
A1: 443431.82 | B1: 443431.82 | C1: 50.9697 | D1: 50.9697 | E1: 1.16 | Z1: =+'Diag Proc Los Colorados'!S8 -> 69486.681
A2: 0 | B2: 0 | C2: 0 | D2: 0 | E2: 0
A3: 35392.021 | B3: 35392.021 | C3: 60.8098 | D3: 60.97474 | E3: 0.78002819
A4: -19882.418 | B4: -20101.563 | C4: 61.2859 | D4: 61.190717 | E4: 1.0089156
A5: 443431.82 | B5: 443431.82 | C5: 50.9697 | D5: 50.9697 | E5: 1.16
A6: 0 | B6: 0 | C6: 0 | D6: 0 | E6: 0
A7: 448636 | B7: 443431.82 | C7: 50.9697 | D7: 50.9697 | E7: 0
A8: 27558.333 | B8: 26777.681 | C8: 50.9697 | D8: 50.396721 | E8: 1.0117361
A9: 415914.77 | B9: 416654.14 | C9: 50.9697 | D9: 51.006524 | E9: 1.16
A10: 15427.958 | B10: 15290.458 | C10: 61.1911 | D10: 60.690808 | E10: 1.0089156
A11: -40663.143 | B11: -42531.584 | C11: 59.1737 | D11: 60.289161 | E11: 1.0089156
A12: 30820.423 | B12: 30820.423 | C12: 53.4454 | D12: 53.4454 | E12: 0.90763688
A13: 305741.77 | B13: 307241.38 | C13: 61.1911 | D13: 60.297908 | E13: 1.16
... A31: 0 | B31: 0 | C31: 0 | D31: 0 | E31: 0
M38: Valores Calculados
M39: TMS | N39: %FeT | O39: TMF Fe
M40: =B1 -> 443431.82 | N40: =IF(D1>1,D1/100,D1) -> 0.509697 | O40: =M40*N40 -> 226015.87
M41: =B2 -> 0 | N41: =IF(D2>1,D2/100,D2) -> 0 | O41: =M41*N41 -> 0
M42: =B3 -> 35392.021 | N42: =IF(D3>1,D3/100,D3) -> 0.6097474 | O42: =M42*N42 -> 21580.193
M43: =B4 -> -20101.563 | N43: =IF(D4>1,D4/100,D4) -> 0.61190717 | O43: =M43*N43 -> -12300.29
M44: =B5 -> 443431.82 | N44: =IF(D5>1,D5/100,D5) -> 0.509697 | O44: =M44*N44 -> 226015.87
M45: =B6 -> 0 | N45: =IF(D6>1,D6/100,D6) -> 0 | O45: =M45*N45 -> 0
M46: =B7 -> 443431.82 | N46: =IF(D7>1,D7/100,D7) -> 0.509697 | O46: =M46*N46 -> 226015.87
M47: =B8 -> 26777.681 | N47: =IF(D8>1,D8/100,D8) -> 0.50396721 | O47: =M47*N47 -> 13495.073
M48: =B9 -> 416654.14 | N48: =IF(D9>1,D9/100,D9) -> 0.51006524 | O48: =M48*N48 -> 212520.8
M49: =B10 -> 15290.458 | N49: =IF(D10>1,D10/100,D10) -> 0.60690808 | O49: =M49*N49 -> 9279.9025
M50: =B11 -> -42531.584 | N50: =IF(D11>1,D11/100,D11) -> 0.60289161 | O50: =M50*N50 -> -25641.935
M51: =B12 -> 30820.423 | N51: =IF(D12>1,D12/100,D12) -> 0.534454 | O51: =M51*N51 -> 16472.099
... M70: =B31 -> 0 | N70: =IF(D31>1,D31/100,D31) -> 0 | O70: =M70*N70 -> 0

Sheet Datos Extra
A1: Preconcentrado hacia Planta de Pellets | B1: 311847.36 | C1: 311815.9 | D1: 0.60972389 | E1: 0.010089156
A2: Sinter Feed hacia Planta de Pellets | B2: 0 | C2: 0 | D2: 0 | E2: 0
A3: P45 hacia Valle Copiapó | B3: 14566.66 | C3: 14565.203 | D3: 0.4735 | E3: 0.01
A4: Preconcentrado hacia Valle Copiapo | B4: 26475.29 | C4: 26473.172 | D4: 0.6042 | E4: 0.008
A5: Sinter Feed hacia Valle Copiapo | B5: 5017.45 | C5: 5017.149 | D5: 0.6296 | E5: 0.006
A6: P45 hacia Valle Elqui | B6: 18139.79 | C6: 18138.219 | D6: 0.4795 | E6: 0.00866
A7: Preconcentrado hacia Valle Elqui | B7: 27832.44 | C7: 27830.213 | D7: 0.5992 | E7: 0.008
A8: Sinter Feed hacia Valle Elqui | B8: 4410.46 | C8: 4410.0781 | D8: 0.6219 | E8: 0.00866
A9: Rechazos Finales | B9: 141299 | C9: 141282.19 | D9: 0.15128995 | E9: 0.0119
A10: Planta Movil | B10: 0 | C10: 0 | D10: 0 | E10: 0
A11: Producto a Partir de Mineral | B11: 309330 | C11: 309294.12 | D11: 0.61191143 | E11: 0.0116
A12: Preconcentrado P45 | B12: 0 | C12: 0 | D12: 0.47780174 | E12: 0.01
... A14: Alimentación Planta Rechazo | B14: 0 | C14: 0 | D14: 0.20043924 | E14: 0.0119
A15: Tabla Entrega
A16: Alimentación Mina | B16: 448636 | C16: 0.50969692 | D16: 0.0116 | E16: 443431.82
A17: Alim Plantas (alim A52 y A82) | B17: 420796 | C17: 0.50969692 | D17: 0.0116 | E17: 415914.77
A18: Producción Plantas | B18: 309330 | C18: 0.61191143 | D18: 0.0116 | E18: 305741.77
A19: Producción Básico (A52 + A82) | B19: 309330 | C19: 0.6119 | D19: 0.0116 | E19: 305741.77
A20: Producción Sinter Feed (A52 + A82) | B20: 0 | C20: 0 | D20: 0 | E20: 0
A21: Alimentación Planta Rechazo + RUMO | B21: 0 | C21: 0 | D21: 0 | E21: 0
A22: Producción Planta Rechazo + RUMO | B22: 0 | C22: 0 | D22: 0 | E22: 0
A23: Alimentación Planta Rechazo | B23: 148804 | C23: 0.20043924 | D23: 0.0119 | E23: 147033.23
A24: Producción Planta Rechazo | B24: 27533 | C24: 0.47780174 | D24: 0.01 | E24: 27257.67
A25: Balance Mes
A26: Producción | B26: 309330
A27: Básico | B27: 100
A28: SF | B28: 0

Sheet Flujos
B2: Mediciones | F2: Balance | J2: % Cambio relativo | M2: Max Var Ton | N2: Max Var FeT
B3: Flujos | C3: TMS | D3: %FeT | F3: Flujos | G3: TMS | H3: %FeT | J3: TMSD | K3: %Fe T
B4: Alimentación Mina | C4: =Utilidad!A1 -> 443431.82 | D4: =IF(Utilidad!C1>1,Utilidad!C1/100,Utilidad!C1) -> 0.509697 | F4: Alimentación Mina | G4: =Utilidad!B1 -> 443431.82 | H4: =IF(Utilidad!D1>1,Utilidad!D1/100,Utilidad!D1) -> 0.509697 | J4: =+IF(C4<>0,(G4-C4)/C4,ABS(G4-C4)) -> 0 | K4: =+IF(D4<>0,(H4-D4)/D4,0) -> 0 | M4: =+IF(J4<>"",ABS(J4),0) -> 0 | N4: =+IF(J4<>"",ABS(K4),0) -> 0
B5: Alim a Planta desde Acopio Mina | C5: =Utilidad!A2 -> 0 | D5: =IF(Utilidad!C2>1,Utilidad!C2/100,Utilidad!C2) -> 0 | F5: Alim a Planta desde Acopio Mina | G5: =Utilidad!B2 -> 0 | H5: =IF(Utilidad!D2>1,Utilidad!D2/100,Utilidad!D2) -> 0 | J5: =+IF(C5<>0,(G5-C5)/C5,ABS(G5-C5)) -> 0 | K5: =+IF(D5<>0,(H5-D5)/D5,0) -> 0 | M5: =+IF(J5<>"",ABS(J5),0) -> 0 | N5: =+IF(J5<>"",ABS(K5),0) -> 0
B6: Acopio Mina a Terceros | C6: =Utilidad!A3 -> 35392.021 | D6: =IF(Utilidad!C3>1,Utilidad!C3/100,Utilidad!C3) -> 0.608098 | F6: Acopio Mina a Terceros | G6: =Utilidad!B3 -> 35392.021 | H6: =IF(Utilidad!D3>1,Utilidad!D3/100,Utilidad!D3) -> 0.6097474 | J6: =+IF(C6<>0,(G6-C6)/C6,ABS(G6-C6)) -> 1.0409227e-11 | K6: =+IF(D6<>0,(H6-D6)/D6,0) -> 0.0027123971 | M6: =+IF(J6<>"",ABS(J6),0) -> 1.0409227e-11 | N6: =+IF(J6<>"",ABS(K6),0) -> 0.0027123971
B7: Delta S Acopio Mina | C7: =Utilidad!A4 -> -19882.418 | D7: =IF(Utilidad!C4>1,Utilidad!C4/100,Utilidad!C4) -> 0.612859 | F7: Delta S Acopio Mina | G7: =Utilidad!B4 -> -20101.563 | H7: =IF(Utilidad!D4>1,Utilidad!D4/100,Utilidad!D4) -> 0.61190717 | J7: =+IF(C7<>0,(G7-C7)/C7,ABS(G7-C7)) -> 0.011022057 | K7: =+IF(D7<>0,(H7-D7)/D7,0) -> -0.0015531029 | M7: =+IF(J7<>"",ABS(J7),0) -> 0.011022057 | N7: =+IF(J7<>"",ABS(K7),0) -> 0.0015531029
B8: Alim a Chancado | C8: =Utilidad!A5 -> 443431.82 | D8: =IF(Utilidad!C5>1,Utilidad!C5/100,Utilidad!C5) -> 0.509697 | F8: Alim a Chancado | G8: =Utilidad!B5 -> 443431.82 | H8: =IF(Utilidad!D5>1,Utilidad!D5/100,Utilidad!D5) -> 0.509697 | J8: =+IF(C8<>0,(G8-C8)/C8,ABS(G8-C8)) -> 0 | K8: =+IF(D8<>0,(H8-D8)/D8,0) -> 0 | M8: =+IF(J8<>"",ABS(J8),0) -> 0 | N8: =+IF(J8<>"",ABS(K8),0) -> 0
B9: Chanc a Stock Prec Los Col. | C9: =Utilidad!A6 -> 0 | D9: =IF(Utilidad!C6>1,Utilidad!C6/100,Utilidad!C6) -> 0 | F9: Chanc a Stock Prec Los Col. | G9: =Utilidad!B6 -> 0 | H9: =IF(Utilidad!D6>1,Utilidad!D6/100,Utilidad!D6) -> 0 | J9: =+IF(C9<>0,(G9-C9)/C9,ABS(G9-C9)) -> 0 | K9: =+IF(D9<>0,(H9-D9)/D9,0) -> 0 | M9: =+IF(J9<>"",ABS(J9),0) -> 0 | N9: =+IF(J9<>"",ABS(K9),0) -> 0
B10: Chanc a Stock Grueso | C10: =Utilidad!A7 -> 448636 | D10: =IF(Utilidad!C7>1,Utilidad!C7/100,Utilidad!C7) -> 0.509697 | F10: Chanc a Stock Grueso | G10: =Utilidad!B7 -> 443431.82 | H10: =IF(Utilidad!D7>1,Utilidad!D7/100,Utilidad!D7) -> 0.509697 | J10: =+IF(C10<>0,(G10-C10)/C10,ABS(G10-C10)) -> -0.0116 | K10: =+IF(D10<>0,(H10-D10)/D10,0) -> 0 | M10: =+IF(J10<>"",ABS(J10),0) -> 0.0116 | N10: =+IF(J10<>"",ABS(K10),0) -> 0
B11: Delta Stock de Grueso | C11: =Utilidad!A8 -> 27558.333 | D11: =IF(Utilidad!C8>1,Utilidad!C8/100,Utilidad!C8) -> 0.509697 | F11: Delta Stock de Grueso | G11: =Utilidad!B8 -> 26777.681 | H11: =IF(Utilidad!D8>1,Utilidad!D8/100,Utilidad!D8) -> 0.50396721 | J11: =+IF(C11<>0,(G11-C11)/C11,ABS(G11-C11)) -> -0.028327236 | K11: =+IF(D11<>0,(H11-D11)/D11,0) -> -0.011241566 | M11: =+IF(J11<>"",ABS(J11),0) -> 0.028327236 | N11: =+IF(J11<>"",ABS(K11),0) -> 0.011241566
B12: De Stock Grueso a conc magn (alim A52 y A82) | C12: =Utilidad!A9 -> 415914.77 | D12: =IF(Utilidad!C9>1,Utilidad!C9/100,Utilidad!C9) -> 0.509697 | F12: De Stock Grueso a conc magn (alim A52 y A82) | G12: =Utilidad!B9 -> 416654.14 | H12: =IF(Utilidad!D9>1,Utilidad!D9/100,Utilidad!D9) -> 0.51006524 | J12: =+IF(C12<>0,(G12-C12)/C12,ABS(G12-C12)) -> 0.0017777074 | K12: =+IF(D12<>0,(H12-D12)/D12,0) -> 0.00072247696 | M12: =+IF(J12<>"",ABS(J12),0) -> 0.0017777074 | N12: =+IF(J12<>"",ABS(K12),0) -> 0.00072247696
B13: Stock Prec a (o desde) Acopio Mina | C13: =Utilidad!A10 -> 15427.958 | D13: =IF(Utilidad!C10>1,Utilidad!C10/100,Utilidad!C10) -> 0.611911 | F13: Stock Prec a (o desde) Acopio Mina | G13: =Utilidad!B10 -> 15290.458 | H13: =IF(Utilidad!D10>1,Utilidad!D10/100,Utilidad!D10) -> 0.60690808 | J13: =+IF(C13<>0,(G13-C13)/C13,ABS(G13-C13)) -> -0.0089124185 | K13: =+IF(D13<>0,(H13-D13)/D13,0) -> -0.0081758991 | M13: =+IF(J13<>"",ABS(J13),0) -> 0.0089124185 | N13: =+IF(J13<>"",ABS(K13),0) -> 0.0081758991
B14: Delta Stock Prec | C14: =Utilidad!A11 -> -40663.143 | D14: =IF(Utilidad!C11>1,Utilidad!C11/100,Utilidad!C11) -> 0.591737 | F14: Delta Stock Prec | G14: =Utilidad!B11 -> -42531.584 | H14: =IF(Utilidad!D11>1,Utilidad!D11/100,Utilidad!D11) -> 0.60289161 | J14: =+IF(C14<>0,(G14-C14)/C14,ABS(G14-C14)) -> 0.045949255 | K14: =+IF(D14<>0,(H14-D14)/D14,0) -> 0.018850613 | M14: =+IF(J14<>"",ABS(J14),0) -> 0.045949255 | N14: =+IF(J14<>"",ABS(K14),0) -> 0.018850613
B15: de Stock Prec a Terceros (a otras faenas) | C15: =Utilidad!A12 -> 30820.423 | D15: =IF(Utilidad!C12>1,Utilidad!C12/100,Utilidad!C12) -> 0.534454 | F15: de Stock Prec a Terceros (a otras faenas) | G15: =Utilidad!B12 -> 30820.423 | H15: =IF(Utilidad!D12>1,Utilidad!D12/100,Utilidad!D12) -> 0.534454 | J15: =+IF(C15<>0,(G15-C15)/C15,ABS(G15-C15)) -> -1.1161666e-12 | K15: =+IF(D15<>0,(H15-D15)/D15,0) -> 0 | M15: =+IF(J15<>"",ABS(J15),0) -> 1.1161666e-12 | N15: =+IF(J15<>"",ABS(K15),0) -> 0
... B34: Venta RUMO en camiones | C34: =Utilidad!A31 -> 0 | D34: =IF(Utilidad!C31>1,Utilidad!C31/100,Utilidad!C31) -> 0 | F34: Venta RUMO en camiones | G34: =Utilidad!B31 -> 0 | H34: =IF(Utilidad!D31>1,Utilidad!D31/100,Utilidad!D31) -> 0 | J34: =+IF(C34<>0,(G34-C34)/C34,ABS(G34-C34)) -> 0 | K34: =+IF(D34<>0,(H34-D34)/D34,0) -> 0 | M34: =+IF(J34<>"",ABS(J34),0) -> 0 | N34: =+IF(J34<>"",ABS(K34),0) -> 0

Sheet Diag Proc Los Colorados
J3: TMH CH primario | K3: =+I6/(1-'Datos Extra'!E13) -> 448636 | L3: =+K4/K3 -> 1.4296401
J4: TMH CH dispach | K4: 641388 | L4: =1-L3 -> -0.42964006
K5: =+K3-K4 -> -192752 | P5: Delta Stock Pila Primaria | S5: =J19 -> 26777.681
F6: =+Utilidad!M41 -> 0 | I6: =+Utilidad!M40+W7 -> 443431.82
E7: =+-C8+D16-F6 -> -20101.563 | F7: =+Utilidad!N41 -> 0 | I7: =+Utilidad!N40 -> 0.509697 | P7: Stock inicial | S7: 42709
C8: =+Utilidad!M42 -> 35392.021 | E8: =+E9/E7 -> 0.61190717 | F8: =+Utilidad!O41 -> 0 | I8: =+Utilidad!O40+W8 -> 226015.87 | P8: Stock final | S8: =+S7+S5 -> 69486.681
C9: =+Utilidad!N42 -> 0.6097474 | E9: =+-C10+D18-F8 -> -12300.29
C10: =+Utilidad!O42 -> 21580.193
J11: =+Utilidad!M46+W7 -> 443431.82
H12: =+Utilidad!M44+W7 -> 443431.82 | J12: =+Utilidad!N46 -> 0.509697
H13: =+Utilidad!N44 -> 0.509697 | J13: =+Utilidad!O46+W8 -> 226015.87
H14: =+Utilidad!O44+W8 -> 226015.87
M15: =+Utilidad!M54 -> 18816.826
D16: =+Utilidad!M49 -> 15290.458 | M16: =+Utilidad!N54 -> 0.22521766
D17: =+Utilidad!N49 -> 0.60690808 | M17: =+Utilidad!O54 -> 4237.8815
D18: =+Utilidad!O49 -> 9279.9025 | R18: =P24+M32-O35-S30 -> 2.5933332e-07
J19: =+J11-K20 -> 26777.681
K20: =+Utilidad!M48 -> 416654.14 | O20: =+M15-P22 -> -36179.352
K21: =+Utilidad!N48 -> 0.51006524 | O21: =+O22/O20 -> 0.12
K22: =+Utilidad!O48 -> 212520.8 | O22: =+M17-P24 -> -4341.5222 | P22: =+Utilidad!M57 -> 54996.178 | Q22: =+P22-L29 -> 54996.178
P23: =+Utilidad!N57 -> 0.156
P24: =+Utilidad!O57 -> 8579.4038
I25: =+Utilidad!M52 -> 307241.38 | L25: =+Utilidad!M53 -> 109412.76 | S25: =S28+O33-P22-M30 -> 9.9999306e-07
I26: =+Utilidad!N52 -> 0.60297908 | L26: =Utilidad!N53 -> 0.2491544
G27: =+I25-C28-G36-D16+F45 -> -13499.381 | I27: =+Utilidad!O52 -> 185260.12 | L27: =L25*L26 -> 27260.672
C28: =+Utilidad!M51 -> 30820.423 | G28: =+G29/G27 -> 0.59319571 | S28: =+Utilidad!M59 -> 115335.12
C29: =+Utilidad!N51 -> 0.534454 | G29: =+I27-C30-G38-D18+F47 -> -8007.7749 | L29: =+L25-L30 -> 9.9999306e-07 | S29: =+Utilidad!N59 -> 0.14938041
C30: =+Utilidad!O51 -> 16472.099 | L30: =+M30+M15 -> 109412.76 | M30: =+Utilidad!M55 -> 90595.937 | S30: =+Utilidad!O59 -> 17228.806
L31: =+M30+L29 -> 90595.937 | M31: =+Utilidad!N55 -> 0.25412608
I32: =(I27-K22)/L25 -> -0.2491544 | K32: TMH Rechazos | M32: =+Utilidad!O55 -> 23022.79
K33: =+K34/(1-'Datos Extra'!E14) -> 147345.53 | O33: =+Utilidad!M60 -> 30257
I34: =(I27+L27-K22)/L25 -> 3.4129438e-11 | K34: =+M30+P22 -> 145592.12 | O34: =+Utilidad!N60 -> 0.47504338
K35: =+K36/K34 -> 0.21705979 | O35: =+Utilidad!O60 -> 14373.388
G36: =+Utilidad!M63 -> 303662.08 | K36: =+M32+P24 -> 31602.194 | S36: =+Utilidad!M62 -> 32379.386
G37: =+Utilidad!N63 -> 0.609724 | S37: =+Utilidad!N62 -> 0.476828
G38: =+Utilidad!O63 -> 185150.06 | J38: =I27+L27-K22 -> 3.7341961e-06 | S38: =+Utilidad!O62 -> 15439.398
P40: =+Utilidad!M61 -> -2122.3855
K41: =K22-L27-I27 -> -3.7341961e-06 | P41: =+P42/P40 -> 0.50226972
P42: =+Utilidad!O61 -> -1066.01
E44: Stock inicial | F44: 29287 | H44: Stock inicial A55 | I44: 42000 | R44: Stock inicial P45 | S44: 2218
...

Sheet Bal Fet Pta Pellets
K3: Nodo Alim Stock Planta Pellet | L3: Stock prec Planta de Pellet | M3: Stock Silos de Molienda | N3: Molienda Clasificación | O3: TK Inventarios | P3: Filtrado | Q3: Nodo Producto Filtrado | R3: Stock Pila Intermedia | S3: Stock Pellet Feed | T3: Balling | U3: Endurecimiento Térmico | V3: Stock Derrames | W3: Pila de Emergencia | X3: Harnero Pruducto | Y3: Stock Chunk | Z3: Stock Chip Fresco | AA3: Planta Re-Harneo | AB3: Stock Pellet Básico | AC3: Stock Finos Huasco | AD3: Stock Pellet Chip | AE3: Stock Sinter Feed | AF3: Nodo Alimentaciones Embarque | AI3: {=+TRANSPOSE(J3:AF58)} -> 0 | AJ3: De Prec Los Colorados Nodo Alim Planta de Pellet | AK3: Preconc Los Colorados a Stock Sinter Feed | AL3: Prec los Colorados a Stock Prec Planta Pellet | AM3: Re-Harneo a Stock Prec Planta Pellet | AN3: Delta Stock Prec Planta Pellet | AO3: Alim Silos Molienda | AP3: Delta Stock Silos Molienda | AQ3: Aliment Molienda Clasificación | AR3: De Molienda/clasificación a Stock Derrames | AS3: EMISARIO SUBMARINO | AT3: Alimentación a TK Inventarios | AU3: Delta TK inventarios | AV3: TK Inventario a Stock Derrames | AW3: Alimentación Filtrado | AX3: Alim Nodo Productos Filtrados | AY3: De filtros a Balling | AZ3: Filtrado a Stock Derrames | BA3: Alim Pila Intermedia desde (de nodo post filtros) | BB3: Delta Stock Pila Intermedia | BC3: de Pila Intermedia a Balling | BD3: de Pila Intermadia a Stok Pellet Feed | BE3: a Stock Pellet Feed (de nodo post filtros) | BF3: Delta Stock Pellet Feed | BG3: A embarque de Stock Pellet Feed | BH3: Aditivo a Balling | BI3: Pellet verde a edurecimiento | BJ3: Endurecimiento a Stock Derrames | BK3: Delta Inventarios de Derrames | BL3: Chunk de endurecimiento a Pila Chunk | BM3: Delta Stock Pila Chunk | BN3: Aporte Oxidación Endurecimiento | BO3: Alim endurecido a Pila Emergencia | BP3: De endurecimiento a Harnero Producto | BQ3: Alim Harnero Producto desde Pila de Emergencia | BR3: Delta Stock Pila Emergencia | BS3: De harnero Producto a Pila Chip Fresco | BT3: Delta Stock Pila Chip Fresco | BU3: De Harnero Producto a Stock Pellets Básico | BV3: Delta Stock Pellet Básico | BW3: A embarque desde Pellet básico | BX3: Alimentación Chip Fresco a Re harneo | BY3: Alimentación de Stock de Derrames a Planta de Re Harneo | BZ3: Alimentación de Pila Chunk a Re Harneo | CA3: Intermedio Re harneo de derrames a Stock Pila de Emergencia | CB3: Alimentación Total a Stock Finos Huasco de Embarque | CC3: Chip Bajo tamaño de Re Harneo a Stock P Chip de Embarque | CD3: Traspaso de F Huasco a S Feed | CE3: A embarque desde Stock Finos Huasco | CF3: Delta Stock Finos Huasco | CG3: A embarque desde Stock Sinter Feed | CH3: Delta Stock Sinter Feed | CI3: Traspaso de P Chip a P Básico | CJ3: A embarque desde Stock Pellet Chip | CK3: Delta Stock Pellet Chip | CL3: Total Embarcado
I4: 1 | J4: De Prec Los Colorados Nodo Alim Planta de Pellet | K4: 1 | L4: 0 | M4: 0 | N4: 0 | O4: 0 | P4: 0 | Q4: 0 | R4: 0 | S4: 0 | T4: 0 | U4: 0 | V4: 0 | W4: 0 | X4: 0 | Y4: 0 | Z4: 0 | AA4: 0 | AB4: 0 | AC4: 0 | AD4: 0 | AE4: 0 | AF4: 0 | AI4: Nodo Alim Stock Planta Pellet | AJ4: 1 | AK4: -1 | AL4: -1 | AM4: 0 | AN4: 0 | AO4: 0 | AP4: 0 | AQ4: 0 | AR4: 0 | AS4: 0 | AT4: 0 | AU4: 0 | AV4: 0 | AW4: 0 | AX4: 0 | AY4: 0 | AZ4: 0 | BA4: 0 | BB4: 0 | BC4: 0 | BD4: 0 | BE4: 0 | BF4: 0 | BG4: 0 | BH4: 0 | BI4: 0 | BJ4: 0 | BK4: 0 | BL4: 0 | BM4: 0 | BN4: 0 | BO4: 0 | BP4: 0 | BQ4: 0 | BR4: 0 | BS4: 0 | BT4: 0 | BU4: 0 | BV4: 0 | BW4: 0 | BX4: 0 | BY4: 0 | BZ4: 0 | CA4: 0 | CB4: 0 | CC4: 0 | CD4: 0 | CE4: 0 | CF4: 0 | CG4: 0 | CH4: 0 | CI4: 0 | CJ4: 0 | CK4: 0 | CL4: 0
I5: 2 | J5: Preconc Los Colorados a Stock Sinter Feed | K5: -1 | L5: 0 | M5: 0 | N5: 0 | O5: 0 | P5: 0 | Q5: 0 | R5: 0 | S5: 0 | T5: 0 | U5: 0 | V5: 0 | W5: 0 | X5: 0 | Y5: 0 | Z5: 0 | AA5: 0 | AB5: 0 | AC5: 0 | AD5: 0 | AE5: 1 | AF5: 0 | AI5: Stock prec Planta de Pellet | AJ5: 0 | AK5: 0 | AL5: 1 | AM5: 1 | AN5: #REF! | AO5: -1 | AP5: 0 | AQ5: 0 | AR5: 0 | AS5: 0 | AT5: 0 | AU5: 0 | AV5: 0 | AW5: 0 | AX5: 0 | AY5: 0 | AZ5: 0 | BA5: 0 | BB5: 0 | BC5: 0 | BD5: 0 | BE5: 0 | BF5: 0 | BG5: 0 | BH5: 0 | BI5: 0 | BJ5: 0 | BK5: 0 | BL5: 0 | BM5: 0 | BN5: 0 | BO5: 0 | BP5: 0 | BQ5: 0 | BR5: 0 | BS5: 0 | BT5: 0 | BU5: 0 | BV5: 0 | BW5: 0 | BX5: 0 | BY5: 0 | BZ5: 0 | CA5: 0 | CB5: 0 | CC5: 0 | CD5: 0 | CE5: 0 | CF5: 0 | CG5: 0 | CH5: 0 | CI5: 0 | CJ5: 0 | CK5: 0 | CL5: 0
I6: 3 | J6: Prec los Colorados a Stock Prec Planta Pellet | K6: -1 | L6: 1 | M6: 0 | N6: 0 | O6: 0 | P6: 0 | Q6: 0 | R6: 0 | S6: 0 | T6: 0 | U6: 0 | V6: 0 | W6: 0 | X6: 0 | Y6: 0 | Z6: 0 | AA6: 0 | AB6: 0 | AC6: 0 | AD6: 0 | AE6: 0 | AF6: 0 | AI6: Stock Silos de Molienda | AJ6: 0 | AK6: 0 | AL6: 0 | AM6: 0 | AN6: 0 | AO6: 1 | AP6: #REF! | AQ6: -1 | AR6: 0 | AS6: 0 | AT6: 0 | AU6: 0 | AV6: 0 | AW6: 0 | AX6: 0 | AY6: 0 | AZ6: 0 | BA6: 0 | BB6: 0 | BC6: 0 | BD6: 0 | BE6: 0 | BF6: 0 | BG6: 0 | BH6: 0 | BI6: 0 | BJ6: 0 | BK6: 0 | BL6: 0 | BM6: 0 | BN6: 0 | BO6: 0 | BP6: 0 | BQ6: 0 | BR6: 0 | BS6: 0 | BT6: 0 | BU6: 0 | BV6: 0 | BW6: 0 | BX6: 0 | BY6: 0 | BZ6: 0 | CA6: 0 | CB6: 0 | CC6: 0 | CD6: 0 | CE6: 0 | CF6: 0 | CG6: 0 | CH6: 0 | CI6: 0 | CJ6: 0 | CK6: 0 | CL6: 0
I7: 4 | J7: Re-Harneo a Stock Prec Planta Pellet | K7: 0 | L7: 1 | M7: 0 | N7: 0 | O7: 0 | P7: 0 | Q7: 0 | R7: 0 | S7: 0 | T7: 0 | U7: 0 | V7: 0 | W7: 0 | X7: 0 | Y7: 0 | Z7: 0 | AA7: -1 | AB7: 0 | AC7: 0 | AD7: 0 | AE7: 0 | AF7: 0 | AI7: Molienda Clasificación | AJ7: 0 | AK7: 0 | AL7: 0 | AM7: 0 | AN7: 0 | AO7: 0 | AP7: 0 | AQ7: 1 | AR7: -1 | AS7: -1 | AT7: -1 | AU7: 0 | AV7: 0 | AW7: 0 | AX7: 0 | AY7: 0 | AZ7: 0 | BA7: 0 | BB7: 0 | BC7: 0 | BD7: 0 | BE7: 0 | BF7: 0 | BG7: 0 | BH7: 0 | BI7: 0 | BJ7: 0 | BK7: 0 | BL7: 0 | BM7: 0 | BN7: 0 | BO7: 0 | BP7: 0 | BQ7: 0 | BR7: 0 | BS7: 0 | BT7: 0 | BU7: 0 | BV7: 0 | BW7: 0 | BX7: 0 | BY7: 0 | BZ7: 0 | CA7: 0 | CB7: 0 | CC7: 0 | CD7: 0 | CE7: 0 | CF7: 0 | CG7: 0 | CH7: 0 | CI7: 0 | CJ7: 0 | CK7: 0 | CL7: 0
I8: 5 | J8: Delta Stock Prec Planta Pellet | K8: 0 | L8: =+#REF! -> #REF! | M8: 0 | N8: 0 | O8: 0 | P8: 0 | Q8: 0 | R8: 0 | S8: 0 | T8: 0 | U8: 0 | V8: 0 | W8: 0 | X8: 0 | Y8: 0 | Z8: 0 | AA8: 0 | AB8: 0 | AC8: 0 | AD8: 0 | AE8: 0 | AF8: 0 | AI8: TK Inventarios | AJ8: 0 | AK8: 0 | AL8: 0 | AM8: 0 | AN8: 0 | AO8: 0 | AP8: 0 | AQ8: 0 | AR8: 0 | AS8: 0 | AT8: 1 | AU8: #REF! | AV8: -1 | AW8: -1 | AX8: 0 | AY8: 0 | AZ8: 0 | BA8: 0 | BB8: 0 | BC8: 0 | BD8: 0 | BE8: 0 | BF8: 0 | BG8: 0 | BH8: 0 | BI8: 0 | BJ8: 0 | BK8: 0 | BL8: 0 | BM8: 0 | BN8: 0 | BO8: 0 | BP8: 0 | BQ8: 0 | BR8: 0 | BS8: 0 | BT8: 0 | BU8: 0 | BV8: 0 | BW8: 0 | BX8: 0 | BY8: 0 | BZ8: 0 | CA8: 0 | CB8: 0 | CC8: 0 | CD8: 0 | CE8: 0 | CF8: 0 | CG8: 0 | CH8: 0 | CI8: 0 | CJ8: 0 | CK8: 0 | CL8: 0
I9: 6 | J9: Alim Silos Molienda | K9: 0 | L9: -1 | M9: 1 | N9: 0 | O9: 0 | P9: 0 | Q9: 0 | R9: 0 | S9: 0 | T9: 0 | U9: 0 | V9: 0 | W9: 0 | X9: 0 | Y9: 0 | Z9: 0 | AA9: 0 | AB9: 0 | AC9: 0 | AD9: 0 | AE9: 0 | AF9: 0 | AI9: Filtrado | AJ9: 0 | AK9: 0 | AL9: 0 | AM9: 0 | AN9: 0 | AO9: 0 | AP9: 0 | AQ9: 0 | AR9: 0 | AS9: 0 | AT9: 0 | AU9: 0 | AV9: 0 | AW9: 1 | AX9: -1 | AY9: -1 | AZ9: -1 | BA9: 0 | BB9: 0 | BC9: 0 | BD9: 0 | BE9: 0 | BF9: 0 | BG9: 0 | BH9: 0 | BI9: 0 | BJ9: 0 | BK9: 0 | BL9: 0 | BM9: 0 | BN9: 0 | BO9: 0 | BP9: 0 | BQ9: 0 | BR9: 0 | BS9: 0 | BT9: 0 | BU9: 0 | BV9: 0 | BW9: 0 | BX9: 0 | BY9: 0 | BZ9: 0 | CA9: 0 | CB9: 0 | CC9: 0 | CD9: 0 | CE9: 0 | CF9: 0 | CG9: 0 | CH9: 0 | CI9: 0 | CJ9: 0 | CK9: 0 | CL9: 0
I10: 7 | J10: Delta Stock Silos Molienda | K10: 0 | L10: 0 | M10: =+#REF! -> #REF! | N10: 0 | O10: 0 | P10: 0 | Q10: 0 | R10: 0 | S10: 0 | T10: 0 | U10: 0 | V10: 0 | W10: 0 | X10: 0 | Y10: 0 | Z10: 0 | AA10: 0 | AB10: 0 | AC10: 0 | AD10: 0 | AE10: 0 | AF10: 0 | AI10: Nodo Producto Filtrado | AJ10: 0 | AK10: 0 | AL10: 0 | AM10: 0 | AN10: 0 | AO10: 0 | AP10: 0 | AQ10: 0 | AR10: 0 | AS10: 0 | AT10: 0 | AU10: 0 | AV10: 0 | AW10: 0 | AX10: 1 | AY10: 0 | AZ10: 0 | BA10: -1 | BB10: 0 | BC10: 0 | BD10: 0 | BE10: -1 | BF10: 0 | BG10: 0 | BH10: 0 | BI10: 0 | BJ10: 0 | BK10: 0 | BL10: 0 | BM10: 0 | BN10: 0 | BO10: 0 | BP10: 0 | BQ10: 0 | BR10: 0 | BS10: 0 | BT10: 0 | BU10: 0 | BV10: 0 | BW10: 0 | BX10: 0 | BY10: 0 | BZ10: 0 | CA10: 0 | CB10: 0 | CC10: 0 | CD10: 0 | CE10: 0 | CF10: 0 | CG10: 0 | CH10: 0 | CI10: 0 | CJ10: 0 | CK10: 0 | CL10: 0
I11: 8 | J11: Aliment Molienda Clasificación | K11: 0 | L11: 0 | M11: -1 | N11: 1 | O11: 0 | P11: 0 | Q11: 0 | R11: 0 | S11: 0 | T11: 0 | U11: 0 | V11: 0 | W11: 0 | X11: 0 | Y11: 0 | Z11: 0 | AA11: 0 | AB11: 0 | AC11: 0 | AD11: 0 | AE11: 0 | AF11: 0 | AI11: Stock Pila Intermedia | AJ11: 0 | AK11: 0 | AL11: 0 | AM11: 0 | AN11: 0 | AO11: 0 | AP11: 0 | AQ11: 0 | AR11: 0 | AS11: 0 | AT11: 0 | AU11: 0 | AV11: 0 | AW11: 0 | AX11: 0 | AY11: 0 | AZ11: 0 | BA11: 1 | BB11: #REF! | BC11: -1 | BD11: -1 | BE11: 0 | BF11: 0 | BG11: 0 | BH11: 0 | BI11: 0 | BJ11: 0 | BK11: 0 | BL11: 0 | BM11: 0 | BN11: 0 | BO11: 0 | BP11: 0 | BQ11: 0 | BR11: 0 | BS11: 0 | BT11: 0 | BU11: 0 | BV11: 0 | BW11: 0 | BX11: 0 | BY11: 0 | BZ11: 0 | CA11: 0 | CB11: 0 | CC11: 0 | CD11: 0 | CE11: 0 | CF11: 0 | CG11: 0 | CH11: 0 | CI11: 0 | CJ11: 0 | CK11: 0 | CL11: 0
I12: 9 | J12: De Molienda/clasificación a Stock Derrames | K12: 0 | L12: 0 | M12: 0 | N12: -1 | O12: 0 | P12: 0 | Q12: 0 | R12: 0 | S12: 0 | T12: 0 | U12: 0 | V12: 1 | W12: 0 | X12: 0 | Y12: 0 | Z12: 0 | AA12: 0 | AB12: 0 | AC12: 0 | AD12: 0 | AE12: 0 | AF12: 0 | AI12: Stock Pellet Feed | AJ12: 0 | AK12: 0 | AL12: 0 | AM12: 0 | AN12: 0 | AO12: 0 | AP12: 0 | AQ12: 0 | AR12: 0 | AS12: 0 | AT12: 0 | AU12: 0 | AV12: 0 | AW12: 0 | AX12: 0 | AY12: 0 | AZ12: 0 | BA12: 0 | BB12: 0 | BC12: 0 | BD12: 1 | BE12: 1 | BF12: #REF! | BG12: -1 | BH12: 0 | BI12: 0 | BJ12: 0 | BK12: 0 | BL12: 0 | BM12: 0 | BN12: 0 | BO12: 0 | BP12: 0 | BQ12: 0 | BR12: 0 | BS12: 0 | BT12: 0 | BU12: 0 | BV12: 0 | BW12: 0 | BX12: 0 | BY12: 0 | BZ12: 0 | CA12: 0 | CB12: 0 | CC12: 0 | CD12: 0 | CE12: 0 | CF12: 0 | CG12: 0 | CH12: 0 | CI12: 0 | CJ12: 0 | CK12: 0 | CL12: 0
I13: 10 | J13: EMISARIO SUBMARINO | K13: 0 | L13: 0 | M13: 0 | N13: -1 | O13: 0 | P13: 0 | Q13: 0 | R13: 0 | S13: 0 | T13: 0 | U13: 0 | V13: 0 | W13: 0 | X13: 0 | Y13: 0 | Z13: 0 | AA13: 0 | AB13: 0 | AC13: 0 | AD13: 0 | AE13: 0 | AF13: 0 | AI13: Balling | AJ13: 0 | AK13: 0 | AL13: 0 | AM13: 0 | AN13: 0 | AO13: 0 | AP13: 0 | AQ13: 0 | AR13: 0 | AS13: 0 | AT13: 0 | AU13: 0 | AV13: 0 | AW13: 0 | AX13: 0 | AY13: 1 | AZ13: 0 | BA13: 0 | BB13: 0 | BC13: 1 | BD13: 0 | BE13: 0 | BF13: 0 | BG13: 0 | BH13: 1 | BI13: -1 | BJ13: 0 | BK13: 0 | BL13: 0 | BM13: 0 | BN13: 0 | BO13: 0 | BP13: 0 | BQ13: 0 | BR13: 0 | BS13: 0 | BT13: 0 | BU13: 0 | BV13: 0 | BW13: 0 | BX13: 0 | BY13: 0 | BZ13: 0 | CA13: 0 | CB13: 0 | CC13: 0 | CD13: 0 | CE13: 0 | CF13: 0 | CG13: 0 | CH13: 0 | CI13: 0 | CJ13: 0 | CK13: 0 | CL13: 0
I14: 11 | J14: Alimentación a TK Inventarios | K14: 0 | L14: 0 | M14: 0 | N14: -1 | O14: 1 | P14: 0 | Q14: 0 | R14: 0 | S14: 0 | T14: 0 | U14: 0 | V14: 0 | W14: 0 | X14: 0 | Y14: 0 | Z14: 0 | AA14: 0 | AB14: 0 | AC14: 0 | AD14: 0 | AE14: 0 | AF14: 0 | AI14: Endurecimiento Térmico | AJ14: 0 | AK14: 0 | AL14: 0 | AM14: 0 | AN14: 0 | AO14: 0 | AP14: 0 | AQ14: 0 | AR14: 0 | AS14: 0 | AT14: 0 | AU14: 0 | AV14: 0 | AW14: 0 | AX14: 0 | AY14: 0 | AZ14: 0 | BA14: 0 | BB14: 0 | BC14: 0 | BD14: 0 | BE14: 0 | BF14: 0 | BG14: 0 | BH14: 0 | BI14: 1 | BJ14: -1 | BK14: 0 | BL14: -1 | BM14: 0 | BN14: 1 | BO14: -1 | BP14: -1 | BQ14: 0 | BR14: 0 | BS14: 0 | BT14: 0 | BU14: 0 | BV14: 0 | BW14: 0 | BX14: 0 | BY14: 0 | BZ14: 0 | CA14: 0 | CB14: 0 | CC14: 0 | CD14: 0 | CE14: 0 | CF14: 0 | CG14: 0 | CH14: 0 | CI14: 0 | CJ14: 0 | CK14: 0 | CL14: 0
I15: 12 | J15: Delta TK inventarios | K15: 0 | L15: 0 | M15: 0 | N15: 0 | O15: =+#REF! -> #REF! | P15: 0 | Q15: 0 | R15: 0 | S15: 0 | T15: 0 | U15: 0 | V15: 0 | W15: 0 | X15: 0 | Y15: 0 | Z15: 0 | AA15: 0 | AB15: 0 | AC15: 0 | AD15: 0 | AE15: 0 | AF15: 0 | AI15: Stock Derrames | AJ15: 0 | AK15: 0 | AL15: 0 | AM15: 0 | AN15: 0 | AO15: 0 | AP15: 0 | AQ15: 0 | AR15: 1 | AS15: 0 | AT15: 0 | AU15: 0 | AV15: 1 | AW15: 0 | AX15: 0 | AY15: 0 | AZ15: 1 | BA15: 0 | BB15: 0 | BC15: 0 | BD15: 0 | BE15: 0 | BF15: 0 | BG15: 0 | BH15: 0 | BI15: 0 | BJ15: 1 | BK15: #REF! | BL15: 0 | BM15: 0 | BN15: 0 | BO15: 0 | BP15: 0 | BQ15: 0 | BR15: 0 | BS15: 0 | BT15: 0 | BU15: 0 | BV15: 0 | BW15: 0 | BX15: 0 | BY15: -1 | BZ15: 0 | CA15: 0 | CB15: 0 | CC15: 0 | CD15: 0 | CE15: 0 | CF15: 0 | CG15: 0 | CH15: 0 | CI15: 0 | CJ15: 0 | CK15: 0 | CL15: 0
I16: 13 | J16: TK Inventario a Stock Derrames | K16: 0 | L16: 0 | M16: 0 | N16: 0 | O16: -1 | P16: 0 | Q16: 0 | R16: 0 | S16: 0 | T16: 0 | U16: 0 | V16: 1 | W16: 0 | X16: 0 | Y16: 0 | Z16: 0 | AA16: 0 | AB16: 0 | AC16: 0 | AD16: 0 | AE16: 0 | AF16: 0 | AI16: Pila de Emergencia | AJ16: 0 | AK16: 0 | AL16: 0 | AM16: 0 | AN16: 0 | AO16: 0 | AP16: 0 | AQ16: 0 | AR16: 0 | AS16: 0 | AT16: 0 | AU16: 0 | AV16: 0 | AW16: 0 | AX16: 0 | AY16: 0 | AZ16: 0 | BA16: 0 | BB16: 0 | BC16: 0 | BD16: 0 | BE16: 0 | BF16: 0 | BG16: 0 | BH16: 0 | BI16: 0 | BJ16: 0 | BK16: 0 | BL16: 0 | BM16: 0 | BN16: 0 | BO16: 1 | BP16: 0 | BQ16: -1 | BR16: #REF! | BS16: 0 | BT16: 0 | BU16: 0 | BV16: 0 | BW16: 0 | BX16: 0 | BY16: 0 | BZ16: 0 | CA16: 1 | CB16: 0 | CC16: 0 | CD16: 0 | CE16: 0 | CF16: 0 | CG16: 0 | CH16: 0 | CI16: 0 | CJ16: 0 | CK16: 0 | CL16: 0
I17: 14 | J17: Alimentación Filtrado | K17: 0 | L17: 0 | M17: 0 | N17: 0 | O17: -1 | P17: 1 | Q17: 0 | R17: 0 | S17: 0 | T17: 0 | U17: 0 | V17: 0 | W17: 0 | X17: 0 | Y17: 0 | Z17: 0 | AA17: 0 | AB17: 0 | AC17: 0 | AD17: 0 | AE17: 0 | AF17: 0 | AI17: Harnero Pruducto | AJ17: 0 | AK17: 0 | AL17: 0 | AM17: 0 | AN17: 0 | AO17: 0 | AP17: 0 | AQ17: 0 | AR17: 0 | AS17: 0 | AT17: 0 | AU17: 0 | AV17: 0 | AW17: 0 | AX17: 0 | AY17: 0 | AZ17: 0 | BA17: 0 | BB17: 0 | BC17: 0 | BD17: 0 | BE17: 0 | BF17: 0 | BG17: 0 | BH17: 0 | BI17: 0 | BJ17: 0 | BK17: 0 | BL17: 0 | BM17: 0 | BN17: 0 | BO17: 0 | BP17: 1 | BQ17: 1 | BR17: 0 | BS17: -1 | BT17: 0 | BU17: -1 | BV17: 0 | BW17: 0 | BX17: 0 | BY17: 0 | BZ17: 0 | CA17: 0 | CB17: 0 | CC17: 0 | CD17: 0 | CE17: 0 | CF17: 0 | CG17: 0 | CH17: 0 | CI17: 0 | CJ17: 0 | CK17: 0 | CL17: 0
I18: 15 | J18: Alim Nodo Productos Filtrados | K18: 0 | L18: 0 | M18: 0 | N18: 0 | O18: 0 | P18: -1 | Q18: 1 | R18: 0 | S18: 0 | T18: 0 | U18: 0 | V18: 0 | W18: 0 | X18: 0 | Y18: 0 | Z18: 0 | AA18: 0 | AB18: 0 | AC18: 0 | AD18: 0 | AE18: 0 | AF18: 0 | AI18: Stock Chunk | AJ18: 0 | AK18: 0 | AL18: 0 | AM18: 0 | AN18: 0 | AO18: 0 | AP18: 0 | AQ18: 0 | AR18: 0 | AS18: 0 | AT18: 0 | AU18: 0 | AV18: 0 | AW18: 0 | AX18: 0 | AY18: 0 | AZ18: 0 | BA18: 0 | BB18: 0 | BC18: 0 | BD18: 0 | BE18: 0 | BF18: 0 | BG18: 0 | BH18: 0 | BI18: 0 | BJ18: 0 | BK18: 0 | BL18: 1 | BM18: #REF! | BN18: 0 | BO18: 0 | BP18: 0 | BQ18: 0 | BR18: 0 | BS18: 0 | BT18: 0 | BU18: 0 | BV18: 0 | BW18: 0 | BX18: 0 | BY18: 0 | BZ18: -1 | CA18: 0 | CB18: 0 | CC18: 0 | CD18: 0 | CE18: 0 | CF18: 0 | CG18: 0 | CH18: 0 | CI18: 0 | CJ18: 0 | CK18: 0 | CL18: 0
I19: 16 | J19: De filtros a Balling | K19: 0 | L19: 0 | M19: 0 | N19: 0 | O19: 0 | P19: -1 | Q19: 0 | R19: 0 | S19: 0 | T19: 1 | U19: 0 | V19: 0 | W19: 0 | X19: 0 | Y19: 0 | Z19: 0 | AA19: 0 | AB19: 0 | AC19: 0 | AD19: 0 | AE19: 0 | AF19: 0 | AI19: Stock Chip Fresco | AJ19: 0 | AK19: 0 | AL19: 0 | AM19: 0 | AN19: 0 | AO19: 0 | AP19: 0 | AQ19: 0 | AR19: 0 | AS19: 0 | AT19: 0 | AU19: 0 | AV19: 0 | AW19: 0 | AX19: 0 | AY19: 0 | AZ19: 0 | BA19: 0 | BB19: 0 | BC19: 0 | BD19: 0 | BE19: 0 | BF19: 0 | BG19: 0 | BH19: 0 | BI19: 0 | BJ19: 0 | BK19: 0 | BL19: 0 | BM19: 0 | BN19: 0 | BO19: 0 | BP19: 0 | BQ19: 0 | BR19: 0 | BS19: 1 | BT19: #REF! | BU19: 0 | BV19: 0 | BW19: 0 | BX19: -1 | BY19: 0 | BZ19: 0 | CA19: 0 | CB19: 0 | CC19: 0 | CD19: 0 | CE19: 0 | CF19: 0 | CG19: 0 | CH19: 0 | CI19: 0 | CJ19: 0 | CK19: 0 | CL19: 0
I20: 17 | J20: Filtrado a Stock Derrames | K20: 0 | L20: 0 | M20: 0 | N20: 0 | O20: 0 | P20: -1 | Q20: 0 | R20: 0 | S20: 0 | T20: 0 | U20: 0 | V20: 1 | W20: 0 | X20: 0 | Y20: 0 | Z20: 0 | AA20: 0 | AB20: 0 | AC20: 0 | AD20: 0 | AE20: 0 | AF20: 0 | AI20: Planta Re-Harneo | AJ20: 0 | AK20: 0 | AL20: 0 | AM20: -1 | AN20: 0 | AO20: 0 | AP20: 0 | AQ20: 0 | AR20: 0 | AS20: 0 | AT20: 0 | AU20: 0 | AV20: 0 | AW20: 0 | AX20: 0 | AY20: 0 | AZ20: 0 | BA20: 0 | BB20: 0 | BC20: 0 | BD20: 0 | BE20: 0 | BF20: 0 | BG20: 0 | BH20: 0 | BI20: 0 | BJ20: 0 | BK20: 0 | BL20: 0 | BM20: 0 | BN20: 0 | BO20: 0 | BP20: 0 | BQ20: 0 | BR20: 0 | BS20: 0 | BT20: 0 | BU20: 0 | BV20: 0 | BW20: 0 | BX20: 1 | BY20: 1 | BZ20: 1 | CA20: -1 | CB20: -1 | CC20: -1 | CD20: 0 | CE20: 0 | CF20: 0 | CG20: 0 | CH20: 0 | CI20: 0 | CJ20: 0 | CK20: 0 | CL20: 0
I21: 18 | J21: Alim Pila Intermedia desde (de nodo post filtros) | K21: 0 | L21: 0 | M21: 0 | N21: 0 | O21: 0 | P21: 0 | Q21: -1 | R21: 1 | S21: 0 | T21: 0 | U21: 0 | V21: 0 | W21: 0 | X21: 0 | Y21: 0 | Z21: 0 | AA21: 0 | AB21: 0 | AC21: 0 | AD21: 0 | AE21: 0 | AF21: 0 | AI21: Stock Pellet Básico | AJ21: 0 | AK21: 0 | AL21: 0 | AM21: 0 | AN21: 0 | AO21: 0 | AP21: 0 | AQ21: 0 | AR21: 0 | AS21: 0 | AT21: 0 | AU21: 0 | AV21: 0 | AW21: 0 | AX21: 0 | AY21: 0 | AZ21: 0 | BA21: 0 | BB21: 0 | BC21: 0 | BD21: 0 | BE21: 0 | BF21: 0 | BG21: 0 | BH21: 0 | BI21: 0 | BJ21: 0 | BK21: 0 | BL21: 0 | BM21: 0 | BN21: 0 | BO21: 0 | BP21: 0 | BQ21: 0 | BR21: 0 | BS21: 0 | BT21: 0 | BU21: 1 | BV21: #REF! | BW21: -1 | BX21: 0 | BY21: 0 | BZ21: 0 | CA21: 0 | CB21: 0 | CC21: 0 | CD21: 0 | CE21: 0 | CF21: 0 | CG21: 0 | CH21: 0 | CI21: 1 | CJ21: 0 | CK21: 0 | CL21: 0
I22: 19 | J22: Delta Stock Pila Intermedia | K22: 0 | L22: 0 | M22: 0 | N22: 0 | O22: 0 | P22: 0 | Q22: 0 | R22: =+#REF! -> #REF! | S22: 0 | T22: 0 | U22: 0 | V22: 0 | W22: 0 | X22: 0 | Y22: 0 | Z22: 0 | AA22: 0 | AB22: 0 | AC22: 0 | AD22: 0 | AE22: 0 | AF22: 0 | AI22: Stock Finos Huasco | AJ22: 0 | AK22: 0 | AL22: 0 | AM22: 0 | AN22: 0 | AO22: 0 | AP22: 0 | AQ22: 0 | AR22: 0 | AS22: 0 | AT22: 0 | AU22: 0 | AV22: 0 | AW22: 0 | AX22: 0 | AY22: 0 | AZ22: 0 | BA22: 0 | BB22: 0 | BC22: 0 | BD22: 0 | BE22: 0 | BF22: 0 | BG22: 0 | BH22: 0 | BI22: 0 | BJ22: 0 | BK22: 0 | BL22: 0 | BM22: 0 | BN22: 0 | BO22: 0 | BP22: 0 | BQ22: 0 | BR22: 0 | BS22: 0 | BT22: 0 | BU22: 0 | BV22: 0 | BW22: 0 | BX22: 0 | BY22: 0 | BZ22: 0 | CA22: 0 | CB22: 1 | CC22: 0 | CD22: -1 | CE22: -1 | CF22: #REF! | CG22: 0 | CH22: 0 | CI22: 0 | CJ22: 0 | CK22: 0 | CL22: 0
I23: 20 | J23: de Pila Intermedia a Balling | K23: 0 | L23: 0 | M23: 0 | N23: 0 | O23: 0 | P23: 0 | Q23: 0 | R23: -1 | S23: 0 | T23: 1 | U23: 0 | V23: 0 | W23: 0 | X23: 0 | Y23: 0 | Z23: 0 | AA23: 0 | AB23: 0 | AC23: 0 | AD23: 0 | AE23: 0 | AF23: 0 | AI23: Stock Pellet Chip | AJ23: 0 | AK23: 0 | AL23: 0 | AM23: 0 | AN23: 0 | AO23: 0 | AP23: 0 | AQ23: 0 | AR23: 0 | AS23: 0 | AT23: 0 | AU23: 0 | AV23: 0 | AW23: 0 | AX23: 0 | AY23: 0 | AZ23: 0 | BA23: 0 | BB23: 0 | BC23: 0 | BD23: 0 | BE23: 0 | BF23: 0 | BG23: 0 | BH23: 0 | BI23: 0 | BJ23: 0 | BK23: 0 | BL23: 0 | BM23: 0 | BN23: 0 | BO23: 0 | BP23: 0 | BQ23: 0 | BR23: 0 | BS23: 0 | BT23: 0 | BU23: 0 | BV23: 0 | BW23: 0 | BX23: 0 | BY23: 0 | BZ23: 0 | CA23: 0 | CB23: 0 | CC23: 1 | CD23: 0 | CE23: 0 | CF23: 0 | CG23: 0 | CH23: 0 | CI23: -1 | CJ23: -1 | CK23: #REF! | CL23: 0
I24: 21 | J24: de Pila Intermadia a Stok Pellet Feed | K24: 0 | L24: 0 | M24: 0 | N24: 0 | O24: 0 | P24: 0 | Q24: 0 | R24: -1 | S24: 1 | T24: 0 | U24: 0 | V24: 0 | W24: 0 | X24: 0 | Y24: 0 | Z24: 0 | AA24: 0 | AB24: 0 | AC24: 0 | AD24: 0 | AE24: 0 | AF24: 0 | AI24: Stock Sinter Feed | AJ24: 0 | AK24: 1 | AL24: 0 | AM24: 0 | AN24: 0 | AO24: 0 | AP24: 0 | AQ24: 0 | AR24: 0 | AS24: 0 | AT24: 0 | AU24: 0 | AV24: 0 | AW24: 0 | AX24: 0 | AY24: 0 | AZ24: 0 | BA24: 0 | BB24: 0 | BC24: 0 | BD24: 0 | BE24: 0 | BF24: 0 | BG24: 0 | BH24: 0 | BI24: 0 | BJ24: 0 | BK24: 0 | BL24: 0 | BM24: 0 | BN24: 0 | BO24: 0 | BP24: 0 | BQ24: 0 | BR24: 0 | BS24: 0 | BT24: 0 | BU24: 0 | BV24: 0 | BW24: 0 | BX24: 0 | BY24: 0 | BZ24: 0 | CA24: 0 | CB24: 0 | CC24: 0 | CD24: 1 | CE24: 0 | CF24: 0 | CG24: -1 | CH24: #REF! | CI24: 0 | CJ24: 0 | CK24: 0 | CL24: 0
I25: 22 | J25: a Stock Pellet Feed (de nodo post filtros) | K25: 0 | L25: 0 | M25: 0 | N25: 0 | O25: 0 | P25: 0 | Q25: -1 | R25: 0 | S25: 1 | T25: 0 | U25: 0 | V25: 0 | W25: 0 | X25: 0 | Y25: 0 | Z25: 0 | AA25: 0 | AB25: 0 | AC25: 0 | AD25: 0 | AE25: 0 | AF25: 0 | AI25: Nodo Alimentaciones Embarque | AJ25: 0 | AK25: 0 | AL25: 0 | AM25: 0 | AN25: 0 | AO25: 0 | AP25: 0 | AQ25: 0 | AR25: 0 | AS25: 0 | AT25: 0 | AU25: 0 | AV25: 0 | AW25: 0 | AX25: 0 | AY25: 0 | AZ25: 0 | BA25: 0 | BB25: 0 | BC25: 0 | BD25: 0 | BE25: 0 | BF25: 0 | BG25: 1 | BH25: 0 | BI25: 0 | BJ25: 0 | BK25: 0 | BL25: 0 | BM25: 0 | BN25: 0 | BO25: 0 | BP25: 0 | BQ25: 0 | BR25: 0 | BS25: 0 | BT25: 0 | BU25: 0 | BV25: 0 | BW25: 1 | BX25: 0 | BY25: 0 | BZ25: 0 | CA25: 0 | CB25: 0 | CC25: 0 | CD25: 0 | CE25: 1 | CF25: 0 | CG25: 1 | CH25: 0 | CI25: 0 | CJ25: 1 | CK25: 0 | CL25: -1
I26: 23 | J26: Delta Stock Pellet Feed | K26: 0 | L26: 0 | M26: 0 | N26: 0 | O26: 0 | P26: 0 | Q26: 0 | R26: 0 | S26: =+#REF! -> #REF! | T26: 0 | U26: 0 | V26: 0 | W26: 0 | X26: 0 | Y26: 0 | Z26: 0 | AA26: 0 | AB26: 0 | AC26: 0 | AD26: 0 | AE26: 0 | AF26: 0
I27: 24 | J27: A embarque de Stock Pellet Feed | K27: 0 | L27: 0 | M27: 0 | N27: 0 | O27: 0 | P27: 0 | Q27: 0 | R27: 0 | S27: -1 | T27: 0 | U27: 0 | V27: 0 | W27: 0 | X27: 0 | Y27: 0 | Z27: 0 | AA27: 0 | AB27: 0 | AC27: 0 | AD27: 0 | AE27: 0 | AF27: 1
I28: 25 | J28: Aditivo a Balling | K28: 0 | L28: 0 | M28: 0 | N28: 0 | O28: 0 | P28: 0 | Q28: 0 | R28: 0 | S28: 0 | T28: 1 | U28: 0 | V28: 0 | W28: 0 | X28: 0 | Y28: 0 | Z28: 0 | AA28: 0 | AB28: 0 | AC28: 0 | AD28: 0 | AE28: 0 | AF28: 0 | AJ28: TMS | AK28: TMF
I29: 26 | J29: Pellet verde a edurecimiento | K29: 0 | L29: 0 | M29: 0 | N29: 0 | O29: 0 | P29: 0 | Q29: 0 | R29: 0 | S29: 0 | T29: -1 | U29: 1 | V29: 0 | W29: 0 | X29: 0 | Y29: 0 | Z29: 0 | AA29: 0 | AB29: 0 | AC29: 0 | AD29: 0 | AE29: 0 | AF29: 0 | AI29: =+I62 -> 1 | AJ29: =+N62 -> 345274.75 | AK29: =+P62 -> 208129.93
I30: 27 | J30: Endurecimiento a Stock Derrames | K30: 0 | L30: 0 | M30: 0 | N30: 0 | O30: 0 | P30: 0 | Q30: 0 | R30: 0 | S30: 0 | T30: 0 | U30: -1 | V30: 1 | W30: 0 | X30: 0 | Y30: 0 | Z30: 0 | AA30: 0 | AB30: 0 | AC30: 0 | AD30: 0 | AE30: 0 | AF30: 0 | AI30: =+I63 -> 2 | AJ30: =+N63 -> 85251.46 | AK30: =+P63 -> 56558.552
I31: 28 | J31: Delta Inventarios de Derrames | K31: 0 | L31: 0 | M31: 0 | N31: 0 | O31: 0 | P31: 0 | Q31: 0 | R31: 0 | S31: 0 | T31: 0 | U31: 0 | V31: =+#REF! -> #REF! | W31: 0 | X31: 0 | Y31: 0 | Z31: 0 | AA31: 0 | AB31: 0 | AC31: 0 | AD31: 0 | AE31: 0 | AF31: 0 | AI31: =+I64 -> 3 | AJ31: =+N64 -> 260023.29 | AK31: =+P64 -> 151571.38
I32: 29 | J32: Chunk de endurecimiento a Pila Chunk | K32: 0 | L32: 0 | M32: 0 | N32: 0 | O32: 0 | P32: 0 | Q32: 0 | R32: 0 | S32: 0 | T32: 0 | U32: -1 | V32: 0 | W32: 0 | X32: 0 | Y32: 1 | Z32: 0 | AA32: 0 | AB32: 0 | AC32: 0 | AD32: 0 | AE32: 0 | AF32: 0 | AI32: =+I65 -> 4 | AJ32: =+N65 -> 0 | AK32: =+P65 -> 0
I33: 30 | J33: Delta Stock Pila Chunk | K33: 0 | L33: 0 | M33: 0 | N33: 0 | O33: 0 | P33: 0 | Q33: 0 | R33: 0 | S33: 0 | T33: 0 | U33: 0 | V33: 0 | W33: 0 | X33: 0 | Y33: =+#REF! -> #REF! | Z33: 0 | AA33: 0 | AB33: 0 | AC33: 0 | AD33: 0 | AE33: 0 | AF33: 0 | AI33: =+I66 -> 5 | AJ33: =+N66 -> 15949.779 | AK33: =+P66 -> 9650.9353
I34: 31 | J34: Aporte Oxidación Endurecimiento | K34: 0 | L34: 0 | M34: 0 | N34: 0 | O34: 0 | P34: 0 | Q34: 0 | R34: 0 | S34: 0 | T34: 0 | U34: 1 | V34: 0 | W34: 0 | X34: 0 | Y34: 0 | Z34: 0 | AA34: 0 | AB34: 0 | AC34: 0 | AD34: 0 | AE34: 0 | AF34: 0 | AI34: =+I67 -> 6 | AJ34: =+N67 -> 244073.52 | AK34: =+P67 -> 141920.44
I35: 32 | J35: Alim endurecido a Pila Emergencia | K35: 0 | L35: 0 | M35: 0 | N35: 0 | O35: 0 | P35: 0 | Q35: 0 | R35: 0 | S35: 0 | T35: 0 | U35: -1 | V35: 0 | W35: 1 | X35: 0 | Y35: 0 | Z35: 0 | AA35: 0 | AB35: 0 | AC35: 0 | AD35: 0 | AE35: 0 | AF35: 0 | AI35: =+I68 -> 7 | AJ35: =+N68 -> 278.0926 | AK35: =+P68 -> 167.30836
I36: 33 | J36: De endurecimiento a Harnero Producto | K36: 0 | L36: 0 | M36: 0 | N36: 0 | O36: 0 | P36: 0 | Q36: 0 | R36: 0 | S36: 0 | T36: 0 | U36: -1 | V36: 0 | W36: 0 | X36: 1 | Y36: 0 | Z36: 0 | AA36: 0 | AB36: 0 | AC36: 0 | AD36: 0 | AE36: 0 | AF36: 0 | AI36: =+I69 -> 8 | AJ36: =+N69 -> 244351.61 | AK36: =+P69 -> 142087.75
I37: 34 | J37: Alim Harnero Producto desde Pila de Emergencia | K37: 0 | L37: 0 | M37: 0 | N37: 0 | O37: 0 | P37: 0 | Q37: 0 | R37: 0 | S37: 0 | T37: 0 | U37: 0 | V37: 0 | W37: -1 | X37: 1 | Y37: 0 | Z37: 0 | AA37: 0 | AB37: 0 | AC37: 0 | AD37: 0 | AE37: 0 | AF37: 0 | AI37: =+I70 -> 9 | AJ37: =+N70 -> 1385.9478 | AK37: =+P70 -> 816.43648
I38: 35 | J38: Delta Stock Pila Emergencia | K38: 0 | L38: 0 | M38: 0 | N38: 0 | O38: 0 | P38: 0 | Q38: 0 | R38: 0 | S38: 0 | T38: 0 | U38: 0 | V38: 0 | W38: =+#REF! -> #REF! | X38: 0 | Y38: 0 | Z38: 0 | AA38: 0 | AB38: 0 | AC38: 0 | AD38: 0 | AE38: 0 | AF38: 0 | AI38: =+I71 -> 10 | AJ38: =+N71 -> 42525.99 | AK38: =+P71 -> 4150.5366
I39: 36 | J39: De harnero Producto a Pila Chip Fresco | K39: 0 | L39: 0 | M39: 0 | N39: 0 | O39: 0 | P39: 0 | Q39: 0 | R39: 0 | S39: 0 | T39: 0 | U39: 0 | V39: 0 | W39: 0 | X39: -1 | Y39: 0 | Z39: 1 | AA39: 0 | AB39: 0 | AC39: 0 | AD39: 0 | AE39: 0 | AF39: 0 | AI39: =+I72 -> 11 | AJ39: =+N72 -> 200439.67 | AK39: =+P72 -> 137120.78
I40: 37 | J40: Delta Stock Pila Chip Fresco | K40: 0 | L40: 0 | M40: 0 | N40: 0 | O40: 0 | P40: 0 | Q40: 0 | R40: 0 | S40: 0 | T40: 0 | U40: 0 | V40: 0 | W40: 0 | X40: 0 | Y40: 0 | Z40: =+#REF! -> #REF! | AA40: 0 | AB40: 0 | AC40: 0 | AD40: 0 | AE40: 0 | AF40: 0 | AI40: =+I73 -> 12 | AJ40: =+N73 -> 2653.3424 | AK40: =+P73 -> 1814.2777
I41: 38 | J41: De Harnero Producto a Stock Pellets Básico | K41: 0 | L41: 0 | M41: 0 | N41: 0 | O41: 0 | P41: 0 | Q41: 0 | R41: 0 | S41: 0 | T41: 0 | U41: 0 | V41: 0 | W41: 0 | X41: -1 | Y41: 0 | Z41: 0 | AA41: 0 | AB41: 1 | AC41: 0 | AD41: 0 | AE41: 0 | AF41: 0 | AI41: =+I74 -> 13 | AJ41: =+N74 -> 0 | AK41: =+P74 -> 0
I42: 39 | J42: Delta Stock Pellet Básico | K42: 0 | L42: 0 | M42: 0 | N42: 0 | O42: 0 | P42: 0 | Q42: 0 | R42: 0 | S42: 0 | T42: 0 | U42: 0 | V42: 0 | W42: 0 | X42: 0 | Y42: 0 | Z42: 0 | AA42: 0 | AB42: =+#REF! -> #REF! | AC42: 0 | AD42: 0 | AE42: 0 | AF42: 0 | AI42: =+I75 -> 14 | AJ42: =+N75 -> 197786.33 | AK42: =+P75 -> 135306.5
...
