Workbook

Sheet Export Summary
B3: This document was exported from Numbers. Each table was converted to an Excel worksheet. All other objects on each Numbers sheet were placed on separate worksheets. Please be aware that formula calculations may differ in Excel.
B7: Numbers Sheet Name | C7: Numbers Table Name | D7: Excel Worksheet Name
B9: Utilidad
C10: Table 1 | D10: Utilidad
B11: Datos Extra
C12: Table 1 | D12: Datos Extra
B13: Flujos
C14: Table 1 | D14: Flujos
B15: Diag Proceso Balance
C16: Table 1 | D16: Diag Proceso Balance
B17: Hoja1
C18: Table 1 | D18: Hoja1
B19: Report
C20: Table 1 | D20: Report

Sheet Utilidad
A1: 179498 | B1: 179498 | C1: 66.05 | D1: 65.689929 | E1: 0
A2: -1732 | B2: -1732 | C2: 65.52 | D2: 65.514753 | E2: 0
A3: 181230 | B3: 181230 | C3: 65.52 | D3: 65.688255 | E3: 0
A4: 0 | B4: 0 | C4: 0 | D4: 0 | E4: 0
A5: 181230 | B5: 181230 | C5: 65.52 | D5: 65.688255 | E5: 0
A6: 1906 | B6: 1906 | C6: 65.52 | D6: 65.524048 | E6: 0
A7: 177417 | B7: 179324 | C7: 66.4 | D7: 65.69 | E7: 0
A8: 0 | B8: 0 | C8: 0 | D8: 0 | E8: 0
A9: 179324 | B9: 179324 | C9: 65.69 | D9: 65.69 | E9: 0
A10: 0 | B10: 0 | C10: 0 | D10: 0 | E10: 0
A11: 0 | B11: 0 | C11: 0 | D11: 0 | E11: 0
A12: 13055 | B12: 13056 | C12: 65.64 | D12: 66.326749 | E12: 0
... A32: 218703 | B32: 218703 | C32: 65.64 | D32: 65.64 | E32: 0
J36: Valores Calculados
J37: TMS | K37: %FeT | L37: TMF Fe
J38: =B1 -> 179498 | K38: =IF(D1>1,D1/100,D1) -> 0.65689929 | L38: =J38*K38 -> 117912.11
J39: =B2 -> -1732 | K39: =IF(D2>1,D2/100,D2) -> 0.65514753 | L39: =J39*K39 -> -1134.7155
J40: =B3 -> 181230 | K40: =IF(D3>1,D3/100,D3) -> 0.65688255 | L40: =J40*K40 -> 119046.82
J41: =B4 -> 0 | K41: =IF(D4>1,D4/100,D4) -> 0 | L41: =J41*K41 -> 0
J42: =B5 -> 181230 | K42: =IF(D5>1,D5/100,D5) -> 0.65688255 | L42: =J42*K42 -> 119046.82
J43: =B6 -> 1906 | K43: =IF(D6>1,D6/100,D6) -> 0.65524048 | L43: =J43*K43 -> 1248.8884
J44: =B7 -> 179324 | K44: =IF(D7>1,D7/100,D7) -> 0.6569 | L44: =J44*K44 -> 117797.94
J45: =B8 -> 0 | K45: =IF(D8>1,D8/100,D8) -> 0 | L45: =J45*K45 -> 0
J46: =B9 -> 179324 | K46: =IF(D9>1,D9/100,D9) -> 0.6569 | L46: =J46*K46 -> 117797.94
J47: =B10 -> 0 | K47: =IF(D10>1,D10/100,D10) -> 0 | L47: =J47*K47 -> 0
J48: =B11 -> 0 | K48: =IF(D11>1,D11/100,D11) -> 0 | L48: =J48*K48 -> 0
J49: =B12 -> 13056 | K49: =IF(D12>1,D12/100,D12) -> 0.66326749 | L49: =J49*K49 -> 8659.6204
... J69: =B32 -> 218703 | K69: =IF(D32>1,D32/100,D32) -> 0.6564 | L69: =J69*K69 -> 143556.65

Sheet Datos Extra
A1: Flujo | B1: 1 | C1: 0.01 | D1: 0.01

Sheet Flujos
B2: Mediciones | F2: Balance | J2: % Cambio relativo | M2: Max Var Ton | N2: Max Var FeT
B3: Flujos | C3: TMS | D3: %FeT | F3: Flujos | G3: TMS | H3: %FeT | J3: TMSD | K3: %Fe T
B4: Producción CNN | C4: ='Utilidad'!A1 -> 179498 | D4: =IF('Utilidad'!C1>1,'Utilidad'!C1/100,'Utilidad'!C1) -> 0.6605 | F4: Producción CNN | G4: ='Utilidad'!B1 -> 179498 | H4: =IF('Utilidad'!D1>1,'Utilidad'!D1/100,'Utilidad'!D1) -> 0.65689929 | J4: =IF(C4<>0,(G4-C4)/C4,ABS(G4-C4)) -> 0 | K4: =IF(D4<>0,(H4-D4)/D4,0) -> -0.0054514941 | M4: =IF(J4<>"",ABS(J4),0) -> 0 | N4: =IF(J4<>"",ABS(K4),0) -> 0.0054514941
B5: Dif. Stock Agitadores Planta CNN | C5: ='Utilidad'!A2 -> -1732 | D5: =IF('Utilidad'!C2>1,'Utilidad'!C2/100,'Utilidad'!C2) -> 0.6552 | F5: Dif. Stock Agitadores Planta CNN | G5: ='Utilidad'!B2 -> -1732 | H5: =IF('Utilidad'!D2>1,'Utilidad'!D2/100,'Utilidad'!D2) -> 0.65514753 | J5: =IF(C5<>0,(G5-C5)/C5,ABS(G5-C5)) -> 0 | K5: =IF(D5<>0,(H5-D5)/D5,0) -> -8.0077717e-05 | M5: =IF(J5<>"",ABS(J5),0) -> 0 | N5: =IF(J5<>"",ABS(K5),0) -> 8.0077717e-05
B6: Bombeo CNN | C6: ='Utilidad'!A3 -> 181230 | D6: =IF('Utilidad'!C3>1,'Utilidad'!C3/100,'Utilidad'!C3) -> 0.6552 | F6: Bombeo CNN | G6: ='Utilidad'!B3 -> 181230 | H6: =IF('Utilidad'!D3>1,'Utilidad'!D3/100,'Utilidad'!D3) -> 0.65688255 | J6: =IF(C6<>0,(G6-C6)/C6,ABS(G6-C6)) -> 0 | K6: =IF(D6<>0,(H6-D6)/D6,0) -> 0.0025679896 | M6: =IF(J6<>"",ABS(J6),0) -> 0 | N6: =IF(J6<>"",ABS(K6),0) -> 0.0025679896
B7: dif. Stock Concentraducto CNN | C7: ='Utilidad'!A4 -> 0 | D7: =IF('Utilidad'!C4>1,'Utilidad'!C4/100,'Utilidad'!C4) -> 0 | F7: dif. Stock Concentraducto CNN | G7: ='Utilidad'!B4 -> 0 | H7: =IF('Utilidad'!D4>1,'Utilidad'!D4/100,'Utilidad'!D4) -> 0 | J7: =IF(C7<>0,(G7-C7)/C7,ABS(G7-C7)) -> 0 | K7: =IF(D7<>0,(H7-D7)/D7,0) -> 0 | M7: =IF(J7<>"",ABS(J7),0) -> 0 | N7: =IF(J7<>"",ABS(K7),0) -> 0
B8: ingreso concentrado CNN a puerto | C8: ='Utilidad'!A5 -> 181230 | D8: =IF('Utilidad'!C5>1,'Utilidad'!C5/100,'Utilidad'!C5) -> 0.6552 | F8: ingreso concentrado CNN a puerto | G8: ='Utilidad'!B5 -> 181230 | H8: =IF('Utilidad'!D5>1,'Utilidad'!D5/100,'Utilidad'!D5) -> 0.65688255 | J8: =IF(C8<>0,(G8-C8)/C8,ABS(G8-C8)) -> 0 | K8: =IF(D8<>0,(H8-D8)/D8,0) -> 0.0025679896 | M8: =IF(J8<>"",ABS(J8),0) -> 0 | N8: =IF(J8<>"",ABS(K8),0) -> 0.0025679896
B9: dif. Stock CNN en Agitadores Puerto | C9: ='Utilidad'!A6 -> 1906 | D9: =IF('Utilidad'!C6>1,'Utilidad'!C6/100,'Utilidad'!C6) -> 0.6552 | F9: dif. Stock CNN en Agitadores Puerto | G9: ='Utilidad'!B6 -> 1906 | H9: =IF('Utilidad'!D6>1,'Utilidad'!D6/100,'Utilidad'!D6) -> 0.65524048 | J9: =IF(C9<>0,(G9-C9)/C9,ABS(G9-C9)) -> 0 | K9: =IF(D9<>0,(H9-D9)/D9,0) -> 6.1782769e-05 | M9: =IF(J9<>"",ABS(J9),0) -> 0 | N9: =IF(J9<>"",ABS(K9),0) -> 6.1782769e-05
B10: Alim espesador CNN | C10: ='Utilidad'!A7 -> 177417 | D10: =IF('Utilidad'!C7>1,'Utilidad'!C7/100,'Utilidad'!C7) -> 0.664 | F10: Alim espesador CNN | G10: ='Utilidad'!B7 -> 179324 | H10: =IF('Utilidad'!D7>1,'Utilidad'!D7/100,'Utilidad'!D7) -> 0.6569 | J10: =IF(C10<>0,(G10-C10)/C10,ABS(G10-C10)) -> 0.010748688 | K10: =IF(D10<>0,(H10-D10)/D10,0) -> -0.010692771 | M10: =IF(J10<>"",ABS(J10),0) -> 0.010748688 | N10: =IF(J10<>"",ABS(K10),0) -> 0.010692771
B11: Desvío TK CNN a piscina | C11: ='Utilidad'!A8 -> 0 | D11: =IF('Utilidad'!C8>1,'Utilidad'!C8/100,'Utilidad'!C8) -> 0 | F11: Desvío TK CNN a piscina | G11: ='Utilidad'!B8 -> 0 | H11: =IF('Utilidad'!D8>1,'Utilidad'!D8/100,'Utilidad'!D8) -> 0 | J11: =IF(C11<>0,(G11-C11)/C11,ABS(G11-C11)) -> 0 | K11: =IF(D11<>0,(H11-D11)/D11,0) -> 0 | M11: =IF(J11<>"",ABS(J11),0) -> 0 | N11: =IF(J11<>"",ABS(K11),0) -> 0
B12: Filtrado CNN | C12: ='Utilidad'!A9 -> 179324 | D12: =IF('Utilidad'!C9>1,'Utilidad'!C9/100,'Utilidad'!C9) -> 0.6569 | F12: Filtrado CNN | G12: ='Utilidad'!B9 -> 179324 | H12: =IF('Utilidad'!D9>1,'Utilidad'!D9/100,'Utilidad'!D9) -> 0.6569 | J12: =IF(C12<>0,(G12-C12)/C12,ABS(G12-C12)) -> 0 | K12: =IF(D12<>0,(H12-D12)/D12,0) -> 0 | M12: =IF(J12<>"",ABS(J12),0) -> 0 | N12: =IF(J12<>"",ABS(K12),0) -> 0
B13: Dif inventario espesador CNN | C13: ='Utilidad'!A10 -> 0 | D13: =IF('Utilidad'!C10>1,'Utilidad'!C10/100,'Utilidad'!C10) -> 0 | F13: Dif inventario espesador CNN | G13: ='Utilidad'!B10 -> 0 | H13: =IF('Utilidad'!D10>1,'Utilidad'!D10/100,'Utilidad'!D10) -> 0 | J13: =IF(C13<>0,(G13-C13)/C13,ABS(G13-C13)) -> 0 | K13: =IF(D13<>0,(H13-D13)/D13,0) -> 0 | M13: =IF(J13<>"",ABS(J13),0) -> 0 | N13: =IF(J13<>"",ABS(K13),0) -> 0
B14: Desvío conc a Filtro MGTTA | C14: ='Utilidad'!A11 -> 0 | D14: =IF('Utilidad'!C11>1,'Utilidad'!C11/100,'Utilidad'!C11) -> 0 | F14: Desvío conc a Filtro MGTTA | G14: ='Utilidad'!B11 -> 0 | H14: =IF('Utilidad'!D11>1,'Utilidad'!D11/100,'Utilidad'!D11) -> 0 | J14: =IF(C14<>0,(G14-C14)/C14,ABS(G14-C14)) -> 0 | K14: =IF(D14<>0,(H14-D14)/D14,0) -> 0 | M14: =IF(J14<>"",ABS(J14),0) -> 0 | N14: =IF(J14<>"",ABS(K14),0) -> 0
B15: Delta Inventario Cancha CNN | C15: ='Utilidad'!A12 -> 13055 | D15: =IF('Utilidad'!C12>1,'Utilidad'!C12/100,'Utilidad'!C12) -> 0.6564 | F15: Delta Inventario Cancha CNN | G15: ='Utilidad'!B12 -> 13056 | H15: =IF('Utilidad'!D12>1,'Utilidad'!D12/100,'Utilidad'!D12) -> 0.66326749 | J15: =IF(C15<>0,(G15-C15)/C15,ABS(G15-C15)) -> 7.6599004e-05 | K15: =IF(D15<>0,(H15-D15)/D15,0) -> 0.010462361 | M15: =IF(J15<>"",ABS(J15),0) -> 7.6599004e-05 | N15: =IF(J15<>"",ABS(K15),0) -> 0.010462361
... B35: Total embarcado | C35: ='Utilidad'!A32 -> 218703 | D35: =IF('Utilidad'!C32>1,'Utilidad'!C32/100,'Utilidad'!C32) -> 0.6564 | F35: Total embarcado | G35: ='Utilidad'!B32 -> 218703 | H35: =IF('Utilidad'!D32>1,'Utilidad'!D32/100,'Utilidad'!D32) -> 0.6564 | J35: =IF(C35<>0,(G35-C35)/C35,ABS(G35-C35)) -> 0 | K35: =IF(D35<>0,(H35-D35)/D35,0) -> 0 | M35: =IF(J35<>"",ABS(J35),0) -> 0 | N35: =IF(J35<>"",ABS(K35),0) -> 0

Sheet Diag Proceso Balance
C3: Producción CNN | E3: ='Utilidad'!J38 -> 179498 | P3: Producción PM | R3: ='Utilidad'!J51 -> 49366
E4: ='Utilidad'!K38 -> 0.65689929 | R4: ='Utilidad'!K51 -> 0.66156524
E5: ='Utilidad'!L38 -> 117912.11 | R5: ='Utilidad'!L51 -> 32658.83
R6: =R3-R9 -> -2483
E7: =E3-E10 -> -1732 | R7: ='Utilidad'!K52 -> 0.65752722
C8: TK Planta CNN | E8: ='Utilidad'!K39 -> 0.65514753 | P8: TK Planta PM | R8: ='Utilidad'!L52 -> -1632.6401
E9: ='Utilidad'!L39 -> -1134.7155 | R9: ='Utilidad'!J53 -> 51849
E10: ='Utilidad'!J40 -> 181230 | R10: ='Utilidad'!K53 -> 0.66137186
E11: ='Utilidad'!K40 -> 0.65688255 | R11: ='Utilidad'!L53 -> 34291.47
C12: Concentraducto CNN | E12: ='Utilidad'!L40 -> 119046.82 | P12: Concentraducto PM
R13: =R9-R18 -> -7699.9116
E14: =E10-E19 -> 0 | R14: ='Utilidad'!K54 -> 0.65766741
E15: ='Utilidad'!K41 -> 0 | R15: ='Utilidad'!L54 -> -5063.9809
E16: ='Utilidad'!L41 -> 0
R18: ='Utilidad'!J55 -> 59548.912
E19: ='Utilidad'!J42 -> 181230 | R19: ='Utilidad'!K53 -> 0.66137186
E20: ='Utilidad'!K42 -> 0.65688255 | R20: ='Utilidad'!L55 -> 39355.451
E21: ='Utilidad'!L42 -> 119046.82
E22: =E19-E25 -> 1906 | G22: ='Utilidad'!J45 -> 0 | N22: ='Utilidad'!J58 -> 0 | P22: TK Puerto PM | R22: =R18-R25 -> -1846.0884
E23: ='Utilidad'!K43 -> 0.65524048 | G23: ='Utilidad'!K45 -> 0 | N23: ='Utilidad'!K58 -> 0 | R23: ='Utilidad'!K56 -> 0.65780456
E24: ='Utilidad'!L43 -> 1248.8884 | G24: ='Utilidad'!L45 -> 0 | N24: ='Utilidad'!L58 -> 0 | R24: ='Utilidad'!L56 -> -1214.3654
C25: TK Puerto CNN | E25: ='Utilidad'!J44 -> 179324 | R25: ='Utilidad'!J57 -> 61395
E26: ='Utilidad'!K44 -> 0.6569 | R26: ='Utilidad'!K57 -> 0.6608
E27: ='Utilidad'!L44 -> 117797.94 | K27: =G22+N22-K29 -> -2778 | R27: ='Utilidad'!L57 -> 40569.816
G29: ='Utilidad'!J48 -> 0 | K29: ='Utilidad'!J66 -> 2778
G30: ='Utilidad'!K48 -> 0 | K30: ='Utilidad'!K66 -> 0.65663629 | R30: ='Utilidad'!J59 -> 61395
E31: ='Utilidad'!J46 -> 179324 | G31: ='Utilidad'!L48 -> 0 | K31: ='Utilidad'!L66 -> 1824.1356 | R31: ='Utilidad'!K59 -> 0.6608
E32: ='Utilidad'!K46 -> 0.6569 | I32: Material Recuperado Piscina de Emergencia | R32: ='Utilidad'!L59 -> 40569.816
E33: ='Utilidad'!L46 -> 117797.94 | K33: =K29-K39 -> 0
K34: ='Utilidad'!K67 -> 0
K35: ='Utilidad'!L67 -> 0 | M35: ='Utilidad'!J62 -> 0
M36: ='Utilidad'!K62 -> 0
M37: ='Utilidad'!L62 -> 0
E38: =E31 -> 179324
E39: =E32 -> 0.6569 | K39: ='Utilidad'!J68 -> 2778 | R39: ='Utilidad'!J61 -> 61395
E40: =E33 -> 117797.94 | H40: ='Utilidad'!J50 -> 166268 | K40: ='Utilidad'!K68 -> 0.65663629 | M40: ='Utilidad'!J64 -> 49656 | R40: ='Utilidad'!K61 -> 0.6608
H41: ='Utilidad'!K50 -> 0.6564 | K41: ='Utilidad'!L68 -> 1824.1356 | M41: ='Utilidad'!K64 -> 0.6564 | R41: ='Utilidad'!L61 -> 40569.816
F42: =E38+M35-H40 -> 13056 | H42: ='Utilidad'!L50 -> 109138.32 | M42: ='Utilidad'!L64 -> 32594.198 | O42: =R39-M40 -> 11739
F43: ='Utilidad'!K49 -> 0.66326749 | O43: ='Utilidad'!K63 -> 0.67941201
F44: ='Utilidad'!L49 -> 8659.6204 | O44: ='Utilidad'!L61 -> 40569.816
...

Sheet Hoja1
C6: Gestión Valle
C7: Producción CNN
C8: Bombeado CNN
C9: Producción PM
C10: Transporte Fluidos PM
C11: Recepción Puerto Punta Totoralillo
C12: Producción Total
C13: Pellet Feed (PM)
C14: Pellet Feed (CNN)
C15: Material Recuperado Piscina
C16: Embarque Puerto Punta Totoralillo
C17: Embarque Total
... C20: Sinter Feed

Sheet Report
F2: BALANCE METALÚRGICO - VALLE DEL COPIAPO
F4: REPORTE PUERTO PUNTA TOTORALILLO | M4: FECHA DE BALANCE | P4: =TODAY() -> 45535
N7: TONELAJE | P7: LEY | Q7: FINO
G8: TONELAJE | I8: LEY | J8: FINO | N8: TMS | O8: TMH | P8: % FeT | Q8: TMF
D9: GESTION POR VALLE | K9: RECEPCION PUERTO PUNTA TOTORALILLO
C10: FL_218_501_01 | D10: CERRO NEGRO NORTE | G10: TMS | H10: TBN | I10: % FeT | J10: TMF | K10: CERRO NEGRO NORTE | N10: TMS | O10: TBN | P10: % FeT | Q10: TMF
D11: Produccion CNN | G11: ='Flujos'!G4 -> 179498 | H11: =G11/0.915 -> 196172.68 | I11: ='Flujos'!H4 -> 0.65689929 | J11: =I11*G11 -> 117912.11 | K11: Filtrado CNN | N11: ='Flujos'!G12 -> 179324 | O11: =N11/0.915 -> 195982.51 | P11: ='Flujos'!H12 -> 0.6569 | Q11: =P11*N11 -> 117797.94
D12: Bombeado CNN | G12: ='Flujos'!G6 -> 181230 | H12: =G12/0.915 -> 198065.57 | I12: ='Flujos'!H6 -> 0.65688255 | J12: =I12*G12 -> 119046.82 | K12: Material Recuperado de piscina CNN | O12: =N12/0.915 -> 0 | Q12: =P12*N12 -> 0
K13: TOTAL | N13: =SUM(N9:N12) -> 179324 | O13: =SUM(O9:O12) -> 195982.51 | Q13: =SUM(Q9:Q12) -> 117797.94
D14: PLANTA MAGNETITA | G14: TMS | H14: TBN | I14: % FeT | J14: TMF
D15: Produccion Magnetita | G15: ='Flujos'!G17 -> 49366 | H15: =G15/0.915 -> 53951.913 | I15: ='Flujos'!H17 -> 0.66156524 | J15: =I15*G15 -> 32658.83 | K15: PLANTA MAGNETITA | N15: TMS | O15: TBN | P15: % FeT | Q15: TMF
D16: Bombeado Magnetita | G16: ='Flujos'!G19 -> 51849 | H16: =G16/0.915 -> 56665.574 | I16: ='Flujos'!H19 -> 0.66137186 | J16: =I16*G16 -> 34291.47 | K16: Filtrado Magnetita | N16: ='Flujos'!G27 -> 61395 | O16: =N16/0.915 -> 67098.361 | P16: ='Flujos'!H27 -> 0.6608 | Q16: =P16*N16 -> 40569.816
K17: Material Recuperado de piscina Magnetita | O17: =N17/0.915 -> 0 | Q17: =P17*N17 -> 0
C18: FL_000_501_03 | D18: TOTAL | G18: =SUM(G10:G17) -> 461943 | H18: =SUM(H10:H17) -> 504855.74 | J18: =SUM(J10:J17) -> 303909.23 | K18: TOTAL | N18: =SUM(N14:N17) -> 61395 | O18: =SUM(O14:O17) -> 67098.361 | Q18: =SUM(Q14:Q17) -> 40569.816
D19: EMBARQUES
D20: PUERTO PUNTA TOTORALILLO | G20: TMS | H20: TBN | I20: % FeT | J20: TMF | K20: CERRO NEGRO NORTE | N20: TMS | O20: TBN | P20: % FeT | Q20: TMF
D21: Pellet Feed CNN | J21: =I21*G21 -> 0 | K21: Pellet Feed PM | O21: =N21/0.915 -> 0
D22: Pellet Feed Magnetita | J22: =I22*G22 -> 0 | K22: Pellet Feed CNN | O22: =N22/0.915 -> 0
D23: TOTAL PELLET FEED | G23: =SUM(G19:G22) -> 0 | H23: =SUM(H19:H22) -> 0 | J23: =SUM(J21:J22) -> 0 | K23: Sinter Feed
D24: Sinter Feed | J24: =I24*G24 -> 0
I27: Delta inventario TMS | J27: Delta inventario TMF
I28: -19721 | J28: -8270.0017
I29: -2071 | J29: -852.74578 | P29: BALANCE
I30: 51 | J30: 34.489375
I31: 0 | J31: 0
I32: -21285 | J32: -13448.821
I33: -63213 | J33: -38546.284
I34: 1032 | J34: 613.6272
I35: =SUM(I28:I34) -> -105207 | J35: =SUM(J28:J34) -> -60469.736
