Workbook
Name vector1: Utilidad!$AK$102:$AK$106

Sheet Up
AD14: =SUM(AO37,AQ38:AR44) -> 78855.359 | AN14: =N53 -> 65407 | AY14: =AI53 -> 54106 | BK14: =BE53
D15: =AQ37/(1-'Datos Extra'!D27) -> 72939.359 | J15: =Report!P11 -> 0.6472 | Q15: =Flujos!G20/(Flujos!G18+Flujos!G16+Flujos!G15) -> 0.59739977 | W15: =Flujos!G20*Flujos!H20/(Flujos!G18*Flujos!H18+Flujos!G16*Flujos!H16+Flujos!G15*Flujos!H15) -> 0.89225688
A17: FLUJO DE PROCESO | AU17: PÉRDIDAS DEL PROCESO
B19: ALIMENTACIÓN MINA | K19: RECEPCIÓN TERCEROS | T19: PRODUCCIÓN PELLET FEED | AC19: TRANSPORTE FERROVIARIO | AL19: EMBARQUE PELLET FEED
B24: Tonelaje Húmedo | F24: (tmh) | H24: =Report!H11 -> 84594 | K24: Tonelaje Húmedo | O24: (tmh) | Q24: =Report!H13+Report!H14 -> 49169.81 | T24: Tonelaje Húmedo | X24: (tmh) | Z24: =Report!O11 -> 63191.172 | AC24: Tonelaje Húmedo | AG24: (tmh) | AI24: =Report!O21 -> 72939.359 | AL24: Tonelaje Húmedo | AP24: (tmh) | AR24: =Report!H21 -> 0
B26: Tonelaje Seco | F26: (tms) | H26: =Report!G11 -> 84594 | K26: Tonelaje Seco | O26: (tms) | Q26: =Report!G13+Report!G14 -> 47870 | T26: Tonelaje Seco | X26: (tms) | Z26: =Report!N11 -> 57667 | AC26: Tonelaje Seco | AG26: (tms) | AI26: =Report!N21 -> 66563 | AL26: Tonelaje Seco | AP26: (tms) | AR26: =Report!G21 -> 0 | AW26: ORIGEN | BH26: TMH | BK26: TMS | BN26: Ley FeT | BP26: TMF
AV27: Rechazos a botadero Chancado | BH27: =Report!O13 -> 31510.494 | BK27: =Report!N13 -> 28540 | BN27: =Report!P13 -> 0.13664455 | BP27: =BK27*BN27 -> 3899.8353
B28: Ley FeT | F28: (%) | H28: =Report!I11 -> 0.26850509 | K28: Ley FeT | O28: (%) | Q28: =(Report!G13*Report!I13+Report!G14*Report!I14)/(Report!G13+Report!G14) -> 0.46138468 | T28: Ley FeT | X28: (%) | Z28: =Report!P11 -> 0.6472 | AC28: Ley FeT | AG28: (%) | AI28: =Report!P21 -> 0.64721223 | AL28: Ley FeT | AP28: (%) | AR28: =Report!I21 -> 0 | AV28: Rechazos a botadero Concentradora | BH28: =Report!O14 -> 11197.693 | BK28: =Report!N14 -> 10522.696 | BN28: =Report!P14 -> 0.22467657 | BP28: =BK28*BN28 -> 2364.2032
AV29: Relaves Concentradora | BH29: - | BK29: =Report!N15 -> 6698.3042 | BN29: =Report!P15 -> 0.1098734 | BP29: =BK29*BN29 -> 735.96548
B30: Finos | F30: (tmf) | H30: =H26*H28 -> 22713.92 | K30: Finos | O30: (tmf) | Q30: =Q26*Q28 -> 22086.484 | T30: Finos | X30: (tmf) | Z30: =Z26*Z28 -> 37322.082 | AC30: Finos | AG30: (tmf) | AI30: =AI26*AI28 -> 43080.387 | AL30: Finos | AP30: (tmf) | AR30: =AI26*AI28 -> 43080.387 | AV30: Relaves Molienda | BH30: - | BK30: =Report!N16 -> 38863 | BN30: =Report!P16 -> 0.1159656 | BP30: =BK30*BN30 -> 4506.7712
A32: PLANTA ROMERAL | AF32: PUERTO GUAYACÁN
A34: OTROS FLUJOS | S34: INVENTARIOS | AF34: ENTRADAS | AY34: SALIDAS
J36: TMH | L36: TMS | N36: %FeT | P36: TMF | AA36: TMH | AC36: TMS | AO36: TMH | AQ36: TMS | AS36: %FeT | AU36: TMF | BG36: TMH | BI36: TMS | BK36: %FeT | BN36: TMF
B37: Producción Chancado | J37: =L37 -> 56054 | L37: =Flujos!G7 -> 56054 | N37: =Flujos!H7 -> 0.33564214 | P37: =L37*N37 -> 18814.085 | S37: Stock Intermedio | AA37: ='Datos Extra'!B1/(1-'Datos Extra'!D1) -> 33494.696 | AC37: ='Datos Extra'!B1 -> 33365.002 | AF37: Pellet Feed Acopiado (Trenes) | AO37: =AQ37/(1-'Datos Extra'!D27) -> 72939.359 | AQ37: =Flujos!G25 -> 66563 | AS37: =Flujos!H25 -> 0.64721223 | AU37: =AQ37*AS37 -> 43080.387 | AY37: Pellet Feed | BG37: =BI37/(1-'Datos Extra'!D23) -> 0 | BI37: ='Mapa de Procesos'!P102 -> 0 | BK37: =Flujos!H27 -> 0 | BN37: =BI37*BK37 -> 0
B38: Alimentación Concentradora | J38: =L38/(1-'Datos Extra'!D47) -> 69255.7 | L38: =Flujos!G10 -> 67525 | N38: =Flujos!H10 -> 0.35526036 | P38: =L38*N38 -> 23988.956 | S38: Stock Preconcentrado | AA38: ='Datos Extra'!B2/(1-'Datos Extra'!D2) -> 22033.794 | AC38: ='Datos Extra'!B2 -> 21178.288 | AF38: Sinter Feed MLC (camiones) | AO38: =AQ38/(1-'Datos Extra'!D30) -> 0 | AQ38: =Flujos!G35 -> 0 | AS38: =Flujos!H35 -> 0 | AU38: =AQ38*AS38 -> 0 | AY38: Sinter | BG38: =BI38/(1-'Datos Extra'!D24) -> 0 | BI38: =Flujos!G33 -> 0 | BK38: =Flujos!H33 -> 0 | BN38: =BI38*BK38 -> 0
B39: Producción Concentradora | J39: ='Datos Extra'!B48/(1-'Datos Extra'!D48)+Flujos!G15 -> 52227.488 | L39: =Flujos!G14+Flujos!G15 -> 50304 | N39: =(Flujos!G14*Flujos!H14+Flujos!G15*Flujos!H15)/(Flujos!G15+Flujos!G14) -> 0.41525102 | P39: =L39*N39 -> 20888.787 | S39: Stock Pellet Feed | AA39: ='Datos Extra'!B3/(1-'Datos Extra'!D3) -> 13532.792 | AC39: ='Datos Extra'!B3 -> 12349.755 | AF39: Sinter Feed Pleito (camiones) | AO39: =AQ39/(1-'Datos Extra'!D31) -> 0 | AQ39: =Flujos!G36 -> 0 | AS39: =Flujos!H36 -> 0 | AU39: =AQ39*AS39 -> 0 | AY39: Granzas | BG39: =BI39/(1-'Datos Extra'!D25) -> 0 | BI39: =Flujos!G40 -> 0 | BK39: =Flujos!H40 -> 0 | BN39: =BI39*BK39 -> 0
B40: Alimentación molienda | J40: ='Datos Extra'!B50/(1-'Datos Extra'!D50)+'Datos Extra'!B49/(1-'Datos Extra'!D49)+Flujos!G15 -> 100730.85 | L40: =Flujos!G18+Flujos!G16+Flujos!G15 -> 96530 | N40: =(Flujos!G15*Flujos!H15+Flujos!G16*Flujos!H16+Flujos!G18*Flujos!H18)/(Flujos!G18+Flujos!G16+Flujos!G15) -> 0.43332491 | P40: =L40*N40 -> 41828.854 | S40: Stock Sinter Feed Patio Tolva | AA40: ='Datos Extra'!B4/(1-'Datos Extra'!D4) -> 0 | AC40: ='Datos Extra'!B4 -> 0 | AF40: Sinter Feed APC (camiones) | AO40: =AQ40/(1-'Datos Extra'!D39) -> 2219.0813 | AQ40: =Flujos!G57 -> 2198 | AS40: =Flujos!H57 -> 0.6273 | AU40: =AQ40*AS40 -> 1378.8054 | AY40: Pellet Feed camiones locales | BG40: =BI40/(1-'Datos Extra'!D26) -> 62.460277 | BI40: =Flujos!G58 -> 57 | BK40: =Flujos!H58 -> 0.6472 | BN40: =BI40*BK40 -> 36.8904
B41: Producción Pellet Feed | J41: =L41/(1-'Datos Extra'!D28) -> 63191.172 | L41: =Flujos!G20 -> 57667 | N41: =Flujos!H20 -> 0.6472 | P41: =L41*N41 -> 37322.082 | AF41: Sinter Feed Caro (camiones) | AO41: =AQ41/(1-'Datos Extra'!D40) -> 1660.7702 | AQ41: =Flujos!G60 -> 1643 | AS41: =Flujos!H60 -> 0.616 | AU41: =AQ41*AS41 -> 1012.088 | AY41: Preconcentrado Ventas | BG41: =BI41/(1-'Datos Extra'!D41) -> 0 | BI41: =Flujos!G68 -> 0 | BK41: =Flujos!H68 -> 0 | BN41: =BI41*BK41 -> 0
AF42: Sinter SERCOOP (camiones) | AO42: =AQ42/(1-'Datos Extra'!D42) -> 387.16814 | AQ42: =Flujos!G66 -> 385 | AS42: =Flujos!H66 -> 0.6283 | AU42: =AQ42*AS42 -> 241.8955
AF43: Sinter Tofo (camiones) | AO43: =AQ43/(1-'Datos Extra'!D43) -> 360.3785 | AQ43: =Flujos!G67 -> 358 | AS43: =Flujos!H67 -> 0.6152 | AU43: =AQ43*AS43 -> 220.2416
AF44: Preconcentrado Ventas (Trenes) | AO44: =AQ44/(1-'Datos Extra'!D41) -> 1354.3467 | AQ44: =Flujos!G65 -> 1332 | AS44: =Flujos!H65 -> 0.5303 | AU44: =AQ44*AS44 -> 706.3596
A47: EMBARQUES DEL MES
E49: PELLET FEED | Z49: SINTER FEED | AV49: PRECONCENTRADO VENTAS
E50: MOTONAVE | J50: PESÓMETRO | N50: CALADO | R50: DIFERENCIA | V50: % | Z50: MOTONAVE | AE50: PESÓMETRO | AI50: CALADO | AM50: DIFERENCIA | AQ50: % | AV50: MOTONAVE | BA50: PESÓMETRO | BE50: CALADO | BI50: DIFERENCIA | BM50: %
E51: True Nautilus | J51: 65200 | N51: 65407 | R51: =IF(N51=0,"",N51-J51) -> 207 | V51: =IFERROR(R51/N51,"") -> 0.0031647989 | Z51: True Nautilus | AE51: 54430 | AI51: 54106 | AM51: =IF(AI51=0,"",AI51-AE51) -> -324 | AQ51: =IFERROR(AM51/AI51,"") -> -0.0059882453 | BM51: =IFERROR(BI51/BE51,"")
R52: =IF(N52=0,"",N52-J52) | V52: =IFERROR(R52/N52,"") | AM52: =IF(AI52=0,"",AI52-AE52) | AQ52: =IFERROR(AM52/AI52,"") | BM52: =IFERROR(BI52/BE52,"")
E53: TOTAL | J53: =IF(AND(J51="",J52=""),"",SUM(J51:M52)) -> 65200 | N53: =IF(AND(N51="",N52=""),"",SUM(N51:Q52)) -> 65407 | R53: =IF(AND(R51="",R52=""),"",SUM(R51:U52)) -> 207 | V53: =IFERROR(R53/N53,"") -> 0.0031647989 | Z53: TOTAL | AE53: =IF(AND(AE51="",AE52=""),"",SUM(AE51:AH52)) -> 54430 | AI53: =IF(AND(AI51="",AI52=""),"",SUM(AI51:AL52)) -> 54106 | AM53: =IF(AND(AM51="",AM52=""),"",SUM(AM51:AP52)) -> -324 | AQ53: =IFERROR(AM53/AI53,"") -> -0.0059882453 | AV53: TOTAL | BA53: =IF(AND(BA51="",BA52=""),"",SUM(BA51:BD52)) | BE53: =IF(AND(BE51="",BE52=""),"",SUM(BE51:BH52)) | BI53: =IF(AND(BI51="",BI52=""),"",SUM(BI51:BL52)) | BM53: =IFERROR(BI53/BE53,"")

Sheet Report
F3: BALANCE METALÚRGICO - VALLE ELQUI
F5: REPORTE MINAS EL ROMERAL | M5: FECHA DE BALANCE | P5: =TODAY()-2 -> 46280
G8: TONELAJE | I8: LEY | J8: FINO | N8: TONELAJE | P8: LEY | Q8: FINO
G9: TMS | H9: TMH | I9: % FeT | J9: TMF | N9: TMS | O9: TMH | P9: % FeT | Q9: TMF
D10: ENTRADAS | K10: PRODUCCIÓN PRIMARIA
C11: FL_218_501_01 | D11: Alimentación Chancado Mina | G11: =Flujos!G4 -> 84594 | H11: =G11/(1-'Datos Extra'!D18) -> 84594 | I11: =Flujos!H4 -> 0.26850509 | J11: =+I11*G11 -> 22713.92 | K11: Pellet Feed Producción Primaria | N11: =Flujos!G20 -> 57667 | O11: =N11/(1-'Datos Extra'!D28) -> 63191.172 | P11: =Flujos!H20 -> 0.6472 | Q11: =+P11*N11 -> 37322.082
D12: Recepción Mediana Ley Pleito | G12: =Flujos!G5 -> 0 | H12: =G12/(1-'Datos Extra'!D19) -> 0 | I12: =Flujos!H5 -> 0 | J12: =+I12*G12 -> 0 | K12: PÉRDIDAS
D13: Materiales a Stock Intermedio | G13: =Flujos!G8 -> 8985 | H13: =G13/(1-'Datos Extra'!D20) -> 9019.9259 | I13: =Flujos!H8 -> 0.4756 | J13: =+I13*G13 -> 4273.266 | K13: Rechazos a botadero Pta. Chancado | N13: =Flujos!G6 -> 28540 | O13: =N13*1/(1-'Datos Extra'!D35) -> 31510.494 | P13: =Flujos!H6 -> 0.13664455 | Q13: =+P13*N13 -> 3899.8353
D14: Materiales a Stock Preconcentrado | G14: =Flujos!G55 -> 38885 | H14: =G14/(1-'Datos Extra'!D21) -> 40149.884 | I14: =Flujos!H55 -> 0.4581 | J14: =+I14*G14 -> 17813.218 | K14: Rechazos a botadero Pta. Concentradora | N14: =Flujos!G12 -> 10522.696 | O14: =N14/(1-'Datos Extra'!D36) -> 11197.693 | P14: =Flujos!H12 -> 0.22467657 | Q14: =+P14*N14 -> 2364.2032
D15: Sinter Feed a Patio Tolva | G15: =Flujos!G31 -> 0 | H15: =G15*'Datos Extra'!D22+Report!G15 -> 0 | I15: =Flujos!H31 -> 0 | J15: =+I15*G15 -> 0 | K15: Colas Pta. Concentradora | N15: =Flujos!G13 -> 6698.3042 | P15: =Flujos!H13 -> 0.1098734 | Q15: =+P15*N15 -> 735.96548
K16: Colas Pta. Molienda | N16: =Flujos!G19 -> 38863 | P16: =Flujos!H19 -> 0.1159656 | Q16: =+P16*N16 -> 4506.7712
C19: FL_000_501_03 | D19: TOTAL | G19: =+SUM(G11:G15) -> 132464 | H19: =+SUM(H11:H15) -> 133763.81 | J19: =+SUM(J11:J15) -> 44800.404 | K19: TOTAL | N19: =+SUM(N13:N16) -> 84624 | O19: =+SUM(O13:O16) -> 42708.187 | Q19: =+SUM(Q13:Q16) -> 11506.775
D20: EMBARQUES - VENTAS LOCALES | K20: PRODUCCIÓN PUESTA EN PUERTO
D21: Pellet Feed | G21: ='Mapa de Procesos'!P102 -> 0 | H21: =G21/(1-'Datos Extra'!D23) -> 0 | I21: =Flujos!H27 -> 0 | J21: =+I21*G21 -> 0 | K21: Pellet Feed Acopiado (Trenes) | N21: =Flujos!G25 -> 66563 | O21: =N21/(1-'Datos Extra'!D27) -> 72939.359 | P21: =Flujos!H25 -> 0.64721223 | Q21: =+P21*N21 -> 43080.387
D22: Sinter | G22: =Flujos!G33 -> 0 | H22: =G22/(1-'Datos Extra'!D24) -> 0 | I22: =Flujos!H33 -> 0 | J22: =+I22*G22 -> 0 | K22: Sinter Feed MLC (camiones) | N22: =Flujos!G35 -> 0 | O22: =N22/(1-'Datos Extra'!D30) -> 0 | P22: =Flujos!H35 -> 0 | Q22: =+P22*N22 -> 0
D23: Granzas | G23: =Flujos!G40 -> 0 | H23: =G23/(1-'Datos Extra'!D25) -> 0 | I23: =Flujos!H40 -> 0 | J23: =+I23*G23 -> 0 | K23: Sinter Feed Pleito (camiones) | N23: =Flujos!G36 -> 0 | O23: =N23/(1-'Datos Extra'!D31) -> 0 | P23: =Flujos!H36 -> 0 | Q23: =+P23*N23 -> 0
D24: Pellet Feed camiones locales | G24: =Flujos!G58 -> 57 | H24: =G24/(1-'Datos Extra'!D41) -> 57.956279 | I24: =Flujos!H58 -> 0.6472 | J24: =G24*I24 -> 36.8904 | K24: Sinter Feed APC (camiones) | N24: =Flujos!G57 -> 2198 | O24: =N24/(1-'Datos Extra'!D39) -> 2219.0813 | P24: =Flujos!H57 -> 0.6273 | Q24: =+P24*N24 -> 1378.8054
D25: Preconcentrado Ventas | G25: =Flujos!G68 -> 0 | H25: =G25/(1-'Datos Extra'!D41) -> 0 | I25: =Flujos!H68 -> 0 | J25: =G25*I25 -> 0 | K25: Sinter Feed Caro (camiones) | N25: =Flujos!G60 -> 1643 | O25: =N25/(1-'Datos Extra'!D40) -> 1660.7702 | P25: =Flujos!H60 -> 0.616 | Q25: =+P25*N25 -> 1012.088
K26: Sinter SERCOOP (camiones) | N26: =Flujos!G66 -> 385 | O26: =N26/(1-'Datos Extra'!D42) -> 387.16814 | P26: =Flujos!H66 -> 0.6283 | Q26: =+P26*N26 -> 241.8955
K27: Sinter Tofo (camiones) | N27: =Flujos!G67 -> 358 | O27: =N27/(1-'Datos Extra'!D43) -> 360.3785 | P27: =Flujos!H67 -> 0.6152 | Q27: =+P27*N27 -> 220.2416
K28: Preconcentrado Ventas | N28: =Flujos!G65 -> 1332 | O28: =N28/(1-'Datos Extra'!D41) -> 1354.3467 | P28: =Flujos!H65 -> 0.5303 | Q28: =+P28*N28 -> 706.3596
K29: Granzas Pleito | N29: =Flujos!G37 -> 0 | O29: =N29/(1-'Datos Extra'!D33) -> 0 | P29: =Flujos!H37 -> 0 | Q29: =+P29*N29 -> 0
K30: Granzas Cristales | N30: =Flujos!G38 -> 0 | O30: =N30/(1-'Datos Extra'!D34) -> 0 | P30: =Flujos!H38 -> 0 | Q30: =+P30*N30 -> 0
D32: TOTAL | G32: =+SUM(G21:G24) -> 57 | H32: =+SUM(H21:H24) -> 57.956279 | J32: =+SUM(J21:J25) -> 36.8904 | K32: TOTAL | N32: =SUM(N21:N30) -> 72479 | O32: =SUM(O21:O30) -> 78921.104 | Q32: =SUM(Q21:Q30) -> 46639.777
D34: INVENTARIOS
G35: TMS | H35: TMH | I35: Delta inventario TMS | J35: Delta inventario TMFe
D36: Stock Intermedio | G36: ='Datos Extra'!B1 -> 33365.002 | H36: ='Datos Extra'!B1/(1-'Datos Extra'!D1) -> 33494.696 | I36: =Flujos!G9 -> -2486 | J36: ='Mapa de Procesos'!L128 -> -901.60555
D37: Stock Preconcentrado | G37: ='Datos Extra'!B2 -> 21178.288 | H37: ='Datos Extra'!B2/(1-'Datos Extra'!D2) -> 22033.794 | I37: =Flujos!G17 -> -7341 | J37: ='Mapa de Procesos'!L129 -> -3126.8476 | M37: ENTRADAS | N37: SALIDAS | O37: DELTA INVENTARIO | P37: BALANCE
D38: Stock Pellet Feed | G38: ='Datos Extra'!B3 -> 12349.755 | H38: ='Datos Extra'!B3/(1-'Datos Extra'!D3) -> 13532.792 | I38: =Flujos!G21 -> -10255 | J38: ='Mapa de Procesos'!L131 -> -6637.246 | L38: TMS | M38: =G19+SUM(N22:N30) -> 138380 | N38: =G21+G22+G23+N19+G24+G25 -> 84681 | O38: =I44 -> 52340 | P38: =M38-N38-O38 -> 1359
D39: Stock Sinter Feed Patio Tolva | G39: ='Datos Extra'!B4 -> 0 | H39: ='Datos Extra'!B4/(1-'Datos Extra'!D4) -> 0 | I39: =Flujos!G31 -> 0 | J39: ='Mapa de Procesos'!L132 -> 0 | L39: TMF | M39: =J19+SUM(Q22:Q30) -> 48359.794 | N39: =Q19+J21+J22+J23+J24 -> 11543.666 | O39: =J44 -> 35937.188 | P39: =M39-N39-O39 -> 878.94109
D40: Stock Pellet Feed Guayacán | G40: ='Datos Extra'!B5 -> 87771.515 | H40: ='Datos Extra'!B5/(1-'Datos Extra'!D5) -> 96179.53 | I40: =Flujos!G26 -> 66506 | J40: ='Mapa de Procesos'!L138 -> 43043.497
D41: Stock Sinter Guayacán | G41: ='Datos Extra'!B6 -> 13126.084 | H41: ='Datos Extra'!B6/(1-'Datos Extra'!D6) -> 13250.345 | I41: =Flujos!G34 -> 4584 | J41: ='Mapa de Procesos'!L139 -> 2853.0305
D42: Stock Granza Guayacán | G42: ='Datos Extra'!B7 -> 0 | H42: ='Datos Extra'!B7/(1-'Datos Extra'!D7) -> 0 | I42: =Flujos!G39 -> 0 | J42: ='Mapa de Procesos'!L140 -> 0
D43: Stock Preconcentrado Ventas | G43: ='Datos Extra'!B8 -> 1366.9568 | H43: ='Datos Extra'!B8/(1-'Datos Extra'!D8) -> 1389.89 | I43: =Flujos!G69 -> 1332 | J43: ='Mapa de Procesos'!L141 -> 706.3596
I44: =SUM(I36:I43) -> 52340 | J44: =SUM(J36:J43) -> 35937.188

Sheet Utilidad
A1: 84594 | B1: 84594 | C1: 27.51 | D1: 26.850509 | E1: 0
A2: 0 | B2: 0 | C2: 0 | D2: 0 | E2: 0
A3: 26228 | B3: 28540 | C3: 13.61 | D3: 13.664455 | E3: 0.10860011
A4: 56054 | B4: 56054 | C4: 34.56 | D4: 33.564214 | E4: 0
A5: 8985 | B5: 8985 | C5: 47.56 | D5: 47.56 | E5: 0.0038720801
A6: -4166 | B6: -2486 | C6: 36.35 | D6: 36.267319 | E6: 0.0038720801
A7: 67525 | B7: 67525 | C7: 36.31 | D7: 35.526036 | E7: 0.02499
A8: 0 | B8: 0 | C8: 0 | D8: 0 | E8: 0
A9: 10511 | B9: 10522.696 | C9: 22.29 | D9: 22.467657 | E9: 0.06028
A10: 6711 | B10: 6698.3042 | C10: 10.96 | D10: 10.98734 | E10: 0
A11: 39752 | B11: 39752 | C11: 40.78 | D11: 39.823325 | E11: 0.04615
A12: 10552 | B12: 10552 | C12: 48.26 | D12: 47.93612 | E12: 0
... A69: 0 | B69: 0 | C69: 0 | D69: 0 | E69: 0
I71: Cola Concentradora (canoa) | J71: =B10 -> 6698.3042 | K71: =IF(D10>1,D10/100,D10) -> 0.1098734 | L71: =+J71*K71 -> 735.96548
I72: Concentradora a Stock Preconcentrado | J72: =B11 -> 39752 | K72: =IF(D11>1,D11/100,D11) -> 0.39823325 | L72: =+J72*K72 -> 15830.568
I73: SF a molienda | J73: =B12 -> 10552 | K73: =IF(D12>1,D12/100,D12) -> 0.4793612 | L73: =+J73*K73 -> 5058.2194
I74: Repulpeo | J74: =B13 -> 8741 | K74: =IF(D13>1,D13/100,D13) -> 0.47725728 | L74: =+J74*K74 -> 4171.7059
I75: Delta Stock Preconcentrado | J75: =B14 -> -7341 | K75: =IF(D14>1,D14/100,D14) -> 0.42594301 | L75: =+J75*K75 -> -3126.8476
I76: Alimentación Preconcentrado a Molienda | J76: =B15 -> 77237 | K76: =IF(D15>1,D15/100,D15) -> 0.42206363 | L76: =+J76*K76 -> 32598.928
I77: Cola de Molienda | J77: =B16 -> 38863 | K77: =IF(D16>1,D16/100,D16) -> 0.1159656 | L77: =+J77*K77 -> 4506.7712
I78: Concentrado a Almacenamiento | J78: =B17 -> 57667 | K78: =IF(D17>1,D17/100,D17) -> 0.6472 | L78: =+J78*K78 -> 37322.082
I79: Delta Almacenamiento de Concentrado | J79: =B18 -> -10255 | K79: =IF(D18>1,D18/100,D18) -> 0.64722048 | L79: =+J79*K79 -> -6637.246
I80: Concentrado a Stock Pellet Feed ROM | J80: =B19 -> 0 | K80: =IF(D19>1,D19/100,D19) -> 0 | L80: =+J80*K80 -> 0
I81: Delta Stock Pellet Feed ROM | J81: =B20 -> 67922 | K81: =IF(D20>1,D20/100,D20) -> 0.64720309 | L81: =+J81*K81 -> 43959.328
I82: Transporte Pellet Feed en camiones a Guayacan | J82: =B21 -> 1358 | K82: =IF(D21>1,D21/100,D21) -> 0.64723203 | L82: =+J82*K82 -> 878.94109
... I116: De nodo Alim Otros Materiales + Emergencia a S Preconcentrado | J116: =B55 -> 57 | K116: =IF(D55>1,D55/100,D55) -> 0.6472 | L116: =+J116*K116 -> 36.8904

Sheet Datos Extra
A1: Stock Intermedio | B1: 33365.002 | C1: 0.36353435 | D1: 0.0038720801
A2: Stock Preconcentrado | B2: 21178.288 | C2: 0.432641 | D2: 0.038827025
A3: Stock Pellet Feed | B3: 12349.755 | C3: 0.64722 | D3: 0.08742
A4: Stock Sinter Feed Patio Tolva | B4: 0 | C4: 0 | D4: 0
A5: Stock Pellet Feed Guayacan | B5: 87771.515 | C5: 0.64722 | D5: 0.08742
A6: Stock Sinter Guayacan | B6: 13126.084 | C6: 0.6217 | D6: 0.0093779988
A7: Stock Granza Guayacan | B7: 0 | C7: 0 | D7: 0
A8: Stock Preconcentrado Ventas | B8: 1366.9568 | C8: 0.5303 | D8: 0.0165
A9: Pellet Feed Produccion Primaria | B9: 57667.002 | C9: 0.64722 | D9: 0.08742
A10: Sinter Feed MLC camiones | B10: 0 | C10: 0 | D10: 0
A11: Sinter Feed Pleito camiones | B11: 0 | C11: 0 | D11: 0
A12: Sinter Feed Infiernillo camiones | B12: 2197.6719 | C12: 0.6273 | D12: 0.0095
... A50: Alimentacion Preconcentrado a Moli | B50: 77237.33 | C50: 0.42029 | D50: 0.04359

Sheet Flujos
B2: Mediciones | F2: Balance | J2: % Cambio relativo | M2: Max Var Ton | N2: Max Var FeT
B3: Flujos | C3: TMS | D3: %FeT | F3: Flujos | G3: TMS | H3: %FeT | J3: TMSD | K3: %Fe T
B4: Alim Mina | C4: =Utilidad!A1 -> 84594 | D4: =IF(Utilidad!C1>1,Utilidad!C1/100,Utilidad!C1) -> 0.2751 | F4: Alim Mina | G4: =Utilidad!B1 -> 84594 | H4: =IF(Utilidad!D1>1,Utilidad!D1/100,Utilidad!D1) -> 0.26850509 | J4: =+IF(C4<>0,(G4-C4)/C4,ABS(G4-C4)) -> 0 | K4: =+IF(D4<>0,(H4-D4)/D4,0) -> -0.023972762 | M4: =+IF(J4<>"",ABS(J4),0) -> 0 | N4: =+IF(J4<>"",ABS(K4),0) -> 0.023972762
B5: Alim ML Pleito a CH-CM | C5: =Utilidad!A2 -> 0 | D5: =IF(Utilidad!C2>1,Utilidad!C2/100,Utilidad!C2) -> 0 | F5: Alim ML Pleito a CH-CM | G5: =Utilidad!B2 -> 0 | H5: =IF(Utilidad!D2>1,Utilidad!D2/100,Utilidad!D2) -> 0 | J5: =+IF(C5<>0,(G5-C5)/C5,ABS(G5-C5)) -> 0 | K5: =+IF(D5<>0,(H5-D5)/D5,0) -> 0 | M5: =+IF(J5<>"",ABS(J5),0) -> 0 | N5: =+IF(J5<>"",ABS(K5),0) -> 0
B6: Rechazos | C6: =Utilidad!A3 -> 26228 | D6: =IF(Utilidad!C3>1,Utilidad!C3/100,Utilidad!C3) -> 0.1361 | F6: Rechazos | G6: =Utilidad!B3 -> 28540 | H6: =IF(Utilidad!D3>1,Utilidad!D3/100,Utilidad!D3) -> 0.13664455 | J6: =+IF(C6<>0,(G6-C6)/C6,ABS(G6-C6)) -> 0.088150069 | K6: =+IF(D6<>0,(H6-D6)/D6,0) -> 0.0040010709 | M6: =+IF(J6<>"",ABS(J6),0) -> 0.088150069 | N6: =+IF(J6<>"",ABS(K6),0) -> 0.0040010709
B7: Producción CH a Stock Intermedio | C7: =Utilidad!A4 -> 56054 | D7: =IF(Utilidad!C4>1,Utilidad!C4/100,Utilidad!C4) -> 0.3456 | F7: Producción CH a Stock Intermedio | G7: =Utilidad!B4 -> 56054 | H7: =IF(Utilidad!D4>1,Utilidad!D4/100,Utilidad!D4) -> 0.33564214 | J7: =+IF(C7<>0,(G7-C7)/C7,ABS(G7-C7)) -> 0 | K7: =+IF(D7<>0,(H7-D7)/D7,0) -> -0.028813252 | M7: =+IF(J7<>"",ABS(J7),0) -> 0 | N7: =+IF(J7<>"",ABS(K7),0) -> 0.028813252
B8: Otros Materiales desde Pleito a Stock Intermedio | C8: =Utilidad!A5 -> 8985 | D8: =IF(Utilidad!C5>1,Utilidad!C5/100,Utilidad!C5) -> 0.4756 | F8: Otros Materiales desde Pleito a Stock Intermedio | G8: =Utilidad!B5 -> 8985 | H8: =IF(Utilidad!D5>1,Utilidad!D5/100,Utilidad!D5) -> 0.4756 | J8: =+IF(C8<>0,(G8-C8)/C8,ABS(G8-C8)) -> 0 | K8: =+IF(D8<>0,(H8-D8)/D8,0) -> 0 | M8: =+IF(J8<>"",ABS(J8),0) -> 0 | N8: =+IF(J8<>"",ABS(K8),0) -> 0
B9: Delta Stock Intermedio | C9: =Utilidad!A6 -> -4166 | D9: =IF(Utilidad!C6>1,Utilidad!C6/100,Utilidad!C6) -> 0.3635 | F9: Delta Stock Intermedio | G9: =Utilidad!B6 -> -2486 | H9: =IF(Utilidad!D6>1,Utilidad!D6/100,Utilidad!D6) -> 0.36267319 | J9: =+IF(C9<>0,(G9-C9)/C9,ABS(G9-C9)) -> -0.40326452 | K9: =+IF(D9<>0,(H9-D9)/D9,0) -> -0.0022745834 | M9: =+IF(J9<>"",ABS(J9),0) -> 0.40326452 | N9: =+IF(J9<>"",ABS(K9),0) -> 0.0022745834 | Q9: =G10-G14-G15 -> 17221
B10: Alimentación a Concentradora | C10: =Utilidad!A7 -> 67525 | D10: =IF(Utilidad!C7>1,Utilidad!C7/100,Utilidad!C7) -> 0.3631 | F10: Alimentación a Concentradora | G10: =Utilidad!B7 -> 67525 | H10: =IF(Utilidad!D7>1,Utilidad!D7/100,Utilidad!D7) -> 0.35526036 | J10: =+IF(C10<>0,(G10-C10)/C10,ABS(G10-C10)) -> 0 | K10: =+IF(D10<>0,(H10-D10)/D10,0) -> -0.021590846 | M10: =+IF(J10<>"",ABS(J10),0) -> 0 | N10: =+IF(J10<>"",ABS(K10),0) -> 0.021590846 | Q10: =G13+G12 -> 17221
B11: By Pass Stock Intermedio a Stock Preconcentrado | C11: =Utilidad!A8 -> 0 | D11: =IF(Utilidad!C8>1,Utilidad!C8/100,Utilidad!C8) -> 0 | F11: By Pass Stock Intermedio a Stock Preconcentrado | G11: =Utilidad!B8 -> 0 | H11: =IF(Utilidad!D8>1,Utilidad!D8/100,Utilidad!D8) -> 0 | J11: =+IF(C11<>0,(G11-C11)/C11,ABS(G11-C11)) -> 0 | K11: =+IF(D11<>0,(H11-D11)/D11,0) -> 0 | M11: =+IF(J11<>"",ABS(J11),0) -> 0 | N11: =+IF(J11<>"",ABS(K11),0) -> 0
B12: Rechazo a Botadero | C12: =Utilidad!A9 -> 10511 | D12: =IF(Utilidad!C9>1,Utilidad!C9/100,Utilidad!C9) -> 0.2229 | F12: Rechazo a Botadero | G12: =Utilidad!B9 -> 10522.696 | H12: =IF(Utilidad!D9>1,Utilidad!D9/100,Utilidad!D9) -> 0.22467657 | J12: =+IF(C12<>0,(G12-C12)/C12,ABS(G12-C12)) -> 0.0011127194 | K12: =+IF(D12<>0,(H12-D12)/D12,0) -> 0.0079702396 | M12: =+IF(J12<>"",ABS(J12),0) -> 0.0011127194 | N12: =+IF(J12<>"",ABS(K12),0) -> 0.0079702396
B13: Cola Concentradora (canoa) | C13: =Utilidad!A10 -> 6711 | D13: =IF(Utilidad!C10>1,Utilidad!C10/100,Utilidad!C10) -> 0.1096 | F13: Cola Concentradora (canoa) | G13: =Utilidad!B10 -> 6698.3042 | H13: =IF(Utilidad!D10>1,Utilidad!D10/100,Utilidad!D10) -> 0.1098734 | J13: =+IF(C13<>0,(G13-C13)/C13,ABS(G13-C13)) -> -0.0018917887 | K13: =+IF(D13<>0,(H13-D13)/D13,0) -> 0.0024945515 | M13: =+IF(J13<>"",ABS(J13),0) -> 0.0018917887 | N13: =+IF(J13<>"",ABS(K13),0) -> 0.0024945515
B14: Concentradora a Stock Preconcentrado | C14: =Utilidad!A11 -> 39752 | D14: =IF(Utilidad!C11>1,Utilidad!C11/100,Utilidad!C11) -> 0.4078 | F14: Concentradora a Stock Preconcentrado | G14: =Utilidad!B11 -> 39752 | H14: =IF(Utilidad!D11>1,Utilidad!D11/100,Utilidad!D11) -> 0.39823325 | J14: =+IF(C14<>0,(G14-C14)/C14,ABS(G14-C14)) -> 0 | K14: =+IF(D14<>0,(H14-D14)/D14,0) -> -0.023459422 | M14: =+IF(J14<>"",ABS(J14),0) -> 0 | N14: =+IF(J14<>"",ABS(K14),0) -> 0.023459422
B15: SF a molienda | C15: =Utilidad!A12 -> 10552 | D15: =IF(Utilidad!C12>1,Utilidad!C12/100,Utilidad!C12) -> 0.4826 | F15: SF a molienda | G15: =Utilidad!B12 -> 10552 | H15: =IF(Utilidad!D12>1,Utilidad!D12/100,Utilidad!D12) -> 0.4793612 | J15: =+IF(C15<>0,(G15-C15)/C15,ABS(G15-C15)) -> 0 | K15: =+IF(D15<>0,(H15-D15)/D15,0) -> -0.0067111502 | M15: =+IF(J15<>"",ABS(J15),0) -> 0 | N15: =+IF(J15<>"",ABS(K15),0) -> 0.0067111502
B16: Repulpeo | C16: =Utilidad!A13 -> 8741 | D16: =IF(Utilidad!C13>1,Utilidad!C13/100,Utilidad!C13) -> 0.477 | F16: Repulpeo | G16: =Utilidad!B13 -> 8741 | H16: =IF(Utilidad!D13>1,Utilidad!D13/100,Utilidad!D13) -> 0.47725728 | I16: =(G14*H14+G15*H15)/(G14+G15)*100 -> 41.525102 | J16: =+IF(C16<>0,(G16-C16)/C16,ABS(G16-C16)) -> 0 | K16: =+IF(D16<>0,(H16-D16)/D16,0) -> 0.00053938113 | M16: =+IF(J16<>"",ABS(J16),0) -> 0 | N16: =+IF(J16<>"",ABS(K16),0) -> 0.00053938113
B17: Delta Stock Preconcentrado | C17: =Utilidad!A14 -> -8730 | D17: =IF(Utilidad!C14>1,Utilidad!C14/100,Utilidad!C14) -> 0.4326 | F17: Delta Stock Preconcentrado | G17: =Utilidad!B14 -> -7341 | H17: =IF(Utilidad!D14>1,Utilidad!D14/100,Utilidad!D14) -> 0.42594301 | J17: =+IF(C17<>0,(G17-C17)/C17,ABS(G17-C17)) -> -0.15910653 | K17: =+IF(D17<>0,(H17-D17)/D17,0) -> -0.015388332 | M17: =+IF(J17<>"",ABS(J17),0) -> 0.15910653 | N17: =+IF(J17<>"",ABS(K17),0) -> 0.015388332
B18: Alimentación Preconcentrado a Molienda | C18: =Utilidad!A15 -> 77237 | D18: =IF(Utilidad!C15>1,Utilidad!C15/100,Utilidad!C15) -> 0.4203 | F18: Alimentación Preconcentrado a Molienda | G18: =Utilidad!B15 -> 77237 | H18: =IF(Utilidad!D15>1,Utilidad!D15/100,Utilidad!D15) -> 0.42206363 | J18: =+IF(C18<>0,(G18-C18)/C18,ABS(G18-C18)) -> 0 | K18: =+IF(D18<>0,(H18-D18)/D18,0) -> 0.0041961116 | M18: =+IF(J18<>"",ABS(J18),0) -> 0 | N18: =+IF(J18<>"",ABS(K18),0) -> 0.0041961116
B19: Cola de Molienda | C19: =Utilidad!A16 -> 27513 | D19: =IF(Utilidad!C16>1,Utilidad!C16/100,Utilidad!C16) -> 0.1136 | F19: Cola de Molienda | G19: =Utilidad!B16 -> 38863 | H19: =IF(Utilidad!D16>1,Utilidad!D16/100,Utilidad!D16) -> 0.1159656 | J19: =+IF(C19<>0,(G19-C19)/C19,ABS(G19-C19)) -> 0.41253226 | K19: =+IF(D19<>0,(H19-D19)/D19,0) -> 0.020823954 | M19: =+IF(J19<>"",ABS(J19),0) -> 0.41253226 | N19: =+IF(J19<>"",ABS(K19),0) -> 0.020823954
B20: Concentrado a Stock Pellet Feed ROM | C20: =Utilidad!A17 -> 57667 | D20: =IF(Utilidad!C17>1,Utilidad!C17/100,Utilidad!C17) -> 0.6472 | F20: Concentrado a Stock Pellet Feed ROM | G20: =Utilidad!B17 -> 57667 | H20: =IF(Utilidad!D17>1,Utilidad!D17/100,Utilidad!D17) -> 0.6472 | J20: =+IF(C20<>0,(G20-C20)/C20,ABS(G20-C20)) -> 0 | K20: =+IF(D20<>0,(H20-D20)/D20,0) -> 0 | M20: =+IF(J20<>"",ABS(J20),0) -> 0 | N20: =+IF(J20<>"",ABS(K20),0) -> 0
B21: Delta Stock Pellet Feed ROM | C21: =Utilidad!A18 -> -10255 | D21: =IF(Utilidad!C18>1,Utilidad!C18/100,Utilidad!C18) -> 0.6472 | F21: Delta Stock Pellet Feed ROM | G21: =Utilidad!B18 -> -10255 | H21: =IF(Utilidad!D18>1,Utilidad!D18/100,Utilidad!D18) -> 0.64722048 | J21: =+IF(C21<>0,(G21-C21)/C21,ABS(G21-C21)) -> 0 | K21: =+IF(D21<>0,(H21-D21)/D21,0) -> 3.1647389e-05 | M21: =+IF(J21<>"",ABS(J21),0) -> 0 | N21: =+IF(J21<>"",ABS(K21),0) -> 3.1647389e-05
B22: Transporte Pellet Feed en camiones a Guayacan | C22: =Utilidad!A19 -> 0 | D22: =IF(Utilidad!C19>1,Utilidad!C19/100,Utilidad!C19) -> 0 | F22: Transporte Pellet Feed en camiones a Guayacan | G22: =Utilidad!B19 -> 0 | H22: =IF(Utilidad!D19>1,Utilidad!D19/100,Utilidad!D19) -> 0 | J22: =+IF(C22<>0,(G22-C22)/C22,ABS(G22-C22)) -> 0 | K22: =+IF(D22<>0,(H22-D22)/D22,0) -> 0 | M22: =+IF(J22<>"",ABS(J22),0) -> 0 | N22: =+IF(J22<>"",ABS(K22),0) -> 0
B23: Transporte Pellet Feed en Trenes a Guayacan | C23: =Utilidad!A20 -> 67922 | D23: =IF(Utilidad!C20>1,Utilidad!C20/100,Utilidad!C20) -> 0.6472 | F23: Transporte Pellet Feed en Trenes a Guayacan | G23: =Utilidad!B20 -> 67922 | H23: =IF(Utilidad!D20>1,Utilidad!D20/100,Utilidad!D20) -> 0.64720309 | J23: =+IF(C23<>0,(G23-C23)/C23,ABS(G23-C23)) -> 0 | K23: =+IF(D23<>0,(H23-D23)/D23,0) -> 4.7781829e-06 | M23: =+IF(J23<>"",ABS(J23),0) -> 0 | N23: =+IF(J23<>"",ABS(K23),0) -> 4.7781829e-06
B24: Pérdidas Pellet Feed por Transporte | C24: =Utilidad!A21 -> 1358 | D24: =IF(Utilidad!C21>1,Utilidad!C21/100,Utilidad!C21) -> 0.6472 | F24: Pérdidas Pellet Feed por Transporte | G24: =Utilidad!B21 -> 1358 | H24: =IF(Utilidad!D21>1,Utilidad!D21/100,Utilidad!D21) -> 0.64723203 | J24: =+IF(C24<>0,(G24-C24)/C24,ABS(G24-C24)) -> 0 | K24: =+IF(D24<>0,(H24-D24)/D24,0) -> 4.9483529e-05 | M24: =+IF(J24<>"",ABS(J24),0) -> 0 | N24: =+IF(J24<>"",ABS(K24),0) -> 4.9483529e-05
B25: Recepción total en Stock Pellet Feed Guayacan | C25: =Utilidad!A22 -> 66563 | D25: =IF(Utilidad!C22>1,Utilidad!C22/100,Utilidad!C22) -> 0.6472 | F25: Recepción total en Stock Pellet Feed Guayacan | G25: =Utilidad!B22 -> 66563 | H25: =IF(Utilidad!D22>1,Utilidad!D22/100,Utilidad!D22) -> 0.64721223 | J25: =+IF(C25<>0,(G25-C25)/C25,ABS(G25-C25)) -> 0 | K25: =+IF(D25<>0,(H25-D25)/D25,0) -> 1.8889555e-05 | M25: =+IF(J25<>"",ABS(J25),0) -> 0 | N25: =+IF(J25<>"",ABS(K25),0) -> 1.8889555e-05
B26: Delta Stock Pellet Feed Guayacan | C26: =Utilidad!A23 -> 66506 | D26: =IF(Utilidad!C23>1,Utilidad!C23/100,Utilidad!C23) -> 0.6472 | F26: Delta Stock Pellet Feed Guayacan | G26: =Utilidad!B23 -> 66506 | H26: =IF(Utilidad!D23>1,Utilidad!D23/100,Utilidad!D23) -> 0.64721224 | J26: =+IF(C26<>0,(G26-C26)/C26,ABS(G26-C26)) -> 0 | K26: =+IF(D26<>0,(H26-D26)/D26,0) -> 1.8905748e-05 | M26: =+IF(J26<>"",ABS(J26),0) -> 0 | N26: =+IF(J26<>"",ABS(K26),0) -> 1.8905748e-05
B27: Embarque Pellet Feed Guayacan | C27: =Utilidad!A24 -> 0 | D27: =IF(Utilidad!C24>1,Utilidad!C24/100,Utilidad!C24) -> 0 | F27: Embarque Pellet Feed Guayacan | G27: =Utilidad!B24 -> 0 | H27: =IF(Utilidad!D24>1,Utilidad!D24/100,Utilidad!D24) -> 0 | J27: =+IF(C27<>0,(G27-C27)/C27,ABS(G27-C27)) -> 0 | K27: =+IF(D27<>0,(H27-D27)/D27,0) -> 0 | M27: =+IF(J27<>"",ABS(J27),0) -> 0 | N27: =+IF(J27<>"",ABS(K27),0) -> 0
B28: Transporte Camiones PF Guayacan | C28: =Utilidad!A25 -> 0 | D28: =IF(Utilidad!C25>1,Utilidad!C25/100,Utilidad!C25) -> 0 | F28: Transporte Camiones PF Guayacan | G28: =Utilidad!B25 -> 0 | H28: =IF(Utilidad!D25>1,Utilidad!D25/100,Utilidad!D25) -> 0 | J28: =+IF(C28<>0,(G28-C28)/C28,ABS(G28-C28)) -> 0 | K28: =+IF(D28<>0,(H28-D28)/D28,0) -> 0 | M28: =+IF(J28<>"",ABS(J28),0) -> 0 | N28: =+IF(J28<>"",ABS(K28),0) -> 0
... B72: Premixto PL | C72: =Utilidad!A69 -> 0 | D72: =IF(Utilidad!C69>1,Utilidad!C69/100,Utilidad!C69) -> 0 | F72: Premixto PL | G72: =Utilidad!B69 -> 0 | H72: =IF(Utilidad!D69>1,Utilidad!D69/100,Utilidad!D69) -> 0 | J72: =+IF(C72<>0,(G72-C72)/C72,ABS(G72-C72)) -> 0 | K72: =+IF(D72<>0,(H72-D72)/D72,0) -> 0 | M72: =+IF(J72<>"",ABS(J72),0) -> 0 | N72: =+IF(J72<>"",ABS(K72),0) -> 0

Sheet Mapa de Procesos
E6: =Flujos!G4 -> 84594
E7: =Flujos!H4 -> 0.26850509 | I7: =+Utilidad!J65 -> 0 | L7: =+Utilidad!J68 -> 0 | Q7: =Flujos!G12 -> 10522.696
E8: =E6*E7 -> 22713.92 | I8: =+Utilidad!K65 -> 0 | L8: =+Utilidad!K68 -> 0 | Q8: =Flujos!H12 -> 0.22467657
I9: =+Utilidad!L65 -> 0 | L9: =+Utilidad!L68 -> 0 | Q9: =Q7*Q8 -> 2364.2032
E10: =+Utilidad!J63 -> 0
E11: =+Utilidad!K63 -> 0 | Q11: =+Utilidad!J71 -> 6698.3042
C12: =+Utilidad!J101 -> 0 | E12: =+Utilidad!L63 -> 0 | Q12: =+Utilidad!K71 -> 0.1098734
C13: =+Utilidad!K101 -> 0 | H13: =+Utilidad!J66 -> 0 | N13: =+Utilidad!J72 -> 39752 | Q13: =+Utilidad!L71 -> 735.96548
C14: =+Utilidad!L101 -> 0 | H14: =+Utilidad!K66 -> 0 | J14: =+I7+H13-L14-L7 -> 0 | L14: =+Utilidad!J69 -> 0 | N14: =+Utilidad!K72 -> 0.39823325
G15: =Flujos!G6 -> 28540 | H15: =+Utilidad!L66 -> 0 | L15: =+Utilidad!K69 -> 0 | N15: =+Utilidad!L72 -> 15830.568
E16: =+C12-E10 -> 0 | G16: =Flujos!H6 -> 0.13664455 | L16: =+Utilidad!L69 -> 0 | P16: Resguardo
G17: =G15*G16 -> 3899.8353 | P17: =Flujos!G70 -> 0
K18: =Flujos!C56 -> 38885 | P18: =Flujos!H70 -> 0
K19: =Flujos!D56 -> 0.4581 | P19: =P17*P18 -> 0
K20: =K18*K19 -> 17813.218 | L20: =+Utilidad!J76 -> 77237 | N20: =+L14+N13+K18-M22-L20 -> -7341
L22: =+Utilidad!K76 -> 0.42206363 | M22: =+Utilidad!J74 -> 8741 | O22: =+Utilidad!J73 -> 10552
L23: =+Utilidad!L76 -> 32598.928 | M23: =+Utilidad!K74 -> 0.47725728 | O23: =+Utilidad!K73 -> 0.4793612
M24: =+Utilidad!L74 -> 4171.7059 | O24: =+Utilidad!L73 -> 5058.2194 | Q24: =+(O22+N13)/(L7) -> #DIV/0!
G25: =+Utilidad!J105 -> 0
C26: =+Utilidad!J103 -> 0 | G26: =+Utilidad!K105 -> 0
C27: =+Utilidad!K103 -> 0 | G27: =+Utilidad!L105 -> 0 | Q27: =+(K28)/(L20+M22+O22) -> 0.59739977
C28: =+Utilidad!L103 -> 0 | K28: =+Utilidad!J78 -> 57667
F29: =+C26-G25 -> 0 | K29: =+Utilidad!K78 -> 0.6472 | M29: =K28/(L20+M22+O22) -> 0.59739977 | O29: =O22+L20+M22 -> 96530
I30: =+Utilidad!J77 -> 38863 | K30: =+Utilidad!L78 -> 37322.082 | O30: =O29-K28 -> 38863
I31: =+Utilidad!K77 -> 0.1159656
I32: =I30*I31 -> 4506.7712
G34: =+Utilidad!J108 -> 0
C35: =+Utilidad!J106 -> 0 | G35: =+Utilidad!K108 -> 0
C36: =+Utilidad!K106 -> 0 | G36: =+Utilidad!L108 -> 0
C37: =+Utilidad!L106 -> 0
F38: =+C35-G34 -> 0
K39: =K28-(I53+L53) -> -10254
C44: =+Utilidad!J109 -> 0 | G44: =+Utilidad!J111 -> 0
C45: =+Utilidad!K109 -> 0 | G45: =+Utilidad!K111 -> 0
C46: =+Utilidad!L109 -> 0 | G46: =+Utilidad!L111 -> 0
F48: =+C44-G44 -> 0
I53: =+Utilidad!J82 -> 1358 | L53: =+Utilidad!J83 -> 66563
C54: =+Utilidad!J112 -> 0 | I54: =+Utilidad!K82 -> 0.64723203 | L54: =+Utilidad!K83 -> 0.64721223
C55: =+Utilidad!K112 -> 0 | I55: =+Utilidad!L82 -> 878.94109 | L55: =+Utilidad!L83 -> 43080.387
C56: =+Utilidad!L112 -> 0
...
