Workbook
Name solver_adj: Utilidad!$O$68:$P$120
Name solver_cvg: 0.0001
Name solver_drv: 1
Name solver_eng: 1
Name solver_eng: 1
Name solver_est: 1
Name solver_itr: 2147483647
Name solver_lhs1: Utilidad!$AC$68:$AC$89
Name solver_lhs10: Utilidad!$W$113
Name solver_lhs11: Utilidad!$W$95
Name solver_lhs12: Utilidad!$AA$63
Name solver_lhs13: Utilidad!$AA$64
Name solver_lhs14: Utilidad!$AA$65
Name solver_lhs15: Utilidad!$AA$66
Name solver_lhs16: Utilidad!$AA$67
Name solver_lhs17: Utilidad!$AA$68
Name solver_lhs18: Utilidad!$AA$69
Name solver_lhs19: Utilidad!$AB$52
Name solver_lhs2: Utilidad!$AD$68:$AD$89
Name solver_lhs20: Utilidad!$AB$53
Name solver_lhs21: Utilidad!$AB$54
Name solver_lhs22: Utilidad!$AB$55
Name solver_lhs23: Utilidad!$AB$56
Name solver_lhs24: Utilidad!$AB$57
Name solver_lhs25: Utilidad!$AB$58
Name solver_lhs26: Utilidad!$AB$59
Name solver_lhs27: Utilidad!$AB$60
Name solver_lhs28: Utilidad!$AB$61
Name solver_lhs29: Utilidad!$AB$62
Name solver_lhs3: Utilidad!$U$113
Name solver_lhs30: Utilidad!$AB$63
Name solver_lhs31: Utilidad!$AB$64
Name solver_lhs32: Utilidad!$AB$65
Name solver_lhs33: Utilidad!$AB$66
Name solver_lhs34: Utilidad!$AB$67
Name solver_lhs35: Utilidad!$AB$68
Name solver_lhs36: Utilidad!$AB$69
Name solver_lhs37: Utilidad!$U$52
Name solver_lhs38: Utilidad!$U$54
Name solver_lhs39: Utilidad!$U$55
Name solver_lhs4: Utilidad!$U$120
Name solver_lhs40: Utilidad!$U$58
Name solver_lhs41: Utilidad!$U$60
Name solver_lhs42: Utilidad!$U$61
Name solver_lhs43: Utilidad!$U$64
Name solver_lhs44: Utilidad!$U$67
Name solver_lhs45: Utilidad!$U$70
Name solver_lhs46: Utilidad!$U$73
Name solver_lhs47: Utilidad!$U$79
Name solver_lhs48: Utilidad!$U$95
Name solver_lhs49: Utilidad!$W$79
Name solver_lhs5: Utilidad!$U$68:$U$95
Name solver_lhs50: Utilidad!$W$95
Name solver_lhs6: Utilidad!$W$102:$W$111
Name solver_lhs7: Utilidad!$W$113
Name solver_lhs8: Utilidad!$W$95
Name solver_lhs9: Utilidad!$U$68:$U$95
Name solver_lin: 2
Name solver_lin: 2
Name solver_mip: 2147483647

Sheet Utilidad
A1: 0 | B1: 0 | C1: 56.57 | D1: 56.56086 | E1: 54.24 | F1: 54.249789 | G1: 0
A2: 0 | B2: 0 | C2: 56.57 | D2: 56.56086 | E2: 54.24 | F2: 54.249789 | G2: 0 | AN2: 1 | AO2: =AN2+1 -> 2 | AP2: =AO2+1 -> 3 | AQ2: =AP2+1 -> 4 | AR2: =AQ2+1 -> 5 | AS2: =AR2+1 -> 6 | AT2: =AS2+1 -> 7 | AU2: =AT2+1 -> 8 | AV2: =AU2+1 -> 9 | ... CE2: =CD2+1 -> 44
A3: 0 | B3: 0 | C3: 56.57 | D3: 56.56519 | E3: 54.24 | F3: 54.244773 | G3: 0
A4: 2249 | B4: 2249 | C4: 39.32 | D4: 39.769437 | E4: 36.89 | F4: 36.468211 | G4: 0
A5: -406 | B5: -405.02495 | C5: 39.32 | D5: 39.400929 | E5: 36.89 | F5: 36.814781 | G5: 0
A6: 2655 | B6: 2654.025 | C6: 39.32 | D6: 39.7132 | E6: 36.89 | F6: 36.5211 | G6: 0
A7: 9579 | B7: 9579 | C7: 40.49 | D7: 40.868513 | E7: 37.87 | F7: 37.516123 | G7: 0
A8: -10902 | B8: -10850.798 | C8: 40.49 | D8: 40.918195 | E8: 37.87 | F8: 37.469387 | G8: 0
A9: 20481 | B9: 20429.798 | C9: 40.49 | D9: 40.8949 | E9: 37.87 | F9: 37.4913 | G9: 0
A10: 0 | B10: 0 | C10: 41.05 | D10: 41.050812 | E10: 37.81 | F10: 37.809257 | G10: 0
A11: 0 | B11: 0 | C11: 41.05 | D11: 41.051542 | E11: 37.81 | F11: 37.80844 | G11: 0
A12: 0 | B12: 0 | C12: 41.05 | D12: 41.046674 | E12: 37.81 | F12: 37.812841 | G12: 0
A13: 626 | B13: 626 | C13: 48.45 | D13: 48.605704 | E13: 43.84 | F13: 43.700217 | G13: 0
A14: -2328 | B14: -2335.385 | C14: 48.45 | D14: 49.022634 | E14: 43.84 | F14: 43.321556 | G14: 0
... A62: 121647 | B62: 130683.6 | C62: 41.05 | D62: 40.229 | E62: 37.81 | F62: 37.808373 | G62: 0
O66: Valores Calculados
O67: TMS | P67: %FeT | Q67: %FeMag
N68: Recepción P55 | O68: =B1 -> 0 | P68: =D1/100 -> 0.5656086 | Q68: =F1/100 -> 0.54249789 | R68: =P68*O68 -> 0
N69: Delta Stock P55 | O69: =B2 -> 0 | P69: =D2/100 -> 0.5656086 | Q69: =F2/100 -> 0.54249789 | R69: =P69*O69 -> 0
N70: Alim P55 | O70: =B3 -> 0 | P70: =D3/100 -> 0.5656519 | Q70: =F3/100 -> 0.54244773 | R70: =P70*O70 -> 0
N71: Recepción Alianza | O71: =B4 -> 2249 | P71: =D4/100 -> 0.39769437 | Q71: =F4/100 -> 0.36468211 | R71: =P71*O71 -> 894.41464
N72: Delta Stock Alianza | O72: =B5 -> -405.02495 | P72: =D5/100 -> 0.39400929 | Q72: =F5/100 -> 0.36814781 | R72: =P72*O72 -> -159.58359
N73: Alim Alianza | O73: =B6 -> 2654.025 | P73: =D6/100 -> 0.397132 | Q73: =F6/100 -> 0.365211 | R73: =P73*O73 -> 1053.9982
N74: Recepción P40 | O74: =B7 -> 9579 | P74: =D7/100 -> 0.40868513 | Q74: =F7/100 -> 0.37516123 | R74: =P74*O74 -> 3914.7948
N75: Delta Stock P40 | O75: =B8 -> -10850.798 | P75: =D8/100 -> 0.40918195 | Q75: =F8/100 -> 0.37469387 | R75: =P75*O75 -> -4439.9504
N76: Alim P40 | O76: =B9 -> 20429.798 | P76: =D9/100 -> 0.408949 | Q76: =F9/100 -> 0.374913 | R76: =P76*O76 -> 8354.7453
N77: Recepción Repulpeo | O77: =B10 -> 0 | P77: =D10/100 -> 0.41050812 | Q77: =F10/100 -> 0.37809257 | R77: =P77*O77 -> 0
N78: Delta Stock Repulpeo | O78: =B11 -> 0 | P78: =D11/100 -> 0.41051542 | Q78: =F11/100 -> 0.3780844 | R78: =P78*O78 -> 0
N79: Alim Repulpeo | O79: =B12 -> 0 | P79: =D12/100 -> 0.41046674 | Q79: =F12/100 -> 0.37812841 | R79: =P79*O79 -> 0
... N87: Delta Stock A&Q | O87: =B20 -> 0 | P87: =D20/100 -> 0.53963031 | Q87: =F20/100 -> 0.47846934 | R87: =P87*O87 -> 0
A88: %FeT | B88: R1 | C88: R2 | D88: Hidro | E88: Finisher | F88: Flot Magn | G88: Flot Neum | H88: Esp. Conc | N88: Alim A&Q | O88: =B21 -> 0 | P88: =D21/100 -> 0.53955239 | Q88: =F21/100 -> 0.47854704 | R88: =P88*O88 -> 0
A89: Alimentación | B89: =+P107 -> 0.10797706 | C89: =+P109 -> 0.32205309 | D89: =+P114 -> 0.40551047 | E89: =+P116 -> 0.47052627 | F89: =+P118 -> 0.61794388 | G89: =+P120 -> 0.62661362 | H89: =+P122 -> 0.6564884 | N89: Recep Autech | O89: =B22 -> 0 | P89: =D22/100 -> 0.63100597 | Q89: =F22/100 -> 0.54498819 | R89: =P89*O89 -> 0
A90: Concentrado | B90: =+P109 -> 0.32205309 | C90: =+P111 -> 0.40229 | D90: =+P116 -> 0.47052627 | E90: =+P118 -> 0.61794388 | F90: =+P120 -> 0.62661362 | G90: =+P122 -> 0.6564884 | H90: =+P125 -> 0.6578 | I90: 2097.3996 | N90: Delta Stock Autech | O90: =B23 -> 0 | P90: =D23/100 -> 0.63104136 | Q90: =F23/100 -> 0.54495847 | R90: =P90*O90 -> 0
A91: Cola | B91: =+P108 -> 0.065225387 | C91: =+P110 -> 0.078129748 | D91: =+P115 -> 0.05676 | E91: =+P117 -> 0.063976 | F91: =+P119 -> 0.078766322 | G91: =+P121 -> 0.546084 | H91: =+P123 -> 0.55713252 | N91: Alim Autech | O91: =B24 -> 0 | P91: =D24/100 -> 0.63095048 | Q91: =F24/100 -> 0.54504767 | R91: =P91*O91 -> 0
N92: Recepción 1 | O92: =B25 -> 419 | P92: =D25/100 -> 0.42736065 | Q92: =F25/100 -> 0.39262664 | R92: =P92*O92 -> 179.06411
I93: =+L92-L94 -> 0 | N93: Delta Stock 1 | O93: =B26 -> -63.977203 | P93: =D26/100 -> 0.42332446 | Q93: =F26/100 -> 0.39641907 | R93: =P93*O93 -> -27.083115
A94: Rec Met Calc | B94: =+IF((B90-B91)<>0,(B90/B89)*(B89-B91)/(B90-B91),0) -> 0.49648622 | C94: =+IF((C90-C91)<>0,(C90/C89)*(C89-C91)/(C90-C91),0) -> 0.93995133 | D94: =+IF((D90-D91)<>0,(D90/D89)*(D89-D91)/(D90-D91),0) -> 0.978006 | E94: =+IF((E90-E91)<>0,(E90/E89)*(E89-E91)/(E90-E91),0) -> 0.96381755 | F94: =+IF((F90-F91)<>0,(F90/F89)*(F89-F91)/(F90-F91),0) -> 0.99798285 | G94: =+IF((G90-G91)<>0,(G90/G89)*(G89-G91)/(G90-G91),0) -> 0.7641815 | H94: =+IF((H90-H91)<>0,(H90/H89)*(H89-H91)/(H90-H91),0) -> 0.98894281 | I94: =+B94*C94*D94*E94*F94*G94*H94 -> 0.33177197 | N94: Alim 1 | O94: =B27 -> 482.9772 | P94: =D27/100 -> 0.426826 | Q94: =F27/100 -> 0.393129 | R94: =P94*O94 -> 206.14723
N95: Recepción 2 | O95: =B28 -> 403 | P95: =D28/100 -> 0.47490582 | Q95: =F28/100 -> 0.42231101 | R95: =P95*O95 -> 191.38704
N96: Delta Stock 2 | O96: =B29 -> -1188.97 | P96: =D29/100 -> 0.47868725 | Q96: =F29/100 -> 0.41889534 | R96: =P96*O96 -> -569.14478
N97: Alim 2 | O97: =B30 -> 1591.97 | P97: =D30/100 -> 0.47773 | Q97: =F30/100 -> 0.41976 | R97: =P97*O97 -> 760.53183
...

Sheet Diagrama Fe T
R5: =Flujos!H43 -> 1043317
R6: =Flujos!I43 -> 0.10797706
O7: Repulpeo | R7: =R5*R6 -> 112654.3
O8: =Flujos!H14 -> 0
J9: =Utilidad!O68 -> 0 | O9: =Flujos!H14*Flujos!I14 -> 0 | U9: =Flujos!H44 -> 869645.92
J10: =Utilidad!P68 -> 0.5656086 | U10: =Flujos!I44 -> 0.065225387
J11: =Utilidad!R68 -> 0 | M11: =Utilidad!O70 -> 0 | R11: =Flujos!H45 -> 173671.08 | U11: =U10*U9 -> 56722.992
L12: =+Utilidad!O69 -> 0 | M12: =Utilidad!P70 -> 0.5656519 | R12: =Flujos!I45 -> 0.32205309
L13: =+Utilidad!R69 -> 0 | M13: =Utilidad!R70 -> 0 | O13: =Flujos!C13 -> 0 | R13: =R11*R12 -> 55931.307
O14: =Flujos!D13 -> 0.4105 | S14: =Flujos!H46 -> 42987.474
O15: =O13*O14 -> 0 | S15: =Flujos!I46 -> 0.078129748 | Y15: =+U9+S14+S29+S36+S41+U45+S22 -> 1002001.9
S16: =S14*S15 -> 3358.6005 | Y16: =+IF(Y15<>0,(U9*U10+S14*S15+S29*S30+S36*S37+S41*S42+U45*U46+S22*S23)/Y15,0) -> 0.078532483
R17: =Flujos!H47 -> 130683.6 | Y17: =Y15*Y16 -> 78689.697
N18: =Flujos!C15 -> 0 | P18: =Flujos!H64 -> 0 | R18: =Flujos!I47 -> 0.40229
N19: =Flujos!D15 -> 0.4105 | P19: =Flujos!I64 -> 0.41050812
N20: =N18*N19 -> 0 | R20: =Flujos!H65 -> 130683.6
J21: =+Utilidad!O71 -> 2249 | R21: =Flujos!I65 -> 0.40229
J22: =+Utilidad!P71/100 -> 0.0039769437 | S22: =Flujos!H48 -> 0
J23: =+Utilidad!R71 -> 894.41464 | M23: =Utilidad!O73 -> 2654.025 | S23: =Flujos!I48 -> 0
L24: =+Utilidad!O72 -> -405.02495 | M24: =Utilidad!P73/100 -> 0.00397132 | N24: =Flujos!H49 -> 28571.901 | R24: =Flujos!H50 -> 159255.5 | S24: =S22*S23 -> 0
L25: =+Utilidad!R72 -> -159.58359 | M25: =Utilidad!R73 -> 1053.9982 | N25: =Flujos!I49 -> 0.4202404 | R25: =Flujos!I50 -> 0.40551047
N26: =N24*N25 -> 12007.067 | R26: =R24*R25 -> 64579.774
O29: =Flujos!H63 -> 0 | S29: =Flujos!H51 -> 25024.09
O30: =Flujos!I63 -> 0.41051542 | S30: =Flujos!I51 -> 0.05676
J31: =+Utilidad!O74 -> 9579 | R31: =Flujos!H52 -> 134231.41 | S31: =S30*S29 -> 1420.3673
J32: =+Utilidad!P74/100 -> 0.0040868513 | R32: =Flujos!I52 -> 0.47052627
J33: =+Utilidad!R74 -> 3914.7948 | M33: =+Utilidad!O76 -> 20429.798 | R33: =R31*R32 -> 63159.406 | Y33: =U9+S14+S29+S36+U45-Y15 -> -1558.9435
L34: =+Utilidad!O75 -> -10850.798 | M34: =+Utilidad!P76/100 -> 0.00408949
L35: =+Utilidad!R75 -> -4439.9504 | M35: =+Utilidad!R76 -> 8354.7453
D36: =Flujos!H28 -> 419 | S36: =Flujos!H53 -> 35720.618
D37: =Flujos!I28 -> 0.42736065 | S37: =Flujos!I53 -> 0.063976
D38: =D36*D37 -> 179.06411 | G38: =Flujos!H30 -> 482.9772 | R38: =Flujos!H54 -> 98510.796 | S38: =S36*S37 -> 2285.2622
F39: =Flujos!H29 -> -63.977203 | G39: =Flujos!I30 -> 0.426826 | R39: =Flujos!I54 -> 0.61794388
F40: =Flujos!I29*Flujos!H29 -> -27.083115 | G40: =G39*G38 -> 206.14723 | R40: =R38*R39 -> 60874.144
S41: =Flujos!H55 -> 1558.9435
S42: =Flujos!I55 -> 0.078766322
E43: T2 | S43: =S41*S42 -> 122.79224
D44: =Flujos!H31 -> 403 | R44: =Flujos!H56 -> 96951.853
D45: =Flujos!I31 -> 0.47490582 | G45: =Flujos!H33 -> 1591.97 | P45: =Flujos!H59 -> 922.58318 | R45: =Flujos!I56 -> 0.62661362 | S45: =R44*R45 -> 60751.352 | U45: =Flujos!H57 -> 27064.853
D46: =D44*D45 -> 191.38704 | F46: =Flujos!H32 -> -1188.97 | G46: =Flujos!I33 -> 0.47773 | P46: =Flujos!I59 -> 0.55713252 | U46: =Flujos!I57 -> 0.546084
...

Sheet Flujos
B2: Mediciones | G2: Balance | L2: % Cambio relativo | P2: Max Var Ton | Q2: Max Var FeT | R2: Max Var FeMag | T2: FeMag < FeT
B3: Flujos | C3: TMS | D3: Ley FeT | E3: Ley FeMag | G3: Flujos | H3: TMS | I3: Ley FeT | J3: Ley FeMag | L3: TMSD | M3: %Fe T | N3: %Fe M
B4: Recepción P55 | C4: =Utilidad!A1 -> 0 | D4: =IF(Utilidad!C$46>1,Utilidad!C1/100,Utilidad!C1) -> 0.5657 | E4: =IF(Utilidad!$E$46>1,Utilidad!E1/100,Utilidad!E1) -> 0.5424 | G4: Recepción P55 | H4: =Utilidad!B1 -> 0 | I4: =IF(Utilidad!$D$46>1,Utilidad!D1/100,Utilidad!D1) -> 0.5656086 | J4: =IF(Utilidad!$F$46>1,Utilidad!F1/100,Utilidad!F1) -> 0.54249789 | L4: =+IF(C4<>0,(H4-C4)/C4,ABS(H4-C4)) -> 0 | M4: =+IF(D4<>0,(I4-D4)/D4,0) -> -0.00016156129 | N4: =+IF(E4<>0,(J4-E4)/E4,0) -> 0.0001804788 | P4: =+IF(L4<>"",ABS(L4),0) -> 0 | Q4: =+IF(L4<>"",ABS(M4),0) -> 0.00016156129 | R4: =+IF(M4<>"",ABS(N4),0) -> 0.0001804788 | T4: =IF(J4<=I4,"SI","NO") -> SI
B5: Delta Stock P55 | C5: =Utilidad!A2 -> 0 | D5: =IF(Utilidad!C$46>1,Utilidad!C2/100,Utilidad!C2) -> 0.5657 | E5: =IF(Utilidad!$E$46>1,Utilidad!E2/100,Utilidad!E2) -> 0.5424 | G5: Delta Stock P55 | H5: =Utilidad!B2 -> 0 | I5: =IF(Utilidad!$D$46>1,Utilidad!D2/100,Utilidad!D2) -> 0.5656086 | J5: =IF(Utilidad!$F$46>1,Utilidad!F2/100,Utilidad!F2) -> 0.54249789 | L5: =+IF(C5<>0,(H5-C5)/C5,ABS(H5-C5)) -> 0 | M5: =+IF(D5<>0,(I5-D5)/D5,0) -> -0.00016156129 | N5: =+IF(E5<>0,(J5-E5)/E5,0) -> 0.0001804788 | P5: =+IF(L5<>"",ABS(L5),0) -> 0 | Q5: =+IF(L5<>"",ABS(M5),0) -> 0.00016156129 | R5: =+IF(M5<>"",ABS(N5),0) -> 0.0001804788 | T5: =IF(J5<=I5,"SI","NO") -> SI
B6: Alim P55 | C6: =Utilidad!A3 -> 0 | D6: =IF(Utilidad!C$46>1,Utilidad!C3/100,Utilidad!C3) -> 0.5657 | E6: =IF(Utilidad!$E$46>1,Utilidad!E3/100,Utilidad!E3) -> 0.5424 | G6: Alim P55 | H6: =Utilidad!B3 -> 0 | I6: =IF(Utilidad!$D$46>1,Utilidad!D3/100,Utilidad!D3) -> 0.5656519 | J6: =IF(Utilidad!$F$46>1,Utilidad!F3/100,Utilidad!F3) -> 0.54244773 | L6: =+IF(C6<>0,(H6-C6)/C6,ABS(H6-C6)) -> 0 | M6: =+IF(D6<>0,(I6-D6)/D6,0) -> -8.502717e-05 | N6: =+IF(E6<>0,(J6-E6)/E6,0) -> 8.7998285e-05 | P6: =+IF(L6<>"",ABS(L6),0) -> 0 | Q6: =+IF(L6<>"",ABS(M6),0) -> 8.502717e-05 | R6: =+IF(M6<>"",ABS(N6),0) -> 8.7998285e-05 | T6: =IF(J6<=I6,"SI","NO") -> SI
B7: Recepción Alianza | C7: =Utilidad!A4 -> 2249 | D7: =IF(Utilidad!C$46>1,Utilidad!C4/100,Utilidad!C4) -> 0.3932 | E7: =IF(Utilidad!$E$46>1,Utilidad!E4/100,Utilidad!E4) -> 0.3689 | G7: Recepción Alianza | H7: =Utilidad!B4 -> 2249 | I7: =IF(Utilidad!$D$46>1,Utilidad!D4/100,Utilidad!D4) -> 0.39769437 | J7: =IF(Utilidad!$F$46>1,Utilidad!F4/100,Utilidad!F4) -> 0.36468211 | L7: =+IF(C7<>0,(H7-C7)/C7,ABS(H7-C7)) -> 0 | M7: =+IF(D7<>0,(I7-D7)/D7,0) -> 0.011430244 | N7: =+IF(E7<>0,(J7-E7)/E7,0) -> -0.011433704 | P7: =+IF(L7<>"",ABS(L7),0) -> 0 | Q7: =+IF(L7<>"",ABS(M7),0) -> 0.011430244 | R7: =+IF(M7<>"",ABS(N7),0) -> 0.011433704 | T7: =IF(J7<=I7,"SI","NO") -> SI
B8: Delta Stock Alianza | C8: =Utilidad!A5 -> -406 | D8: =IF(Utilidad!C$46>1,Utilidad!C5/100,Utilidad!C5) -> 0.3932 | E8: =IF(Utilidad!$E$46>1,Utilidad!E5/100,Utilidad!E5) -> 0.3689 | G8: Delta Stock Alianza | H8: =Utilidad!B5 -> -405.02495 | I8: =IF(Utilidad!$D$46>1,Utilidad!D5/100,Utilidad!D5) -> 0.39400929 | J8: =IF(Utilidad!$F$46>1,Utilidad!F5/100,Utilidad!F5) -> 0.36814781 | L8: =+IF(C8<>0,(H8-C8)/C8,ABS(H8-C8)) -> -0.0024015924 | M8: =+IF(D8<>0,(I8-D8)/D8,0) -> 0.0020582181 | N8: =+IF(E8<>0,(J8-E8)/E8,0) -> -0.0020390013 | P8: =+IF(L8<>"",ABS(L8),0) -> 0.0024015924 | Q8: =+IF(L8<>"",ABS(M8),0) -> 0.0020582181 | R8: =+IF(M8<>"",ABS(N8),0) -> 0.0020390013 | T8: =IF(J8<=I8,"SI","NO") -> SI
B9: Alim Alianza | C9: =Utilidad!A6 -> 2655 | D9: =IF(Utilidad!C$46>1,Utilidad!C6/100,Utilidad!C6) -> 0.3932 | E9: =IF(Utilidad!$E$46>1,Utilidad!E6/100,Utilidad!E6) -> 0.3689 | G9: Alim Alianza | H9: =Utilidad!B6 -> 2654.025 | I9: =IF(Utilidad!$D$46>1,Utilidad!D6/100,Utilidad!D6) -> 0.397132 | J9: =IF(Utilidad!$F$46>1,Utilidad!F6/100,Utilidad!F6) -> 0.365211 | L9: =+IF(C9<>0,(H9-C9)/C9,ABS(H9-C9)) -> -0.00036724915 | M9: =+IF(D9<>0,(I9-D9)/D9,0) -> 0.01 | N9: =+IF(E9<>0,(J9-E9)/E9,0) -> -0.01 | P9: =+IF(L9<>"",ABS(L9),0) -> 0.00036724915 | Q9: =+IF(L9<>"",ABS(M9),0) -> 0.01 | R9: =+IF(M9<>"",ABS(N9),0) -> 0.01 | T9: =IF(J9<=I9,"SI","NO") -> SI
B10: Recepción P40 | C10: =Utilidad!A7 -> 9579 | D10: =IF(Utilidad!C$46>1,Utilidad!C7/100,Utilidad!C7) -> 0.4049 | E10: =IF(Utilidad!$E$46>1,Utilidad!E7/100,Utilidad!E7) -> 0.3787 | G10: Recepción P40 | H10: =Utilidad!B7 -> 9579 | I10: =IF(Utilidad!$D$46>1,Utilidad!D7/100,Utilidad!D7) -> 0.40868513 | J10: =IF(Utilidad!$F$46>1,Utilidad!F7/100,Utilidad!F7) -> 0.37516123 | L10: =+IF(C10<>0,(H10-C10)/C10,ABS(H10-C10)) -> 0 | M10: =+IF(D10<>0,(I10-D10)/D10,0) -> 0.0093482999 | N10: =+IF(E10<>0,(J10-E10)/E10,0) -> -0.0093445272 | P10: =+IF(L10<>"",ABS(L10),0) -> 0 | Q10: =+IF(L10<>"",ABS(M10),0) -> 0.0093482999 | R10: =+IF(M10<>"",ABS(N10),0) -> 0.0093445272 | T10: =IF(J10<=I10,"SI","NO") -> SI
B11: Delta Stock P40 | C11: =Utilidad!A8 -> -10902 | D11: =IF(Utilidad!C$46>1,Utilidad!C8/100,Utilidad!C8) -> 0.4049 | E11: =IF(Utilidad!$E$46>1,Utilidad!E8/100,Utilidad!E8) -> 0.3787 | G11: Delta Stock P40 | H11: =Utilidad!B8 -> -10850.798 | I11: =IF(Utilidad!$D$46>1,Utilidad!D8/100,Utilidad!D8) -> 0.40918195 | J11: =IF(Utilidad!$F$46>1,Utilidad!F8/100,Utilidad!F8) -> 0.37469387 | L11: =+IF(C11<>0,(H11-C11)/C11,ABS(H11-C11)) -> -0.0046966153 | M11: =+IF(D11<>0,(I11-D11)/D11,0) -> 0.010575316 | N11: =+IF(E11<>0,(J11-E11)/E11,0) -> -0.010578646 | P11: =+IF(L11<>"",ABS(L11),0) -> 0.0046966153 | Q11: =+IF(L11<>"",ABS(M11),0) -> 0.010575316 | R11: =+IF(M11<>"",ABS(N11),0) -> 0.010578646 | T11: =IF(J11<=I11,"SI","NO") -> SI
B12: Alim P40 | C12: =Utilidad!A9 -> 20481 | D12: =IF(Utilidad!C$46>1,Utilidad!C9/100,Utilidad!C9) -> 0.4049 | E12: =IF(Utilidad!$E$46>1,Utilidad!E9/100,Utilidad!E9) -> 0.3787 | G12: Alim P40 | H12: =Utilidad!B9 -> 20429.798 | I12: =IF(Utilidad!$D$46>1,Utilidad!D9/100,Utilidad!D9) -> 0.408949 | J12: =IF(Utilidad!$F$46>1,Utilidad!F9/100,Utilidad!F9) -> 0.374913 | L12: =+IF(C12<>0,(H12-C12)/C12,ABS(H12-C12)) -> -0.0025 | M12: =+IF(D12<>0,(I12-D12)/D12,0) -> 0.01 | N12: =+IF(E12<>0,(J12-E12)/E12,0) -> -0.01 | P12: =+IF(L12<>"",ABS(L12),0) -> 0.0025 | Q12: =+IF(L12<>"",ABS(M12),0) -> 0.01 | R12: =+IF(M12<>"",ABS(N12),0) -> 0.01 | T12: =IF(J12<=I12,"SI","NO") -> SI
B13: Recepción Repulpeo | C13: =Utilidad!A10 -> 0 | D13: =IF(Utilidad!C$46>1,Utilidad!C10/100,Utilidad!C10) -> 0.4105 | E13: =IF(Utilidad!$E$46>1,Utilidad!E10/100,Utilidad!E10) -> 0.3781 | G13: Recepción Repulpeo | H13: =Utilidad!B10 -> 0 | I13: =IF(Utilidad!$D$46>1,Utilidad!D10/100,Utilidad!D10) -> 0.41050812 | J13: =IF(Utilidad!$F$46>1,Utilidad!F10/100,Utilidad!F10) -> 0.37809257 | L13: =+IF(C13<>0,(H13-C13)/C13,ABS(H13-C13)) -> 0 | M13: =+IF(D13<>0,(I13-D13)/D13,0) -> 1.9769379e-05 | N13: =+IF(E13<>0,(J13-E13)/E13,0) -> -1.9648188e-05 | P13: =+IF(L13<>"",ABS(L13),0) -> 0 | Q13: =+IF(L13<>"",ABS(M13),0) -> 1.9769379e-05 | R13: =+IF(M13<>"",ABS(N13),0) -> 1.9648188e-05 | T13: =IF(J13<=I13,"SI","NO") -> SI
B14: Delta Stock Repulpeo | C14: =Utilidad!A11 -> 0 | D14: =IF(Utilidad!C$46>1,Utilidad!C11/100,Utilidad!C11) -> 0.4105 | E14: =IF(Utilidad!$E$46>1,Utilidad!E11/100,Utilidad!E11) -> 0.3781 | G14: Delta Stock Repulpeo | H14: =Utilidad!B11 -> 0 | I14: =IF(Utilidad!$D$46>1,Utilidad!D11/100,Utilidad!D11) -> 0.41051542 | J14: =IF(Utilidad!$F$46>1,Utilidad!F11/100,Utilidad!F11) -> 0.3780844 | L14: =+IF(C14<>0,(H14-C14)/C14,ABS(H14-C14)) -> 0 | M14: =+IF(D14<>0,(I14-D14)/D14,0) -> 3.756838e-05 | N14: =+IF(E14<>0,(J14-E14)/E14,0) -> -4.1250331e-05 | P14: =+IF(L14<>"",ABS(L14),0) -> 0 | Q14: =+IF(L14<>"",ABS(M14),0) -> 3.756838e-05 | R14: =+IF(M14<>"",ABS(N14),0) -> 4.1250331e-05 | T14: =IF(J14<=I14,"SI","NO") -> SI
B15: Alim Repulpeo | C15: =Utilidad!A12 -> 0 | D15: =IF(Utilidad!C$46>1,Utilidad!C12/100,Utilidad!C12) -> 0.4105 | E15: =IF(Utilidad!$E$46>1,Utilidad!E12/100,Utilidad!E12) -> 0.3781 | G15: Alim Repulpeo | H15: =Utilidad!B12 -> 0 | I15: =IF(Utilidad!$D$46>1,Utilidad!D12/100,Utilidad!D12) -> 0.41046674 | J15: =IF(Utilidad!$F$46>1,Utilidad!F12/100,Utilidad!F12) -> 0.37812841 | L15: =+IF(C15<>0,(H15-C15)/C15,ABS(H15-C15)) -> 0 | M15: =+IF(D15<>0,(I15-D15)/D15,0) -> -8.1024921e-05 | N15: =+IF(E15<>0,(J15-E15)/E15,0) -> 7.513589e-05 | P15: =+IF(L15<>"",ABS(L15),0) -> 0 | Q15: =+IF(L15<>"",ABS(M15),0) -> 8.1024921e-05 | R15: =+IF(M15<>"",ABS(N15),0) -> 7.513589e-05 | T15: =IF(J15<=I15,"SI","NO") -> SI
... B65: CR2 a Molienda | C65: =Utilidad!A62 -> 121647 | D65: =IF(Utilidad!C$46>1,Utilidad!C62/100,Utilidad!C62) -> 0.4105 | E65: =IF(Utilidad!$E$46>1,Utilidad!E62/100,Utilidad!E62) -> 0.3781 | G65: CR2 a Molienda | H65: =Utilidad!B62 -> 130683.6 | I65: =IF(Utilidad!$D$46>1,Utilidad!D62/100,Utilidad!D62) -> 0.40229 | J65: =IF(Utilidad!$F$46>1,Utilidad!F62/100,Utilidad!F62) -> 0.37808373 | L65: =+IF(C65<>0,(H65-C65)/C65,ABS(H65-C65)) -> 0.074285454 | M65: =+IF(D65<>0,(I65-D65)/D65,0) -> -0.02 | N65: =+IF(E65<>0,(J65-E65)/E65,0) -> -4.3021793e-05 | P65: =+IF(L65<>"",ABS(L65),0) -> 0.074285454 | Q65: =+IF(L65<>"",ABS(M65),0) -> 0.02 | R65: =+IF(M65<>"",ABS(N65),0) -> 4.3021793e-05 | T65: =IF(J65<=I65,"SI","NO") -> SI
B70: Fe total (%) | C70: R1 | D70: R2 | E70: Hidro | F70: Finisher | G70: Flot. Magnética | H70: Flot Neumática | I70: Esp. Concentrado | J70: Total (Planta)
B71: Alimentación | C71: =+I43 -> 0.10797706 | D71: =+C72 -> 0.32205309 | E71: =+I50 -> 0.40551047 | F71: =E72 -> 0.47052627 | G71: =F72 -> 0.61794388 | H71: =G72 -> 0.62661362 | I71: =+H72 -> 0.6564884
B72: Concentrado | C72: =+I45 -> 0.32205309 | D72: =+I47 -> 0.40229 | E72: =+I52 -> 0.47052627 | F72: =+I54 -> 0.61794388 | G72: =+I56 -> 0.62661362 | H72: =+I58 -> 0.6564884 | I72: =+I61 -> 0.6578
B73: Cola | C73: =+I44 -> 0.065225387 | D73: =+I46 -> 0.078129748 | E73: =+I51 -> 0.05676 | F73: =+I53 -> 0.063976 | G73: =+I55 -> 0.078766322 | H73: =+I57 -> 0.546084 | I73: =+I59 -> 0.55713252
B74: Rp | C74: =+(C71-C73)/(C72-C73)*100 -> 16.646051 | D74: =+(D71-D73)/(D72-D73)*100 -> 75.247764 | E74: =+(E71-E73)/(E72-E73)*100 -> 84.286829 | F74: =+(F71-F73)/(F72-F73)*100 -> 73.388779 | G74: =+(G71-G73)/(G72-G73)*100 -> 98.41749 | H74: =+(H71-H73)/(H72-H73)*100 -> 72.940594 | I74: =+(I71-I73)/(I72-I73)*100 -> 98.697093 | J74: =+C74*D74*E74*F74*G74*H74*I74/1000000000000 -> 5.4895928
B75: Rm | C75: =+(C72/C71)*C74 -> 49.648622 | D75: =+(D72/D71)*D74 -> 93.995133 | E75: =+(E72/E71)*E74 -> 97.8006 | F75: =+(F72/F71)*F74 -> 96.381755 | G75: =+(G72/G71)*G74 -> 99.798285 | H75: =+(H72/H71)*H74 -> 76.41815 | I75: =+(I72/I71)*I74 -> 98.894281 | J75: =+C75*D75*E75*F75*G75*H75*I75/1000000000000 -> 33.177197
B77: Fe Magnético (%) | C77: R1 | D77: R2 | E77: Hidro | F77: Finisher | G77: Flot. Magnética | H77: Flot Neumática | I77: Esp. Concentrado | J77: Total (Planta)
B78: Alimentación | C78: =+J43 -> 0.051604 | D78: =+C79 -> 0.2884927 | E78: =+J50 -> 0.37892347 | F78: =+E79 -> 0.44687081 | G78: =+J54 -> 0.60086775 | H78: =G79 -> 0.6104034 | I78: =+H79 -> 0.64696029
B79: Concentrado | C79: =+J45 -> 0.2884927 | D79: =+J47 -> 0.37808373 | E79: =+J52 -> 0.44687081 | F79: =+J54 -> 0.60086775 | G79: =+J56 -> 0.6104034 | H79: =+J58 -> 0.64696029 | I79: =+J61 -> 0.6488
B80: Cola | C80: =+J44 -> 0.0042965672 | D80: =+J46 -> 0.016132465 | E80: =+J51 -> 0.014448 | F80: =+J53 -> 0.022176 | G80: =+J55 -> 0.007838516 | H80: =+J57 -> 0.5112555 | I80: =+J59 -> 0.50759985
B81: Rp | C81: =+(C78-C80)/(C79-C80)*100 -> 16.646051 | D81: =+(D78-D80)/(D79-D80)*100 -> 75.247764 | E81: =+(E78-E80)/(E79-E80)*100 -> 84.286829 | F81: =+(F78-F80)/(F79-F80)*100 -> 73.388779 | G81: =+(G78-G80)/(G79-G80)*100 -> 98.41749 | H81: =+(H78-H80)/(H79-H80)*100 -> 73.061457 | I81: =+(I78-I80)/(I79-I80)*100 -> 98.697093 | J81: =+C81*D81*E81*F81*G81*H81*I81/1000000000000 -> 5.4986891
B82: Rmm | C82: =+(C79/C78)*C81 -> 93.059921 | D82: =+(D79/D78)*D81 -> 98.615859 | E82: =+(E79/E78)*E81 -> 99.400871 | F82: =+(F79/F78)*F81 -> 98.679416 | G82: =+(G79/G78)*G81 -> 99.979356 | H82: =+(H79/H78)*H81 -> 77.437088 | I82: =+(I79/I78)*I81 -> 98.977749 | J82: =+C82*D82*E82*F82*G82*H82*I82/1000000000000 -> 68.979989
D85: =C74*D74/100 -> 12.525781 | E85: =H43*D85% -> 130683.6 | F85: 28571.901
E86: =E85+F85 -> 159255.5
E87: =H61/E86*100 -> 43.88357
E88: =E87*D85/100 -> 5.4967598

Sheet Datos Extra
A1: Pellet Feed | B1: 93467.25 | C1: 0.65706082 | D1: 0.64809191 | E1: 0
A2: Produccion Filtrado | B2: 69610 | C2: 0.6578 | D2: 0.648821 | E2: 0

Sheet Reporte
D2: BALANCE METALÚRGICO - VALLE COPIAPO
D4: REPORTE DE PLANTA MAGNETITA | L4: =TODAY()-4 -> 45893
E7: TONELAJE | F7: LEY | G7: FINO | H7: LEY | K7: TONELAJE | L7: LEY | M7: FINO | N7: LEY
E8: TMS | F8: % FeT | G8: TMF | H8: % Fe Mag | K8: TMS | L8: % FeT | M8: TMF | N8: % Fe Mag
B9: ENTRADAS | H9: SALIDA
B10: Relaves CCMC | E10: =Flujos!H43 -> 1043317 | F10: =Flujos!I43 -> 0.10797706 | G10: =E10*F10 -> 112654.3 | H10: =Flujos!J43 -> 0.051604 | I10: Produccion Planta | K10: =Flujos!H61 -> 69887 | L10: =Flujos!I61 -> 0.6578 | M10: =+L10*K10 -> 45971.669 | N10: =Flujos!J61 -> 0.6488 | Q10: RP R1XR2 | R10: =Flujos!C74*Flujos!D74/100 -> 12.525781
B11: Alim P55 | E11: =Flujos!H6 -> 0 | F11: =Flujos!I6 -> 0.5656519 | H11: =Flujos!J6 -> 0.54244773 | I11: Produccion Filtrado | K11: ='Datos Extra'!B2 -> 69610 | L11: ='Datos Extra'!C2 -> 0.6578 | M11: =+L11*K11 -> 45789.458 | N11: ='Datos Extra'!D2 -> 0.648821 | Q11: ALIM CCMCXRPR1R2 | R11: =Flujos!H43*Flujos!D85/100 -> 130683.6
B12: Alim P40 | E12: =Utilidad!O76 -> 20429.798 | F12: =Flujos!I12 -> 0.408949 | G12: =+E12*F12 -> 8354.7453 | H12: =Flujos!J12 -> 0.374913 | Q12: ALIM TERCEROS | R12: =SUM(E12:E20) -> 28571.901
B13: Alim Repulpeo | Q13: ALIM TOTAL MOLIENDA | R13: =R11+R12 -> 159255.5
B14: Alim Ema | E14: =Flujos!H18 -> 2961.385 | F14: =Flujos!I18 -> 0.489345 | G14: =+E14*F14 -> 1449.1389 | H14: =Flujos!J18 -> 0.434016 | Q14: RP MOLIENDA | R14: =Flujos!H61/R13*100 -> 43.88357
B15: Alim Marcela | E15: =Utilidad!O85 -> 451.74641 | F15: =Utilidad!P85 -> 0.404 | G15: =+E15*F15 -> 182.50555 | H15: =Flujos!J21 -> 0.363528 | Q15: RP GLOBAL | R15: =R14*R10/100 -> 5.4967598
B16: Alim A&Q | Q16: RP ARCHIVO | R16: =Flujos!J74 -> 5.4895928
B17: Alim Autech | E17: =Flujos!H27 -> 0 | F17: =Flujos!I27 -> 0.63095048 | H17: =Flujos!J27 -> 0.54504767
B18: Alim Alianza | E18: =Utilidad!O73 -> 2654.025 | F18: =Flujos!I9 -> 0.397132 | G18: =+E18*F18 -> 1053.9982 | H18: =Flujos!J9 -> 0.365211
B19: Alim San Andres | E19: =Flujos!H30 -> 482.9772 | F19: =Flujos!I30 -> 0.426826 | G19: =+E19*F19 -> 206.14723 | H19: =Flujos!J30 -> 0.393129
B20: Alim Rajos de Hierro | E20: =Flujos!H33 -> 1591.97 | F20: =Flujos!I33 -> 0.47773 | G20: =+E20*F20 -> 760.53183 | H20: =Flujos!J33 -> 0.41976
B23: TOTAL | E23: =SUM(E10:E22) -> 1071888.9 | F23: =+G23/E23 -> 0.11630064 | G23: =SUM(G10:G22) -> 124661.37 | H23: =SUMPRODUCT(E10:E22,H10:H22)/E23 -> 0.060431295
B24: EMBARQUES | H24: PÉRDIDAS
B25: Pellet Feed | E25: ='Datos Extra'!B1 -> 93467.25 | F25: ='Datos Extra'!C1 -> 0.65706082 | G25: =+E25*F25 -> 61413.667 | H25: Relaves CCMC | K25: =Flujos!H62 -> 1002001.9 | L25: =Flujos!I62 -> 0.078532483 | M25: =+K25*L25 -> 78689.697
B26: TOTAL | E26: =SUM(E24:E25) -> 93467.25 | F26: =F25 -> 0.65706082 | G26: =SUM(G24:G25) -> 61413.667 | H26: TOTAL | K26: =K25 -> 1002001.9 | L26: =L25 -> 0.078532483 | M26: =M25 -> 78689.697
B28: INDICADORES PLANTA MAGNETITA
B30: RECUPERACIÓN EN PESO | G30: RECUPERACIÓN METALÚRGICA | K30: RECUPERACIÓN MAGNÉTICA METALÚRGICA
B31: =Flujos!J74/100 -> 0.054895928 | G31: =Utilidad!I94 -> 0.33177197 | K31: =Utilidad!I104 -> 0.68979989
